Workbook

Sheet Instructivo
B2: COLEGIO MARÍA AUXILIADORA DE SOACHA
B3: Arquitectura del plan de estudios 2027 · Tarea 1.5.1 · Libro de trabajo
B4: Asistencia técnica EICIT · Versión 3 · malla definitiva del consenso del 30 de septiembre de 2026
B6: Encuadre | C6: EICIT propone, diseña y acompaña; el Colegio delibera, decide y adopta. Esta malla es una propuesta técnica: su versión definitiva corresponde al Consejo Académico, al Consejo Directivo y a la resolución rectoral, con plena autonomía curricular y preservando la identidad salesiana.
B7: Estado | C7: Versión definitiva: incorpora el consenso del 30 de septiembre de 2026 y el acta de consenso de la tarea 1.5.1. Es la fuente única para el PEI (§3.3) y para la elaboración de los planes de estudio, que se incorporan como anexos en desarrollo.
B8: Propósito | C8: Definir la arquitectura del plan de estudios 2027: áreas obligatorias (arts. 23 y 31 de la Ley 115), optativas, énfasis y especialidad técnica; intensidades semanales por asignatura y grado; verificación de mínimos legales y de la regla 80/20. Es el insumo 1 para generar los planes de estudio en el formato 1.5.2.
B9: Insumos | C9: Versión definitiva de la malla por horas del Colegio (MALLA_X_HORAS_Ver_2.xlsx, «V2»), hoja crono_academico, Horario base 2027, horario del II semestre de 2026, resultados Saber 11 2023–2025 (matriz 1.2.4), matriz de referentes 1.3.6, formato de plan de estudios 1.5.2 y propuesta v1 de esta tarea.
B10: Cómo usar | C10: Las celdas en azul son editables. Al modificar una intensidad en Malla_2027, se recalculan los totales, la verificación normativa (Validacion), el comparativo y el catálogo de planes con sus sesiones por período. Los parámetros de tiempo escolar están en Parametros y Calendario_2027.
B11: Hojas | C11: Parametros · Calendario_2027 · Calendario_2027_40s y Vista_mensual_2027 (alternativa) · Malla_2027 · Validacion · Calidad_Saber11 · Innovacion · Catalogo_planes · Comparativo · Acuerdos · Transversales · Decisiones_CMA.
B12: Cómputo del tiempo | C12: El Decreto 0277 de 2025 exige 40 semanas lectivas y fija 37 h semanales y 1.480 anuales para la media técnica. La hoja Parametros permite elegir el criterio de cómputo de la sesión de 55 min (estricto o Decreto 0277) y el carácter de la media; la verificación se recalcula.
B13: Acuerdos clave | C13: Física en Ciencias Naturales; historia integrada en Ciencias Sociales y en Ciencias Económicas y Políticas (Ley 1874 de 2017); competencias ciudadanas en Ética; sesión de 55 + 5 min = 1 hora efectiva; 38 semanas completas; Cátedra de Educación Emocional como proyecto transversal; Infancia Misionera como proyecto pastoral sin plan de estudios.
B15: Cifras clave (se actualizan con las fórmulas)
B16: Planes de estudio por elaborar | C16: =Catalogo_planes!H154 -> 146
B17: Días lectivos efectivos proyectados (2027) | C17: =Calendario_2027!G11 -> 180
B18: Horas efectivas anuales 6°–9° · Escenario 1 | C18: =Validacion!H11 -> 1330
B19: Horas efectivas anuales 6°–9° · Escenario 2 (40 semanas) | C19: =Validacion!H12 -> 1400
B20: Días mínimos para cumplir 1.200 h en 6°–9° | C20: =Validacion!H16 -> 172
B21: Horas anuales 10°–11° · Escenario 1 | C21: =Validacion!L11 -> 1406
B22: Brecha de la media técnica frente a 1.480 h | C22: =Validacion!L13-Validacion!L11 -> 74
B23: Contingencia: segunda franja de 2 h · horas anuales media | C23: =(Validacion!L8+2)*Parametros!C11/5 -> 1482
B24: Base del cómputo anual | C24: =Parametros!C32 -> Semanas lectivas del calendario
B25: Mínimo anual aplicable a 10°–11° | C25: =Validacion!L13 -> 1480
B26: Criterio de cómputo de la sesión | C26: =Parametros!C28 -> Decreto 0277 de 2025 (55 min + 5 de descanso = 1 h efectiva)
B27: Decisiones pendientes del Colegio | C27: =COUNTIF(Decisiones_CMA!G5:G19,"Pendiente*") -> 3
B28: Aporte de Matemáticas, Sociales y C. Naturales a la caída del global Saber 11 | C28: =Calidad_Saber11!H7+Calidad_Saber11!H8+Calidad_Saber11!H9 -> 0.84448819

Sheet Parametros
A1: Parámetros del tiempo escolar 2027
A2: EICIT_CMA_1.5.1 · Versión 3 · consenso del 30 de septiembre de 2026 (acta de consenso, tarea 1.5.1). EICIT propone; el Colegio María Auxiliadora de Soacha delibera, decide y adopta (Consejo Académico → Consejo Directivo → resolución rectoral).
B3: Parámetro | C3: Valor | D3: Fuente / nota
B4: Duración de la sesión regular (min) | C4: 55 | D4: Horario base 2027 del Colegio
B5: Sesiones diarias en jornada regular | C5: 7 | D5: Horario base 2027 (06:45–14:30; Horas 1 a 7)
B6: Días de clase por semana | C6: 5 | D6: Horario base 2027
B7: Sesiones semanales en jornada regular | C7: =C5*C6 -> 35 | D7: Cálculo
B8: Duración de la sesión en jornada extendida (min) | C8: 60 | D8: Horario base 2027: 120 min/semana en 10°–11°
B9: Sesiones semanales en jornada extendida (10°–11°) | C9: 2 | D9: Horario base 2027
B11: Escenario 1 · calendario adoptado por el Colegio (días equivalentes) | C11: =IF(LEFT(C32,7)="Semanas",C33*5,Calendario_2027!G11) -> 190 | D11: Según la base de cómputo (C32): semanas lectivas × 5 o días efectivos
B12: Escenario 2 · calendario alternativo de 40 semanas (días equivalentes) | C12: =IF(LEFT(C32,7)="Semanas",C34*5,Calendario_2027_40s!G10) -> 200 | D12: Hoja Calendario_2027_40s
B14: Semanas planeables · Período 1 | C14: 10 | D14: Proyección de cronograma 2027 del Colegio (ver nota de Semana Santa)
B15: Semanas planeables · Período 2 | C15: 9 | D15: Proyección del Colegio
B16: Semanas planeables · Período 3 | C16: 9 | D16: Proyección del Colegio
B17: Semanas planeables · Período 4 | C17: 9 | D17: Proyección del Colegio
B18: Total semanas planeables | C18: =SUM(C14:C17) -> 37 | D18: Las 2 semanas de refuerzo no se planean con contenido nuevo
B20: Mínimos de intensidad en horas efectivas de 60 minutos: Resolución MEN 1730 de 2004 (no oficiales) y Decreto 0277 de 2025 (estatales; referencia de la SEM)
B21: Nivel | C21: Horas semanales | D21: Horas anuales
B22: Preescolar | C22: 20 | D22: 800
B23: Básica primaria | C23: 25 | D23: 1000
B24: Básica secundaria y media académica | C24: 30 | D24: 1200
B25: Proporción mínima de intensidad en áreas obligatorias | C25: 0.8 | D25: Ley 115, arts. 23 y 31; Decreto 1075 de 2015, art. 2.4.3.1.2, par. 1, modificado por el Decreto 0277 de 2025
B26: Proporción máxima de énfasis institucional dentro de cada asignatura | C26: 0.2 | D26: Regla institucional propuesta (tarea 1.5.1) para el campo 80/20 del formato 1.5.2
B27: Cómputo de la sesión y carácter de la media
B28: Criterio de cómputo de la sesión regular | C28: Decreto 0277 de 2025 (55 min + 5 de descanso = 1 h efectiva) | D28: Seleccione. Decreto 0277, art. 2.4.3.1.2, par. 3: 5 min de cada periodo de 60 min son descanso pedagógico. Alternativa: minutos reales (lectura estricta). Ver D-14.
B29: Minutos efectivos por sesión regular | C29: =IF(LEFT(C28,7)="Decreto",60,C4) -> 60 | D29: Cálculo según el criterio
B30: Carácter de la media en 2027 | C30: Media técnica | D30: Seleccione: Media técnica / Media académica
B31: Mínimo media técnica (h semanales / h anuales) | C31: 37 | D31: 1480
B32: Base del cómputo anual | C32: Semanas lectivas del calendario | D32: Acordado: semanas lectivas completas, sin descontar festivos (acta de consenso). Alternativa: días efectivos
B33: Escenario 1 · semanas lectivas del calendario adoptado | C33: 38 | D33: Acordado en el consenso del 30 de septiembre de 2026
B34: Escenario 2 · semanas lectivas del calendario alternativo | C34: =Calendario_2027_40s!F10 -> 40 | D34: Hoja Calendario_2027_40s

Sheet Calendario_2027
A1: Calendario académico 2027 adoptado por el Colegio · 38 semanas lectivas completas
A2: EICIT_CMA_1.5.1 · Versión 3 · consenso del 30 de septiembre de 2026 (acta de consenso, tarea 1.5.1). EICIT propone; el Colegio María Auxiliadora de Soacha delibera, decide y adopta (Consejo Académico → Consejo Directivo → resolución rectoral). Fechas trasladadas a 2027 (el insumo registra 2026 por error de digitación). El cómputo acordado usa semanas completas; los días efectivos se muestran como referencia.
A5: Período | B5: Semanas (Colegio) | C5: Inicio | D5: Fin | E5: Receso: inicio | F5: Receso: fin | G5: Días hábiles efectivos | H5: Observación | J5: Festivos 2027 (Colombia)
A6: Período 1 | B6: 10 | C6: 46420 | D6: 46486 | E6: 46468 | F6: 46472 | G6: =NETWORKDAYS(C6,D6,$J$6:$J$23)-IF(E6="",0,NETWORKDAYS(E6,F6,$J$6:$J$23)) -> 44 | H6: Receso de Semana Santa supuesto (22–26 de marzo). Confirmar. | J6: 46388
A7: Período 2 | B7: 9 | C7: 46490 | D7: 46549 | G7: =NETWORKDAYS(C7,D7,$J$6:$J$23)-IF(E7="",0,NETWORKDAYS(E7,F7,$J$6:$J$23)) -> 41 | H7: Incluye festivos 10 y 31 de mayo y 7 de junio. | J7: 46398
A8: Período 3 | B8: 9 | C8: 46552 | D8: 46633 | E8: 46560 | F8: 46580 | G8: =NETWORKDAYS(C8,D8,$J$6:$J$23)-IF(E8="",0,NETWORKDAYS(E8,F8,$J$6:$J$23)) -> 43 | H8: Receso de mitad de año 22 de junio–12 de julio; festivos 20 de julio y 16 de agosto. | J8: 46468
A9: Período 4 | B9: 9 | C9: 46636 | D9: 46703 | E9: 46671 | F9: 46675 | G9: =NETWORKDAYS(C9,D9,$J$6:$J$23)-IF(E9="",0,NETWORKDAYS(E9,F9,$J$6:$J$23)) -> 43 | H9: Receso 11–15 de octubre; festivos 18 de octubre y 1 de noviembre. | J9: 46471
A10: Refuerzos y recuperaciones | B10: 2 | C10: 46707 | D10: 46717 | G10: =NETWORKDAYS(C10,D10,$J$6:$J$23)-IF(E10="",0,NETWORKDAYS(E10,F10,$J$6:$J$23)) -> 9 | H10: Cuenta como trabajo académico solo si asisten todos los estudiantes. | J10: 46472
A11: Total | G11: =SUM(G6:G10) -> 180 | J11: 46508
A12: Semanas equivalentes (días ÷ 5) | G12: =G11/5 -> 36 | J12: 46517
A13: Brecha frente a 40 semanas (200 días) | G13: =200-G11 -> 20 | J13: 46538
J14: 46545
A15: Nota: Formación Salesiana (15 min diarios) no se computa como intensidad de área. | J15: 46573
J16: 46588
J17: 46606
J18: 46615
J19: 46678
J20: 46692
J21: 46706
J22: 46729
J23: 46746

Sheet Calendario_2027_40s
A1: Calendario 2027 de 40 semanas · alternativa presentada (Escenario 2)
A2: EICIT_CMA_1.5.1 · Versión 3 · consenso del 30 de septiembre de 2026 (acta de consenso, tarea 1.5.1). EICIT propone; el Colegio María Auxiliadora de Soacha delibera, decide y adopta (Consejo Académico → Consejo Directivo → resolución rectoral).
A3: Alternativa presentada el 30 de septiembre de 2026; el Colegio adoptó 38 semanas lectivas completas (Escenario 1). Se conserva como referencia de contingencia. Cuatro períodos de 10 semanas lectivas; inicio el 25 de enero; receso de mitad de año de 2 semanas; semana de receso de octubre (Decreto 1373 de 2007); refuerzo integrado al Período 4 como semanas de profundización y nivelación con todos los estudiantes. Jornada extendida de 10°–11° en miércoles y jueves (sin festivos en semanas lectivas).
A5: Período | B5: Inicio | C5: Fin | D5: Receso: inicio | E5: Receso: fin | F5: Semanas lectivas | G5: Días efectivos | H5: Miércoles lectivos | I5: Jueves lectivos | J5: Observación
A6: Período 1 | B6: 46412 | C6: 46486 | D6: 46468 | E6: 46472 | F6: 10 | G6: =NETWORKDAYS(B6,C6,Calendario_2027!$J$6:$J$23)-IF(D6="",0,NETWORKDAYS(D6,E6,Calendario_2027!$J$6:$J$23)) -> 50 | H6: =NETWORKDAYS.INTL(B6,C6,"1101111",Calendario_2027!$J$6:$J$23)-IF(D6="",0,NETWORKDAYS.INTL(D6,E6,"1101111",Calendario_2027!$J$6:$J$23)) -> 10 | I6: =NETWORKDAYS.INTL(B6,C6,"1110111",Calendario_2027!$J$6:$J$23)-IF(D6="",0,NETWORKDAYS.INTL(D6,E6,"1110111",Calendario_2027!$J$6:$J$23)) -> 10 | J6: Receso de Semana Santa (22–26 de marzo).
A7: Período 2 | B7: 46489 | C7: 46556 | F7: 10 | G7: =NETWORKDAYS(B7,C7,Calendario_2027!$J$6:$J$23)-IF(D7="",0,NETWORKDAYS(D7,E7,Calendario_2027!$J$6:$J$23)) -> 47 | H7: =NETWORKDAYS.INTL(B7,C7,"1101111",Calendario_2027!$J$6:$J$23)-IF(D7="",0,NETWORKDAYS.INTL(D7,E7,"1101111",Calendario_2027!$J$6:$J$23)) -> 10 | I7: =NETWORKDAYS.INTL(B7,C7,"1110111",Calendario_2027!$J$6:$J$23)-IF(D7="",0,NETWORKDAYS.INTL(D7,E7,"1110111",Calendario_2027!$J$6:$J$23)) -> 10 | J7: Festivos 10 y 31 de mayo y 7 de junio.
A8: Período 3 | B8: 46574 | C8: 46640 | F8: 10 | G8: =NETWORKDAYS(B8,C8,Calendario_2027!$J$6:$J$23)-IF(D8="",0,NETWORKDAYS(D8,E8,Calendario_2027!$J$6:$J$23)) -> 47 | H8: =NETWORKDAYS.INTL(B8,C8,"1101111",Calendario_2027!$J$6:$J$23)-IF(D8="",0,NETWORKDAYS.INTL(D8,E8,"1101111",Calendario_2027!$J$6:$J$23)) -> 10 | I8: =NETWORKDAYS.INTL(B8,C8,"1110111",Calendario_2027!$J$6:$J$23)-IF(D8="",0,NETWORKDAYS.INTL(D8,E8,"1110111",Calendario_2027!$J$6:$J$23)) -> 10 | J8: Inicia el martes 6 de julio (5 de julio festivo). Saber 11 calendario A: agosto, fecha por confirmar ICFES.
A9: Período 4 | B9: 46643 | C9: 46717 | D9: 46671 | E9: 46675 | F9: 10 | G9: =NETWORKDAYS(B9,C9,Calendario_2027!$J$6:$J$23)-IF(D9="",0,NETWORKDAYS(D9,E9,Calendario_2027!$J$6:$J$23)) -> 47 | H9: =NETWORKDAYS.INTL(B9,C9,"1101111",Calendario_2027!$J$6:$J$23)-IF(D9="",0,NETWORKDAYS.INTL(D9,E9,"1101111",Calendario_2027!$J$6:$J$23)) -> 10 | I9: =NETWORKDAYS.INTL(B9,C9,"1110111",Calendario_2027!$J$6:$J$23)-IF(D9="",0,NETWORKDAYS.INTL(D9,E9,"1110111",Calendario_2027!$J$6:$J$23)) -> 10 | J9: Receso de octubre 11–15. Semanas 16–26 de noviembre: profundización y nivelación con todos los estudiantes.
A10: Total | F10: =SUM(F6:F9) -> 40 | G10: =SUM(G6:G9) -> 191 | H10: =SUM(H6:H9) -> 40 | I10: =SUM(I6:I9) -> 40
A12: Nivel | B12: Sesiones regulares/sem | C12: Horas extendidas/sem | D12: Lectura de la sesión | E12: Horas/año · por semanas | F12: Horas/año · por días | G12: Mínimo anual | H12: ¿Cumple por semanas? | I12: ¿Cumple por días?
A13: Transición a 9° | B13: 35 | C13: 0 | D13: Decreto 0277 | E13: =(B13*60/60+C13)*$F$10 -> 1400 | F13: =$G$10*B13/5*60/60+0 -> 1337 | G13: 1200 | H13: =IF(E13>=G13,"Cumple","No cumple") -> Cumple | I13: =IF(F13>=G13,"Cumple","No cumple") -> Cumple
A14: Transición a 9° | B14: 35 | C14: 0 | D14: Estricta | E14: =(B14*55/60+C14)*$F$10 -> 1283.3333 | F14: =$G$10*B14/5*55/60+0 -> 1225.5833 | G14: 1200 | H14: =IF(E14>=G14,"Cumple","No cumple") -> Cumple | I14: =IF(F14>=G14,"Cumple","No cumple") -> Cumple
A15: 10°–11° media técnica · extendida 2 h (miércoles) | B15: 35 | C15: 2 | D15: Decreto 0277 | E15: =(B15*60/60+C15)*$F$10 -> 1480 | F15: =$G$10*B15/5*60/60+2*($H$10) -> 1417 | G15: 1480 | H15: =IF(E15>=G15,"Cumple","No cumple") -> Cumple | I15: =IF(F15>=G15,"Cumple","No cumple") -> No cumple
A16: 10°–11° media técnica · extendida 2 h (miércoles) | B16: 35 | C16: 2 | D16: Estricta | E16: =(B16*55/60+C16)*$F$10 -> 1363.3333 | F16: =$G$10*B16/5*55/60+2*($H$10) -> 1305.5833 | G16: 1480 | H16: =IF(E16>=G16,"Cumple","No cumple") -> No cumple | I16: =IF(F16>=G16,"Cumple","No cumple") -> No cumple
A17: 10°–11° media técnica · extendida 4 h (miércoles y jueves) | B17: 35 | C17: 4 | D17: Decreto 0277 | E17: =(B17*60/60+C17)*$F$10 -> 1560 | F17: =$G$10*B17/5*60/60+4/2*($H$10+$I$10) -> 1497 | G17: 1480 | H17: =IF(E17>=G17,"Cumple","No cumple") -> Cumple | I17: =IF(F17>=G17,"Cumple","No cumple") -> Cumple
A18: 10°–11° media técnica · extendida 5 h (miércoles y jueves) | B18: 35 | C18: 5 | D18: Estricta | E18: =(B18*55/60+C18)*$F$10 -> 1483.3333 | F18: =$G$10*B18/5*55/60+5/2*($H$10+$I$10) -> 1425.5833 | G18: 1480 | H18: =IF(E18>=G18,"Cumple","No cumple") -> Cumple | I18: =IF(F18>=G18,"Cumple","No cumple") -> No cumple
A19: «Por semanas»: intensidad semanal × semanas lectivas del calendario (práctica usual de verificación). «Por días»: días efectivos descontados festivos (lectura prudencial). Transición a 9°: mínimo de secundaria (1.200 h), el más exigente del tramo.
A22: Hito o tiempo institucional | B22: Fechas | C22: Tipo
A23: Desarrollo institucional de inicio de año | B23: 12–22 de enero | C23: Desarrollo institucional
A24: Inicio de clases | B24: 25 de enero | C24: Hito
A25: Receso de Semana Santa | B25: 22–26 de marzo | C25: Receso estudiantil
A26: Cierre Período 1 · informes | B26: 9 de abril | C26: Hito
A27: Cierre Período 2 · informes | B27: 18 de junio | C27: Hito
A28: Desarrollo institucional de mitad de año | B28: 21–25 de junio | C28: Desarrollo institucional
A29: Receso de mitad de año (estudiantes) | B29: 21 de junio – 2 de julio | C29: Receso estudiantil
A30: Reinicio de clases | B30: 6 de julio | C30: Hito
A31: Saber 11 (calendario A) | B31: Agosto · fecha por confirmar ICFES | C31: Hito
A32: Cierre Período 3 · informes | B32: 10 de septiembre | C32: Hito
A33: Receso de octubre / desarrollo institucional | B33: 11–15 de octubre | C33: Receso estudiantil
... A35: Comisiones de evaluación y promoción, clausura y planeación 2028 | B35: 29 de noviembre – 10 de diciembre | C35: Desarrollo institucional
A37: Desarrollo institucional: 6 semanas (12–22 ene; 21–25 jun; 11–15 oct; 29 nov–10 dic). Las vacaciones docentes y la distribución exacta las fija la Rectoría según los contratos laborales.

Sheet Vista_mensual_2027
A1: Calendario 2027 de 40 semanas · vista mensual (alternativa, Escenario 2)
A2: EICIT_CMA_1.5.1 · Versión 3 · consenso del 30 de septiembre de 2026 (acta de consenso, tarea 1.5.1). EICIT propone; el Colegio María Auxiliadora de Soacha delibera, decide y adopta (Consejo Académico → Consejo Directivo → resolución rectoral).
A4: Convenciones: | J4: Lectivo | O4: Festivo | T4: Receso estudiantil | Y4: Desarrollo institucional
A5: Enero | I5: Febrero | Q5: Marzo | Y5: Abril
A6: L | B6: M | C6: M | D6: J | E6: V | F6: S | G6: D | I6: L | J6: M | K6: M | L6: J | M6: V | N6: S | O6: D | Q6: L | R6: M | S6: M | T6: J | U6: V | V6: S | W6: D | Y6: L | Z6: M | AA6: M | AB6: J | AC6: V | AD6: S | AE6: D
E7: 1 | F7: 2 | G7: 3 | I7: 1 | J7: 2 | K7: 3 | L7: 4 | M7: 5 | N7: 6 | O7: 7 | Q7: 1 | R7: 2 | S7: 3 | T7: 4 | U7: 5 | V7: 6 | W7: 7 | AB7: 1 | AC7: 2 | AD7: 3 | AE7: 4
A8: 4 | B8: 5 | C8: 6 | D8: 7 | E8: 8 | F8: 9 | G8: 10 | I8: 8 | J8: 9 | K8: 10 | L8: 11 | M8: 12 | N8: 13 | O8: 14 | Q8: 8 | R8: 9 | S8: 10 | T8: 11 | U8: 12 | V8: 13 | W8: 14 | Y8: 5 | Z8: 6 | AA8: 7 | AB8: 8 | AC8: 9 | AD8: 10 | AE8: 11
A9: 11 | B9: 12 | C9: 13 | D9: 14 | E9: 15 | F9: 16 | G9: 17 | I9: 15 | J9: 16 | K9: 17 | L9: 18 | M9: 19 | N9: 20 | O9: 21 | Q9: 15 | R9: 16 | S9: 17 | T9: 18 | U9: 19 | V9: 20 | W9: 21 | Y9: 12 | Z9: 13 | AA9: 14 | AB9: 15 | AC9: 16 | AD9: 17 | AE9: 18
A10: 18 | B10: 19 | C10: 20 | D10: 21 | E10: 22 | F10: 23 | G10: 24 | I10: 22 | J10: 23 | K10: 24 | L10: 25 | M10: 26 | N10: 27 | O10: 28 | Q10: 22 | R10: 23 | S10: 24 | T10: 25 | U10: 26 | V10: 27 | W10: 28 | Y10: 19 | Z10: 20 | AA10: 21 | AB10: 22 | AC10: 23 | AD10: 24 | AE10: 25
A11: 25 | B11: 26 | C11: 27 | D11: 28 | E11: 29 | F11: 30 | G11: 31 | Q11: 29 | R11: 30 | S11: 31 | Y11: 26 | Z11: 27 | AA11: 28 | AB11: 29 | AC11: 30
A14: Mayo | I14: Junio | Q14: Julio | Y14: Agosto
A15: L | B15: M | C15: M | D15: J | E15: V | F15: S | G15: D | I15: L | J15: M | K15: M | L15: J | M15: V | N15: S | O15: D | Q15: L | R15: M | S15: M | T15: J | U15: V | V15: S | W15: D | Y15: L | Z15: M | AA15: M | AB15: J | AC15: V | AD15: S | AE15: D
F16: 1 | G16: 2 | J16: 1 | K16: 2 | L16: 3 | M16: 4 | N16: 5 | O16: 6 | T16: 1 | U16: 2 | V16: 3 | W16: 4 | AE16: 1
A17: 3 | B17: 4 | C17: 5 | D17: 6 | E17: 7 | F17: 8 | G17: 9 | I17: 7 | J17: 8 | K17: 9 | L17: 10 | M17: 11 | N17: 12 | O17: 13 | Q17: 5 | R17: 6 | S17: 7 | T17: 8 | U17: 9 | V17: 10 | W17: 11 | Y17: 2 | Z17: 3 | AA17: 4 | AB17: 5 | AC17: 6 | AD17: 7 | AE17: 8
A18: 10 | B18: 11 | C18: 12 | D18: 13 | E18: 14 | F18: 15 | G18: 16 | I18: 14 | J18: 15 | K18: 16 | L18: 17 | M18: 18 | N18: 19 | O18: 20 | Q18: 12 | R18: 13 | S18: 14 | T18: 15 | U18: 16 | V18: 17 | W18: 18 | Y18: 9 | Z18: 10 | AA18: 11 | AB18: 12 | AC18: 13 | AD18: 14 | AE18: 15
A19: 17 | B19: 18 | C19: 19 | D19: 20 | E19: 21 | F19: 22 | G19: 23 | I19: 21 | J19: 22 | K19: 23 | L19: 24 | M19: 25 | N19: 26 | O19: 27 | Q19: 19 | R19: 20 | S19: 21 | T19: 22 | U19: 23 | V19: 24 | W19: 25 | Y19: 16 | Z19: 17 | AA19: 18 | AB19: 19 | AC19: 20 | AD19: 21 | AE19: 22
A20: 24 | B20: 25 | C20: 26 | D20: 27 | E20: 28 | F20: 29 | G20: 30 | I20: 28 | J20: 29 | K20: 30 | Q20: 26 | R20: 27 | S20: 28 | T20: 29 | U20: 30 | V20: 31 | Y20: 23 | Z20: 24 | AA20: 25 | AB20: 26 | AC20: 27 | AD20: 28 | AE20: 29
A21: 31 | Y21: 30 | Z21: 31
A23: Septiembre | I23: Octubre | Q23: Noviembre | Y23: Diciembre
A24: L | B24: M | C24: M | D24: J | E24: V | F24: S | G24: D | I24: L | J24: M | K24: M | L24: J | M24: V | N24: S | O24: D | Q24: L | R24: M | S24: M | T24: J | U24: V | V24: S | W24: D | Y24: L | Z24: M | AA24: M | AB24: J | AC24: V | AD24: S | AE24: D
C25: 1 | D25: 2 | E25: 3 | F25: 4 | G25: 5 | M25: 1 | N25: 2 | O25: 3 | Q25: 1 | R25: 2 | S25: 3 | T25: 4 | U25: 5 | V25: 6 | W25: 7 | AA25: 1 | AB25: 2 | AC25: 3 | AD25: 4 | AE25: 5
A26: 6 | B26: 7 | C26: 8 | D26: 9 | E26: 10 | F26: 11 | G26: 12 | I26: 4 | J26: 5 | K26: 6 | L26: 7 | M26: 8 | N26: 9 | O26: 10 | Q26: 8 | R26: 9 | S26: 10 | T26: 11 | U26: 12 | V26: 13 | W26: 14 | Y26: 6 | Z26: 7 | AA26: 8 | AB26: 9 | AC26: 10 | AD26: 11 | AE26: 12
A27: 13 | B27: 14 | C27: 15 | D27: 16 | E27: 17 | F27: 18 | G27: 19 | I27: 11 | J27: 12 | K27: 13 | L27: 14 | M27: 15 | N27: 16 | O27: 17 | Q27: 15 | R27: 16 | S27: 17 | T27: 18 | U27: 19 | V27: 20 | W27: 21 | Y27: 13 | Z27: 14 | AA27: 15 | AB27: 16 | AC27: 17 | AD27: 18 | AE27: 19
A28: 20 | B28: 21 | C28: 22 | D28: 23 | E28: 24 | F28: 25 | G28: 26 | I28: 18 | J28: 19 | K28: 20 | L28: 21 | M28: 22 | N28: 23 | O28: 24 | Q28: 22 | R28: 23 | S28: 24 | T28: 25 | U28: 26 | V28: 27 | W28: 28 | Y28: 20 | Z28: 21 | AA28: 22 | AB28: 23 | AC28: 24 | AD28: 25 | AE28: 26
A29: 27 | B29: 28 | C29: 29 | D29: 30 | I29: 25 | J29: 26 | K29: 27 | L29: 28 | M29: 29 | N29: 30 | O29: 31 | Q29: 29 | R29: 30 | Y29: 27 | Z29: 28 | AA29: 29 | AB29: 30 | AC29: 31

Sheet Malla_2027
A1: Malla por horas 2027 · distribución semanal por asignatura y grado (definitiva, consenso)
A2: EICIT_CMA_1.5.1 · Versión 3 · consenso del 30 de septiembre de 2026 (acta de consenso, tarea 1.5.1). EICIT propone; el Colegio María Auxiliadora de Soacha delibera, decide y adopta (Consejo Académico → Consejo Directivo → resolución rectoral).
A3: Convenciones: celdas de intensidad en azul = datos editables por el Colegio. Tipo «Obligatoria» = áreas de los arts. 23 y 31 de la Ley 115. Básica y media en esta tabla; Transición en la tabla inferior.
A5: Código | B5: Área (Ley 115) | C5: Asignatura | D5: Tipo | E5: 1° | F5: 2° | G5: 3° | H5: 4° | I5: 5° | J5: 6° | K5: 7° | L5: 8° | M5: 9° | N5: 10° | O5: 11° | P5: Total | Q5: Duración efectiva (min) | R5: Observación
A6: CNA | B6: Ciencias Naturales y Educación Ambiental | C6: Ciencias Naturales y Educación Ambiental | D6: Obligatoria (art. 23) | E6: 4 | F6: 4 | G6: 4 | H6: 4 | I6: 4 | J6: 4 | K6: 4 | L6: 4 | M6: 4 | N6: 0 | O6: 0 | P6: =SUM(E6:O6) -> 36 | Q6: =Parametros!$C$29 -> 60 | R6: Sin cambio.
A7: QUI | B7: Ciencias Naturales y Educación Ambiental | C7: Química | D7: Obligatoria (art. 23) | E7: 0 | F7: 0 | G7: 0 | H7: 0 | I7: 0 | J7: 0 | K7: 0 | L7: 0 | M7: 0 | N7: 3 | O7: 3 | P7: =SUM(E7:O7) -> 6 | Q7: =Parametros!$C$29 -> 60 | R7: Integra el componente biológico y CTS que evalúa Saber 11.
A8: FIS | B8: Ciencias Naturales y Educación Ambiental | C8: Física | D8: Obligatoria (art. 23) | E8: 0 | F8: 0 | G8: 0 | H8: 0 | I8: 0 | J8: 0 | K8: 0 | L8: 0 | M8: 0 | N8: 3 | O8: 3 | P8: =SUM(E8:O8) -> 6 | Q8: =Parametros!$C$29 -> 60 | R8: Ubicada en Ciencias Naturales y Educación Ambiental (consenso).
A9: SOC | B9: Ciencias Sociales, Historia, Geografía, Constitución Política y Democracia | C9: Ciencias Sociales | D9: Obligatoria (art. 23) | E9: 4 | F9: 4 | G9: 4 | H9: 4 | I9: 4 | J9: 5 | K9: 5 | L9: 5 | M9: 5 | N9: 0 | O9: 0 | P9: =SUM(E9:O9) -> 40 | Q9: =Parametros!$C$29 -> 60 | R9: Historia de Colombia integrada y reforzada como disciplina (Ley 1874 de 2017).
A10: CEP | B10: Ciencias Sociales, Historia, Geografía, Constitución Política y Democracia | C10: Ciencias Económicas y Políticas | D10: Obligatoria media (art. 31) | E10: 0 | F10: 0 | G10: 0 | H10: 0 | I10: 0 | J10: 0 | K10: 0 | L10: 0 | M10: 0 | N10: 2 | O10: 2 | P10: =SUM(E10:O10) -> 4 | Q10: =Parametros!$C$29 -> 60 | R10: Da continuidad a Ciencias Sociales en la media, con historia de Colombia integrada.
A11: FIL | B11: Filosofía | C11: Filosofía | D11: Obligatoria media (art. 31) | E11: 0 | F11: 0 | G11: 0 | H11: 0 | I11: 0 | J11: 0 | K11: 0 | L11: 0 | M11: 0 | N11: 2 | O11: 2 | P11: =SUM(E11:O11) -> 4 | Q11: =Parametros!$C$29 -> 60 | R11: Aporta a Lectura Crítica.
A12: ART | B12: Educación Artística y Cultural | C12: Artes plásticas | D12: Obligatoria (art. 23) | E12: 1 | F12: 1 | G12: 1 | H12: 1 | I12: 1 | J12: 1 | K12: 1 | L12: 1 | M12: 0 | N12: 0 | O12: 0 | P12: =SUM(E12:O12) -> 8 | Q12: =Parametros!$C$29 -> 60 | R12: 1 h en 1°–8°; sin asignación en 9° (el área continúa con Música y Danzas).
A13: MUS | B13: Educación Artística y Cultural | C13: Música | D13: Obligatoria (art. 23) | E13: 1 | F13: 1 | G13: 1 | H13: 1 | I13: 1 | J13: 1 | K13: 1 | L13: 1 | M13: 1 | N13: 1 | O13: 1 | P13: =SUM(E13:O13) -> 11 | Q13: =Parametros!$C$29 -> 60 | R13: Sin cambio.
A14: DAN | B14: Educación Artística y Cultural | C14: Danzas | D14: Obligatoria (art. 23) | E14: 1 | F14: 1 | G14: 1 | H14: 1 | I14: 1 | J14: 1 | K14: 1 | L14: 1 | M14: 1 | N14: 1 | O14: 1 | P14: =SUM(E14:O14) -> 11 | Q14: =Parametros!$C$29 -> 60 | R14: Sin cambio.
A15: ETI | B15: Educación Ética y en Valores Humanos | C15: Ética y Valores Humanos | D15: Obligatoria (art. 23) | E15: 1 | F15: 1 | G15: 1 | H15: 1 | I15: 1 | J15: 1 | K15: 1 | L15: 1 | M15: 1 | N15: 2 | O15: 2 | P15: =SUM(E15:O15) -> 13 | Q15: =Parametros!$C$29 -> 60 | R15: Incluye las competencias ciudadanas.
A16: EFI | B16: Educación Física, Recreación y Deportes | C16: Educación Física, Recreación y Deportes | D16: Obligatoria (art. 23) | E16: 2 | F16: 2 | G16: 2 | H16: 2 | I16: 2 | J16: 2 | K16: 2 | L16: 2 | M16: 2 | N16: 1 | O16: 1 | P16: =SUM(E16:O16) -> 20 | Q16: =Parametros!$C$29 -> 60 | R16: 2 h en 1°–9°; 1 h en la media.
A17: ERE | B17: Educación Religiosa | C17: Educación Religiosa Escolar | D17: Obligatoria (art. 23) | E17: 3 | F17: 3 | G17: 3 | H17: 3 | I17: 3 | J17: 3 | K17: 3 | L17: 3 | M17: 3 | N17: 3 | O17: 3 | P17: =SUM(E17:O17) -> 33 | Q17: =Parametros!$C$29 -> 60 | R17: Sin cambio.
... A27: MTR | B27: Especialidad media técnica | C27: Media técnica: Programación para Analítica de Datos (jornada regular) | D27: Especialidad media técnica (art. 32) | E27: 0 | F27: 0 | G27: 0 | H27: 0 | I27: 0 | J27: 0 | K27: 0 | L27: 0 | M27: 0 | N27: 2 | O27: 2 | P27: =SUM(E27:O27) -> 4 | Q27: =Parametros!$C$29 -> 60 | R27: Componente SENA (programa 228117): 2 h en jornada regular.
A28: MTE | B28: Especialidad media técnica | C28: Media técnica: Programación para Analítica de Datos (jornada extendida) | D28: Especialidad media técnica (art. 32) | E28: 0 | F28: 0 | G28: 0 | H28: 0 | I28: 0 | J28: 0 | K28: 0 | L28: 0 | M28: 0 | N28: 2 | O28: 2 | P28: =SUM(E28:O28) -> 4 | Q28: =Parametros!$C$8 -> 60 | R28: 2 h en jornada extendida (120 min semanales).
C30: Total de sesiones semanales | E30: =SUM(E6:E28) -> 35 | F30: =SUM(F6:F28) -> 35 | G30: =SUM(G6:G28) -> 35 | H30: =SUM(H6:H28) -> 35 | I30: =SUM(I6:I28) -> 35 | J30: =SUM(J6:J28) -> 35 | K30: =SUM(K6:K28) -> 35 | L30: =SUM(L6:L28) -> 35 | ... O30: =SUM(O6:O28) -> 37
C31: Sesiones disponibles en la jornada | E31: 35 | F31: 35 | G31: 35 | H31: 35 | I31: 35 | J31: 35 | K31: 35 | L31: 35 | M31: 35 | N31: 37 | O31: 37
C32: Diferencia | E32: =E31-E30 -> 0 | F32: =F31-F30 -> 0 | G32: =G31-G30 -> 0 | H32: =H31-H30 -> 0 | I32: =I31-I30 -> 0 | J32: =J31-J30 -> 0 | K32: =K31-K30 -> 0 | L32: =L31-L30 -> 0 | ... O32: =O31-O30 -> 0
C33: Control | E33: =IF(E32=0,"OK","REVISAR") -> OK | F33: =IF(F32=0,"OK","REVISAR") -> OK | G33: =IF(G32=0,"OK","REVISAR") -> OK | H33: =IF(H32=0,"OK","REVISAR") -> OK | I33: =IF(I32=0,"OK","REVISAR") -> OK | J33: =IF(J32=0,"OK","REVISAR") -> OK | K33: =IF(K32=0,"OK","REVISAR") -> OK | L33: =IF(L32=0,"OK","REVISAR") -> OK | ... O33: =IF(O32=0,"OK","REVISAR") -> OK
C34: Sesiones en áreas obligatorias | E34: =SUMIF($D$6:$D$28,"Obligatoria*",E6:E28) -> 34 | F34: =SUMIF($D$6:$D$28,"Obligatoria*",F6:F28) -> 34 | G34: =SUMIF($D$6:$D$28,"Obligatoria*",G6:G28) -> 34 | H34: =SUMIF($D$6:$D$28,"Obligatoria*",H6:H28) -> 34 | I34: =SUMIF($D$6:$D$28,"Obligatoria*",I6:I28) -> 34 | J34: =SUMIF($D$6:$D$28,"Obligatoria*",J6:J28) -> 35 | K34: =SUMIF($D$6:$D$28,"Obligatoria*",K6:K28) -> 35 | L34: =SUMIF($D$6:$D$28,"Obligatoria*",L6:L28) -> 35 | ... O34: =SUMIF($D$6:$D$28,"Obligatoria*",O6:O28) -> 33
C35: Proporción en áreas obligatorias | E35: =E34/E30 -> 0.97142857 | F35: =F34/F30 -> 0.97142857 | G35: =G34/G30 -> 0.97142857 | H35: =H34/H30 -> 0.97142857 | I35: =I34/I30 -> 0.97142857 | J35: =J34/J30 -> 1 | K35: =K34/K30 -> 1 | L35: =L34/L30 -> 1 | ... O35: =O34/O30 -> 0.89189189
C36: Minutos semanales de clase | E36: =SUMPRODUCT(E6:E28,$Q$6:$Q$28) -> 2100 | F36: =SUMPRODUCT(F6:F28,$Q$6:$Q$28) -> 2100 | G36: =SUMPRODUCT(G6:G28,$Q$6:$Q$28) -> 2100 | H36: =SUMPRODUCT(H6:H28,$Q$6:$Q$28) -> 2100 | I36: =SUMPRODUCT(I6:I28,$Q$6:$Q$28) -> 2100 | J36: =SUMPRODUCT(J6:J28,$Q$6:$Q$28) -> 2100 | K36: =SUMPRODUCT(K6:K28,$Q$6:$Q$28) -> 2100 | L36: =SUMPRODUCT(L6:L28,$Q$6:$Q$28) -> 2100 | ... O36: =SUMPRODUCT(O6:O28,$Q$6:$Q$28) -> 2220
A38: Resumen por área o componente (sesiones semanales)
B39: Área o componente | E39: 2° | F39: 3° | G39: 4° | H39: 5° | I39: 6° | J39: 7° | K39: 8° | L39: 9° | M39: 10° | N39: 11°
B40: Ciencias Naturales y Educación Ambiental | E40: =SUMIF($B$6:$B$28,$B40,E$6:E$28) -> 4 | F40: =SUMIF($B$6:$B$28,$B40,F$6:F$28) -> 4 | G40: =SUMIF($B$6:$B$28,$B40,G$6:G$28) -> 4 | H40: =SUMIF($B$6:$B$28,$B40,H$6:H$28) -> 4 | I40: =SUMIF($B$6:$B$28,$B40,I$6:I$28) -> 4 | J40: =SUMIF($B$6:$B$28,$B40,J$6:J$28) -> 4 | K40: =SUMIF($B$6:$B$28,$B40,K$6:K$28) -> 4 | L40: =SUMIF($B$6:$B$28,$B40,L$6:L$28) -> 4 | ... O40: =SUMIF($B$6:$B$28,$B40,O$6:O$28) -> 6
B41: Ciencias Sociales, Historia, Geografía, Constitución Política y Democracia | E41: =SUMIF($B$6:$B$28,$B41,E$6:E$28) -> 4 | F41: =SUMIF($B$6:$B$28,$B41,F$6:F$28) -> 4 | G41: =SUMIF($B$6:$B$28,$B41,G$6:G$28) -> 4 | H41: =SUMIF($B$6:$B$28,$B41,H$6:H$28) -> 4 | I41: =SUMIF($B$6:$B$28,$B41,I$6:I$28) -> 4 | J41: =SUMIF($B$6:$B$28,$B41,J$6:J$28) -> 5 | K41: =SUMIF($B$6:$B$28,$B41,K$6:K$28) -> 5 | L41: =SUMIF($B$6:$B$28,$B41,L$6:L$28) -> 5 | ... O41: =SUMIF($B$6:$B$28,$B41,O$6:O$28) -> 2
B42: Filosofía | E42: =SUMIF($B$6:$B$28,$B42,E$6:E$28) -> 0 | F42: =SUMIF($B$6:$B$28,$B42,F$6:F$28) -> 0 | G42: =SUMIF($B$6:$B$28,$B42,G$6:G$28) -> 0 | H42: =SUMIF($B$6:$B$28,$B42,H$6:H$28) -> 0 | I42: =SUMIF($B$6:$B$28,$B42,I$6:I$28) -> 0 | J42: =SUMIF($B$6:$B$28,$B42,J$6:J$28) -> 0 | K42: =SUMIF($B$6:$B$28,$B42,K$6:K$28) -> 0 | L42: =SUMIF($B$6:$B$28,$B42,L$6:L$28) -> 0 | ... O42: =SUMIF($B$6:$B$28,$B42,O$6:O$28) -> 2
B43: Educación Artística y Cultural | E43: =SUMIF($B$6:$B$28,$B43,E$6:E$28) -> 3 | F43: =SUMIF($B$6:$B$28,$B43,F$6:F$28) -> 3 | G43: =SUMIF($B$6:$B$28,$B43,G$6:G$28) -> 3 | H43: =SUMIF($B$6:$B$28,$B43,H$6:H$28) -> 3 | I43: =SUMIF($B$6:$B$28,$B43,I$6:I$28) -> 3 | J43: =SUMIF($B$6:$B$28,$B43,J$6:J$28) -> 3 | K43: =SUMIF($B$6:$B$28,$B43,K$6:K$28) -> 3 | L43: =SUMIF($B$6:$B$28,$B43,L$6:L$28) -> 3 | ... O43: =SUMIF($B$6:$B$28,$B43,O$6:O$28) -> 2
B44: Educación Ética y en Valores Humanos | E44: =SUMIF($B$6:$B$28,$B44,E$6:E$28) -> 1 | F44: =SUMIF($B$6:$B$28,$B44,F$6:F$28) -> 1 | G44: =SUMIF($B$6:$B$28,$B44,G$6:G$28) -> 1 | H44: =SUMIF($B$6:$B$28,$B44,H$6:H$28) -> 1 | I44: =SUMIF($B$6:$B$28,$B44,I$6:I$28) -> 1 | J44: =SUMIF($B$6:$B$28,$B44,J$6:J$28) -> 1 | K44: =SUMIF($B$6:$B$28,$B44,K$6:K$28) -> 1 | L44: =SUMIF($B$6:$B$28,$B44,L$6:L$28) -> 1 | ... O44: =SUMIF($B$6:$B$28,$B44,O$6:O$28) -> 2
B45: Educación Física, Recreación y Deportes | E45: =SUMIF($B$6:$B$28,$B45,E$6:E$28) -> 2 | F45: =SUMIF($B$6:$B$28,$B45,F$6:F$28) -> 2 | G45: =SUMIF($B$6:$B$28,$B45,G$6:G$28) -> 2 | H45: =SUMIF($B$6:$B$28,$B45,H$6:H$28) -> 2 | I45: =SUMIF($B$6:$B$28,$B45,I$6:I$28) -> 2 | J45: =SUMIF($B$6:$B$28,$B45,J$6:J$28) -> 2 | K45: =SUMIF($B$6:$B$28,$B45,K$6:K$28) -> 2 | L45: =SUMIF($B$6:$B$28,$B45,L$6:L$28) -> 2 | ... O45: =SUMIF($B$6:$B$28,$B45,O$6:O$28) -> 1
B46: Educación Religiosa | E46: =SUMIF($B$6:$B$28,$B46,E$6:E$28) -> 3 | F46: =SUMIF($B$6:$B$28,$B46,F$6:F$28) -> 3 | G46: =SUMIF($B$6:$B$28,$B46,G$6:G$28) -> 3 | H46: =SUMIF($B$6:$B$28,$B46,H$6:H$28) -> 3 | I46: =SUMIF($B$6:$B$28,$B46,I$6:I$28) -> 3 | J46: =SUMIF($B$6:$B$28,$B46,J$6:J$28) -> 3 | K46: =SUMIF($B$6:$B$28,$B46,K$6:K$28) -> 3 | L46: =SUMIF($B$6:$B$28,$B46,L$6:L$28) -> 3 | ... O46: =SUMIF($B$6:$B$28,$B46,O$6:O$28) -> 3
B47: Humanidades: Lengua Castellana e Idiomas Extranjeros | E47: =SUMIF($B$6:$B$28,$B47,E$6:E$28) -> 9 | F47: =SUMIF($B$6:$B$28,$B47,F$6:F$28) -> 9 | G47: =SUMIF($B$6:$B$28,$B47,G$6:G$28) -> 9 | H47: =SUMIF($B$6:$B$28,$B47,H$6:H$28) -> 9 | I47: =SUMIF($B$6:$B$28,$B47,I$6:I$28) -> 9 | J47: =SUMIF($B$6:$B$28,$B47,J$6:J$28) -> 9 | K47: =SUMIF($B$6:$B$28,$B47,K$6:K$28) -> 9 | L47: =SUMIF($B$6:$B$28,$B47,L$6:L$28) -> 9 | ... O47: =SUMIF($B$6:$B$28,$B47,O$6:O$28) -> 9
B48: Matemáticas | E48: =SUMIF($B$6:$B$28,$B48,E$6:E$28) -> 5 | F48: =SUMIF($B$6:$B$28,$B48,F$6:F$28) -> 5 | G48: =SUMIF($B$6:$B$28,$B48,G$6:G$28) -> 5 | H48: =SUMIF($B$6:$B$28,$B48,H$6:H$28) -> 5 | I48: =SUMIF($B$6:$B$28,$B48,I$6:I$28) -> 5 | J48: =SUMIF($B$6:$B$28,$B48,J$6:J$28) -> 5 | K48: =SUMIF($B$6:$B$28,$B48,K$6:K$28) -> 5 | L48: =SUMIF($B$6:$B$28,$B48,L$6:L$28) -> 5 | ... O48: =SUMIF($B$6:$B$28,$B48,O$6:O$28) -> 3
B49: Tecnología e Informática | E49: =SUMIF($B$6:$B$28,$B49,E$6:E$28) -> 3 | F49: =SUMIF($B$6:$B$28,$B49,F$6:F$28) -> 3 | G49: =SUMIF($B$6:$B$28,$B49,G$6:G$28) -> 3 | H49: =SUMIF($B$6:$B$28,$B49,H$6:H$28) -> 3 | I49: =SUMIF($B$6:$B$28,$B49,I$6:I$28) -> 3 | J49: =SUMIF($B$6:$B$28,$B49,J$6:J$28) -> 3 | K49: =SUMIF($B$6:$B$28,$B49,K$6:K$28) -> 3 | L49: =SUMIF($B$6:$B$28,$B49,L$6:L$28) -> 3 | ... O49: =SUMIF($B$6:$B$28,$B49,O$6:O$28) -> 3
B50: Optativa institucional | E50: =SUMIF($B$6:$B$28,$B50,E$6:E$28) -> 0 | F50: =SUMIF($B$6:$B$28,$B50,F$6:F$28) -> 0 | G50: =SUMIF($B$6:$B$28,$B50,G$6:G$28) -> 0 | H50: =SUMIF($B$6:$B$28,$B50,H$6:H$28) -> 0 | I50: =SUMIF($B$6:$B$28,$B50,I$6:I$28) -> 0 | J50: =SUMIF($B$6:$B$28,$B50,J$6:J$28) -> 0 | K50: =SUMIF($B$6:$B$28,$B50,K$6:K$28) -> 0 | L50: =SUMIF($B$6:$B$28,$B50,L$6:L$28) -> 0 | ... O50: =SUMIF($B$6:$B$28,$B50,O$6:O$28) -> 0
B51: Proyecto pedagógico pastoral | E51: =SUMIF($B$6:$B$28,$B51,E$6:E$28) -> 1 | F51: =SUMIF($B$6:$B$28,$B51,F$6:F$28) -> 1 | G51: =SUMIF($B$6:$B$28,$B51,G$6:G$28) -> 1 | H51: =SUMIF($B$6:$B$28,$B51,H$6:H$28) -> 1 | I51: =SUMIF($B$6:$B$28,$B51,I$6:I$28) -> 1 | J51: =SUMIF($B$6:$B$28,$B51,J$6:J$28) -> 0 | K51: =SUMIF($B$6:$B$28,$B51,K$6:K$28) -> 0 | L51: =SUMIF($B$6:$B$28,$B51,L$6:L$28) -> 0 | ... O51: =SUMIF($B$6:$B$28,$B51,O$6:O$28) -> 0
B52: Especialidad media técnica | E52: =SUMIF($B$6:$B$28,$B52,E$6:E$28) -> 0 | F52: =SUMIF($B$6:$B$28,$B52,F$6:F$28) -> 0 | G52: =SUMIF($B$6:$B$28,$B52,G$6:G$28) -> 0 | H52: =SUMIF($B$6:$B$28,$B52,H$6:H$28) -> 0 | I52: =SUMIF($B$6:$B$28,$B52,I$6:I$28) -> 0 | J52: =SUMIF($B$6:$B$28,$B52,J$6:J$28) -> 0 | K52: =SUMIF($B$6:$B$28,$B52,K$6:K$28) -> 0 | L52: =SUMIF($B$6:$B$28,$B52,L$6:L$28) -> 0 | ... O52: =SUMIF($B$6:$B$28,$B52,O$6:O$28) -> 4
...

Sheet Validacion
A1: Verificación normativa por grado · intensidad semanal, anual y regla 80/20
A2: EICIT_CMA_1.5.1 · Versión 3 · consenso del 30 de septiembre de 2026 (acta de consenso, tarea 1.5.1). EICIT propone; el Colegio María Auxiliadora de Soacha delibera, decide y adopta (Consejo Académico → Consejo Directivo → resolución rectoral).
A4: Indicador | B4: T | C4: 1° | D4: 2° | E4: 3° | F4: 4° | G4: 5° | H4: 6° | I4: 7° | J4: 8° | K4: 9° | L4: 10° | M4: 11°
A5: Nivel | B5: Preescolar | C5: Básica primaria | D5: Básica primaria | E5: Básica primaria | F5: Básica primaria | G5: Básica primaria | H5: Básica secundaria | I5: Básica secundaria | J5: Básica secundaria | K5: Básica secundaria | L5: =Parametros!$C$30 -> Media técnica | M5: =Parametros!$C$30 -> Media técnica
A6: Sesiones semanales | B6: =Malla_2027!E70 -> 35 | C6: =Malla_2027!E30 -> 35 | D6: =Malla_2027!F30 -> 35 | E6: =Malla_2027!G30 -> 35 | F6: =Malla_2027!H30 -> 35 | G6: =Malla_2027!I30 -> 35 | H6: =Malla_2027!J30 -> 35 | I6: =Malla_2027!K30 -> 35 | J6: =Malla_2027!L30 -> 35 | ... M6: =Malla_2027!O30 -> 37
A7: Minutos semanales | B7: =Malla_2027!E73 -> 2100 | C7: =Malla_2027!E36 -> 2100 | D7: =Malla_2027!F36 -> 2100 | E7: =Malla_2027!G36 -> 2100 | F7: =Malla_2027!H36 -> 2100 | G7: =Malla_2027!I36 -> 2100 | H7: =Malla_2027!J36 -> 2100 | I7: =Malla_2027!K36 -> 2100 | J7: =Malla_2027!L36 -> 2100 | ... M7: =Malla_2027!O36 -> 2220
A8: Horas efectivas semanales | B8: =B7/60 -> 35 | C8: =C7/60 -> 35 | D8: =D7/60 -> 35 | E8: =E7/60 -> 35 | F8: =F7/60 -> 35 | G8: =G7/60 -> 35 | H8: =H7/60 -> 35 | I8: =I7/60 -> 35 | ... M8: =M7/60 -> 37
A9: Mínimo semanal (h) | B9: =Parametros!$C$22 -> 20 | C9: =Parametros!$C$23 -> 25 | D9: =Parametros!$C$23 -> 25 | E9: =Parametros!$C$23 -> 25 | F9: =Parametros!$C$23 -> 25 | G9: =Parametros!$C$23 -> 25 | H9: =Parametros!$C$24 -> 30 | I9: =Parametros!$C$24 -> 30 | J9: =Parametros!$C$24 -> 30 | K9: =Parametros!$C$24 -> 30 | L9: =IF(Parametros!$C$30="Media técnica",Parametros!$C$31,Parametros!$C$24) -> 37 | M9: =IF(Parametros!$C$30="Media técnica",Parametros!$C$31,Parametros!$C$24) -> 37
A10: ¿Cumple mínimo semanal? | B10: =IF(B8>=B9,"Cumple","No cumple") -> Cumple | C10: =IF(C8>=C9,"Cumple","No cumple") -> Cumple | D10: =IF(D8>=D9,"Cumple","No cumple") -> Cumple | E10: =IF(E8>=E9,"Cumple","No cumple") -> Cumple | F10: =IF(F8>=F9,"Cumple","No cumple") -> Cumple | G10: =IF(G8>=G9,"Cumple","No cumple") -> Cumple | H10: =IF(H8>=H9,"Cumple","No cumple") -> Cumple | I10: =IF(I8>=I9,"Cumple","No cumple") -> Cumple | ... M10: =IF(M8>=M9,"Cumple","No cumple") -> Cumple
A11: Horas efectivas anuales · Escenario 1 (calendario adoptado, 38 semanas) | B11: =B8*Parametros!$C$11/5 -> 1330 | C11: =C8*Parametros!$C$11/5 -> 1330 | D11: =D8*Parametros!$C$11/5 -> 1330 | E11: =E8*Parametros!$C$11/5 -> 1330 | F11: =F8*Parametros!$C$11/5 -> 1330 | G11: =G8*Parametros!$C$11/5 -> 1330 | H11: =H8*Parametros!$C$11/5 -> 1330 | I11: =I8*Parametros!$C$11/5 -> 1330 | ... M11: =M8*Parametros!$C$11/5 -> 1406
A12: Horas efectivas anuales · Escenario 2 (alternativa de 40 semanas) | B12: =B8*Parametros!$C$12/5 -> 1400 | C12: =C8*Parametros!$C$12/5 -> 1400 | D12: =D8*Parametros!$C$12/5 -> 1400 | E12: =E8*Parametros!$C$12/5 -> 1400 | F12: =F8*Parametros!$C$12/5 -> 1400 | G12: =G8*Parametros!$C$12/5 -> 1400 | H12: =H8*Parametros!$C$12/5 -> 1400 | I12: =I8*Parametros!$C$12/5 -> 1400 | ... M12: =M8*Parametros!$C$12/5 -> 1480
A13: Mínimo anual (h) | B13: =Parametros!$D$22 -> 800 | C13: =Parametros!$D$23 -> 1000 | D13: =Parametros!$D$23 -> 1000 | E13: =Parametros!$D$23 -> 1000 | F13: =Parametros!$D$23 -> 1000 | G13: =Parametros!$D$23 -> 1000 | H13: =Parametros!$D$24 -> 1200 | I13: =Parametros!$D$24 -> 1200 | J13: =Parametros!$D$24 -> 1200 | K13: =Parametros!$D$24 -> 1200 | L13: =IF(Parametros!$C$30="Media técnica",Parametros!$D$31,Parametros!$D$24) -> 1480 | M13: =IF(Parametros!$C$30="Media técnica",Parametros!$D$31,Parametros!$D$24) -> 1480
A14: ¿Cumple · Escenario 1? | B14: =IF(B11>=B13,"Cumple","No cumple") -> Cumple | C14: =IF(C11>=C13,"Cumple","No cumple") -> Cumple | D14: =IF(D11>=D13,"Cumple","No cumple") -> Cumple | E14: =IF(E11>=E13,"Cumple","No cumple") -> Cumple | F14: =IF(F11>=F13,"Cumple","No cumple") -> Cumple | G14: =IF(G11>=G13,"Cumple","No cumple") -> Cumple | H14: =IF(H11>=H13,"Cumple","No cumple") -> Cumple | I14: =IF(I11>=I13,"Cumple","No cumple") -> Cumple | ... M14: =IF(M11>=M13,"Cumple","No cumple") -> No cumple
A15: ¿Cumple · Escenario 2? | B15: =IF(B12>=B13,"Cumple","No cumple") -> Cumple | C15: =IF(C12>=C13,"Cumple","No cumple") -> Cumple | D15: =IF(D12>=D13,"Cumple","No cumple") -> Cumple | E15: =IF(E12>=E13,"Cumple","No cumple") -> Cumple | F15: =IF(F12>=F13,"Cumple","No cumple") -> Cumple | G15: =IF(G12>=G13,"Cumple","No cumple") -> Cumple | H15: =IF(H12>=H13,"Cumple","No cumple") -> Cumple | I15: =IF(I12>=I13,"Cumple","No cumple") -> Cumple | ... M15: =IF(M12>=M13,"Cumple","No cumple") -> Cumple
A16: Días lectivos mínimos para el mínimo anual | B16: =ROUNDUP(B13/(B8/5),0) -> 115 | C16: =ROUNDUP(C13/(C8/5),0) -> 143 | D16: =ROUNDUP(D13/(D8/5),0) -> 143 | E16: =ROUNDUP(E13/(E8/5),0) -> 143 | F16: =ROUNDUP(F13/(F8/5),0) -> 143 | G16: =ROUNDUP(G13/(G8/5),0) -> 143 | H16: =ROUNDUP(H13/(H8/5),0) -> 172 | I16: =ROUNDUP(I13/(I8/5),0) -> 172 | ... M16: =ROUNDUP(M13/(M8/5),0) -> 200
A17: Sesiones en áreas obligatorias | B17: ="No aplica" -> No aplica | C17: =Malla_2027!E34 -> 34 | D17: =Malla_2027!F34 -> 34 | E17: =Malla_2027!G34 -> 34 | F17: =Malla_2027!H34 -> 34 | G17: =Malla_2027!I34 -> 34 | H17: =Malla_2027!J34 -> 35 | I17: =Malla_2027!K34 -> 35 | J17: =Malla_2027!L34 -> 35 | ... M17: =Malla_2027!O34 -> 33
A18: Horas efectivas semanales en áreas obligatorias | B18: ="No aplica" -> No aplica | C18: =C17*Parametros!$C$29/60 -> 34 | D18: =D17*Parametros!$C$29/60 -> 34 | E18: =E17*Parametros!$C$29/60 -> 34 | F18: =F17*Parametros!$C$29/60 -> 34 | G18: =G17*Parametros!$C$29/60 -> 34 | H18: =H17*Parametros!$C$29/60 -> 35 | I18: =I17*Parametros!$C$29/60 -> 35 | J18: =J17*Parametros!$C$29/60 -> 35 | ... M18: =M17*Parametros!$C$29/60 -> 33
A19: Mínimo 80 % (h semanales) | B19: ="No aplica" -> No aplica | C19: =C9*Parametros!$C$25 -> 20 | D19: =D9*Parametros!$C$25 -> 20 | E19: =E9*Parametros!$C$25 -> 20 | F19: =F9*Parametros!$C$25 -> 20 | G19: =G9*Parametros!$C$25 -> 20 | H19: =H9*Parametros!$C$25 -> 24 | I19: =I9*Parametros!$C$25 -> 24 | J19: =J9*Parametros!$C$25 -> 24 | ... M19: =M9*Parametros!$C$25 -> 29.6
A20: ¿Cumple regla 80/20? | B20: ="No aplica" -> No aplica | C20: =IF(C18>=C19,"Cumple","No cumple") -> Cumple | D20: =IF(D18>=D19,"Cumple","No cumple") -> Cumple | E20: =IF(E18>=E19,"Cumple","No cumple") -> Cumple | F20: =IF(F18>=F19,"Cumple","No cumple") -> Cumple | G20: =IF(G18>=G19,"Cumple","No cumple") -> Cumple | H20: =IF(H18>=H19,"Cumple","No cumple") -> Cumple | I20: =IF(I18>=I19,"Cumple","No cumple") -> Cumple | J20: =IF(J18>=J19,"Cumple","No cumple") -> Cumple | ... M20: =IF(M18>=M19,"Cumple","No cumple") -> Cumple
A21: Proporción de sesiones en áreas obligatorias | B21: ="No aplica" -> No aplica | C21: =Malla_2027!E35 -> 0.97142857 | D21: =Malla_2027!F35 -> 0.97142857 | E21: =Malla_2027!G35 -> 0.97142857 | F21: =Malla_2027!H35 -> 0.97142857 | G21: =Malla_2027!I35 -> 0.97142857 | H21: =Malla_2027!J35 -> 1 | I21: =Malla_2027!K35 -> 1 | J21: =Malla_2027!L35 -> 1 | ... M21: =Malla_2027!O35 -> 0.89189189
A24: Lectura: el Escenario 1 usa los días lectivos efectivos del calendario proyectado por el Colegio (hoja Calendario_2027); el Escenario 2, un año lectivo de 40 semanas. En 10°–11° se suman las 2 sesiones de 60 min de la jornada extendida. La regla 80/20 se verifica sobre el mínimo semanal legal: al menos el 80 % de ese mínimo, en horas de 60 minutos, corresponde a áreas obligatorias (Ley 115, arts. 23 y 31). Transición se organiza por dimensiones del desarrollo; la regla no aplica.

Sheet Catalogo_planes
A1: Catálogo de planes de estudio por elaborar · intensidad por período y regla 80/20 intra-asignatura
A2: EICIT_CMA_1.5.1 · Versión 3 · consenso del 30 de septiembre de 2026 (acta de consenso, tarea 1.5.1). EICIT propone; el Colegio María Auxiliadora de Soacha delibera, decide y adopta (Consejo Académico → Consejo Directivo → resolución rectoral).
A3: Infancia Misionera (proyecto pastoral) no requiere plan. «No aplica» en la regla 80/20: la optativa y la media técnica son en sí mismas espacios de énfasis institucional; la media técnica sigue el diseño curricular articulado con el SENA. Horas efectivas = sesiones × duración efectiva ÷ 60 (ver criterio en Parametros).
A4: N.° | B4: Código del plan | C4: Nivel | D4: Grado | E4: Área / dimensión | F4: Asignatura / experiencia | G4: Tipo | H4: Horas semanales | I4: Sesiones P1 | J4: Sesiones P2 | K4: Sesiones P3 | L4: Sesiones P4 | M4: Sesiones al año | N4: Horas efectivas al año | O4: Máx. sesiones de énfasis (20 %) | P4: Mín. sesiones núcleo común (80 %) | Q4: Estado | R4: Responsable
A5: 1 | B5: T-SAN | C5: Preescolar | D5: T | E5: Dimensión socioafectiva | F5: Exploración del medio natural | G5: Dimensión (preescolar) | H5: =Malla_2027!E56 -> 3 | I5: =H5*Parametros!$C$14 -> 30 | J5: =H5*Parametros!$C$15 -> 27 | K5: =H5*Parametros!$C$16 -> 27 | L5: =H5*Parametros!$C$17 -> 27 | M5: =SUM(I5:L5) -> 111 | N5: =M5*Parametros!$C$29/60 -> 111 | O5: =ROUNDDOWN(M5*Parametros!$C$26,0) -> 22 | P5: =M5-O5 -> 89 | Q5: Por elaborar | R5: Docentes del Colegio
A6: 2 | B6: T-COM | C6: Preescolar | D6: T | E6: Dimensión comunicativa | F6: Lenguaje: oralidad, lectura y escritura emergentes | G6: Dimensión (preescolar) | H6: =Malla_2027!E57 -> 6 | I6: =H6*Parametros!$C$14 -> 60 | J6: =H6*Parametros!$C$15 -> 54 | K6: =H6*Parametros!$C$16 -> 54 | L6: =H6*Parametros!$C$17 -> 54 | M6: =SUM(I6:L6) -> 222 | N6: =M6*Parametros!$C$29/60 -> 222 | O6: =ROUNDDOWN(M6*Parametros!$C$26,0) -> 44 | P6: =M6-O6 -> 178 | Q6: Por elaborar | R6: Docentes del Colegio
A7: 3 | B7: T-ING | C7: Preescolar | D7: T | E7: Dimensión comunicativa | F7: Inglés | G7: Dimensión (preescolar) | H7: =Malla_2027!E58 -> 3 | I7: =H7*Parametros!$C$14 -> 30 | J7: =H7*Parametros!$C$15 -> 27 | K7: =H7*Parametros!$C$16 -> 27 | L7: =H7*Parametros!$C$17 -> 27 | M7: =SUM(I7:L7) -> 111 | N7: =M7*Parametros!$C$29/60 -> 111 | O7: =ROUNDDOWN(M7*Parametros!$C$26,0) -> 22 | P7: =M7-O7 -> 89 | Q7: Por elaborar | R7: Docentes del Colegio
A8: 4 | B8: T-SAS | C8: Preescolar | D8: T | E8: Dimensión socioafectiva | F8: Exploración del medio social y convivencia | G8: Dimensión (preescolar) | H8: =Malla_2027!E59 -> 3 | I8: =H8*Parametros!$C$14 -> 30 | J8: =H8*Parametros!$C$15 -> 27 | K8: =H8*Parametros!$C$16 -> 27 | L8: =H8*Parametros!$C$17 -> 27 | M8: =SUM(I8:L8) -> 111 | N8: =M8*Parametros!$C$29/60 -> 111 | O8: =ROUNDDOWN(M8*Parametros!$C$26,0) -> 22 | P8: =M8-O8 -> 89 | Q8: Por elaborar | R8: Docentes del Colegio
A9: 5 | B9: T-COR | C9: Preescolar | D9: T | E9: Dimensión corporal | F9: Motricidad, juego y educación física | G9: Dimensión (preescolar) | H9: =Malla_2027!E60 -> 2 | I9: =H9*Parametros!$C$14 -> 20 | J9: =H9*Parametros!$C$15 -> 18 | K9: =H9*Parametros!$C$16 -> 18 | L9: =H9*Parametros!$C$17 -> 18 | M9: =SUM(I9:L9) -> 74 | N9: =M9*Parametros!$C$29/60 -> 74 | O9: =ROUNDDOWN(M9*Parametros!$C$26,0) -> 14 | P9: =M9-O9 -> 60 | Q9: Por elaborar | R9: Docentes del Colegio
A10: 6 | B10: T-EST | C10: Preescolar | D10: T | E10: Dimensión estética | F10: Expresión plástica | G10: Dimensión (preescolar) | H10: =Malla_2027!E61 -> 2 | I10: =H10*Parametros!$C$14 -> 20 | J10: =H10*Parametros!$C$15 -> 18 | K10: =H10*Parametros!$C$16 -> 18 | L10: =H10*Parametros!$C$17 -> 18 | M10: =SUM(I10:L10) -> 74 | N10: =M10*Parametros!$C$29/60 -> 74 | O10: =ROUNDDOWN(M10*Parametros!$C$26,0) -> 14 | P10: =M10-O10 -> 60 | Q10: Por elaborar | R10: Docentes del Colegio
A11: 7 | B11: T-MUS | C11: Preescolar | D11: T | E11: Dimensión estética | F11: Música | G11: Dimensión (preescolar) | H11: =Malla_2027!E62 -> 1 | I11: =H11*Parametros!$C$14 -> 10 | J11: =H11*Parametros!$C$15 -> 9 | K11: =H11*Parametros!$C$16 -> 9 | L11: =H11*Parametros!$C$17 -> 9 | M11: =SUM(I11:L11) -> 37 | N11: =M11*Parametros!$C$29/60 -> 37 | O11: =ROUNDDOWN(M11*Parametros!$C$26,0) -> 7 | P11: =M11-O11 -> 30 | Q11: Por elaborar | R11: Docentes del Colegio
A12: 8 | B12: T-DAN | C12: Preescolar | D12: T | E12: Dimensión estética | F12: Danzas | G12: Dimensión (preescolar) | H12: =Malla_2027!E63 -> 1 | I12: =H12*Parametros!$C$14 -> 10 | J12: =H12*Parametros!$C$15 -> 9 | K12: =H12*Parametros!$C$16 -> 9 | L12: =H12*Parametros!$C$17 -> 9 | M12: =SUM(I12:L12) -> 37 | N12: =M12*Parametros!$C$29/60 -> 37 | O12: =ROUNDDOWN(M12*Parametros!$C$26,0) -> 7 | P12: =M12-O12 -> 30 | Q12: Por elaborar | R12: Docentes del Colegio
A13: 9 | B13: T-ETI | C13: Preescolar | D13: T | E13: Dimensión ética | F13: Ética y valores | G13: Dimensión (preescolar) | H13: =Malla_2027!E64 -> 1 | I13: =H13*Parametros!$C$14 -> 10 | J13: =H13*Parametros!$C$15 -> 9 | K13: =H13*Parametros!$C$16 -> 9 | L13: =H13*Parametros!$C$17 -> 9 | M13: =SUM(I13:L13) -> 37 | N13: =M13*Parametros!$C$29/60 -> 37 | O13: =ROUNDDOWN(M13*Parametros!$C$26,0) -> 7 | P13: =M13-O13 -> 30 | Q13: Por elaborar | R13: Docentes del Colegio
A14: 10 | B14: T-ESP | C14: Preescolar | D14: T | E14: Dimensión espiritual | F14: Educación Religiosa | G14: Dimensión (preescolar) | H14: =Malla_2027!E65 -> 3 | I14: =H14*Parametros!$C$14 -> 30 | J14: =H14*Parametros!$C$15 -> 27 | K14: =H14*Parametros!$C$16 -> 27 | L14: =H14*Parametros!$C$17 -> 27 | M14: =SUM(I14:L14) -> 111 | N14: =M14*Parametros!$C$29/60 -> 111 | O14: =ROUNDDOWN(M14*Parametros!$C$26,0) -> 22 | P14: =M14-O14 -> 89 | Q14: Por elaborar | R14: Docentes del Colegio
A15: 11 | B15: T-COG | C15: Preescolar | D15: T | E15: Dimensión cognitiva | F15: Pensamiento matemático y exploración | G15: Dimensión (preescolar) | H15: =Malla_2027!E66 -> 6 | I15: =H15*Parametros!$C$14 -> 60 | J15: =H15*Parametros!$C$15 -> 54 | K15: =H15*Parametros!$C$16 -> 54 | L15: =H15*Parametros!$C$17 -> 54 | M15: =SUM(I15:L15) -> 222 | N15: =M15*Parametros!$C$29/60 -> 222 | O15: =ROUNDDOWN(M15*Parametros!$C$26,0) -> 44 | P15: =M15-O15 -> 178 | Q15: Por elaborar | R15: Docentes del Colegio
A16: 12 | B16: T-TEC | C16: Preescolar | D16: T | E16: Dimensión cognitiva | F16: Tecnología e Informática | G16: Dimensión (preescolar) | H16: =Malla_2027!E67 -> 3 | I16: =H16*Parametros!$C$14 -> 30 | J16: =H16*Parametros!$C$15 -> 27 | K16: =H16*Parametros!$C$16 -> 27 | L16: =H16*Parametros!$C$17 -> 27 | M16: =SUM(I16:L16) -> 111 | N16: =M16*Parametros!$C$29/60 -> 111 | O16: =ROUNDDOWN(M16*Parametros!$C$26,0) -> 22 | P16: =M16-O16 -> 89 | Q16: Por elaborar | R16: EICIT
A17: 13 | B17: CNA-1 | C17: Básica primaria | D17: 1° | E17: Ciencias Naturales y Educación Ambiental | F17: Ciencias Naturales y Educación Ambiental | G17: Obligatoria (art. 23) | H17: =Malla_2027!E6 -> 4 | I17: =H17*Parametros!$C$14 -> 40 | J17: =H17*Parametros!$C$15 -> 36 | K17: =H17*Parametros!$C$16 -> 36 | L17: =H17*Parametros!$C$17 -> 36 | M17: =SUM(I17:L17) -> 148 | N17: =M17*Parametros!$C$29/60 -> 148 | O17: =ROUNDDOWN(M17*Parametros!$C$26,0) -> 29 | P17: =M17-O17 -> 119 | Q17: Por elaborar | R17: Docentes del Colegio
A18: 14 | B18: SOC-1 | C18: Básica primaria | D18: 1° | E18: Ciencias Sociales, Historia, Geografía, Constitución Política y Democracia | F18: Ciencias Sociales | G18: Obligatoria (art. 23) | H18: =Malla_2027!E9 -> 4 | I18: =H18*Parametros!$C$14 -> 40 | J18: =H18*Parametros!$C$15 -> 36 | K18: =H18*Parametros!$C$16 -> 36 | L18: =H18*Parametros!$C$17 -> 36 | M18: =SUM(I18:L18) -> 148 | N18: =M18*Parametros!$C$29/60 -> 148 | O18: =ROUNDDOWN(M18*Parametros!$C$26,0) -> 29 | P18: =M18-O18 -> 119 | Q18: Por elaborar | R18: Docentes del Colegio
A19: 15 | B19: ART-1 | C19: Básica primaria | D19: 1° | E19: Educación Artística y Cultural | F19: Artes plásticas | G19: Obligatoria (art. 23) | H19: =Malla_2027!E12 -> 1 | I19: =H19*Parametros!$C$14 -> 10 | J19: =H19*Parametros!$C$15 -> 9 | K19: =H19*Parametros!$C$16 -> 9 | L19: =H19*Parametros!$C$17 -> 9 | M19: =SUM(I19:L19) -> 37 | N19: =M19*Parametros!$C$29/60 -> 37 | O19: =ROUNDDOWN(M19*Parametros!$C$26,0) -> 7 | P19: =M19-O19 -> 30 | Q19: Por elaborar | R19: Docentes del Colegio
A20: 16 | B20: MUS-1 | C20: Básica primaria | D20: 1° | E20: Educación Artística y Cultural | F20: Música | G20: Obligatoria (art. 23) | H20: =Malla_2027!E13 -> 1 | I20: =H20*Parametros!$C$14 -> 10 | J20: =H20*Parametros!$C$15 -> 9 | K20: =H20*Parametros!$C$16 -> 9 | L20: =H20*Parametros!$C$17 -> 9 | M20: =SUM(I20:L20) -> 37 | N20: =M20*Parametros!$C$29/60 -> 37 | O20: =ROUNDDOWN(M20*Parametros!$C$26,0) -> 7 | P20: =M20-O20 -> 30 | Q20: Por elaborar | R20: Docentes del Colegio
A21: 17 | B21: DAN-1 | C21: Básica primaria | D21: 1° | E21: Educación Artística y Cultural | F21: Danzas | G21: Obligatoria (art. 23) | H21: =Malla_2027!E14 -> 1 | I21: =H21*Parametros!$C$14 -> 10 | J21: =H21*Parametros!$C$15 -> 9 | K21: =H21*Parametros!$C$16 -> 9 | L21: =H21*Parametros!$C$17 -> 9 | M21: =SUM(I21:L21) -> 37 | N21: =M21*Parametros!$C$29/60 -> 37 | O21: =ROUNDDOWN(M21*Parametros!$C$26,0) -> 7 | P21: =M21-O21 -> 30 | Q21: Por elaborar | R21: Docentes del Colegio
A22: 18 | B22: ETI-1 | C22: Básica primaria | D22: 1° | E22: Educación Ética y en Valores Humanos | F22: Ética y Valores Humanos | G22: Obligatoria (art. 23) | H22: =Malla_2027!E15 -> 1 | I22: =H22*Parametros!$C$14 -> 10 | J22: =H22*Parametros!$C$15 -> 9 | K22: =H22*Parametros!$C$16 -> 9 | L22: =H22*Parametros!$C$17 -> 9 | M22: =SUM(I22:L22) -> 37 | N22: =M22*Parametros!$C$29/60 -> 37 | O22: =ROUNDDOWN(M22*Parametros!$C$26,0) -> 7 | P22: =M22-O22 -> 30 | Q22: Por elaborar | R22: Docentes del Colegio
A23: 19 | B23: EFI-1 | C23: Básica primaria | D23: 1° | E23: Educación Física, Recreación y Deportes | F23: Educación Física, Recreación y Deportes | G23: Obligatoria (art. 23) | H23: =Malla_2027!E16 -> 2 | I23: =H23*Parametros!$C$14 -> 20 | J23: =H23*Parametros!$C$15 -> 18 | K23: =H23*Parametros!$C$16 -> 18 | L23: =H23*Parametros!$C$17 -> 18 | M23: =SUM(I23:L23) -> 74 | N23: =M23*Parametros!$C$29/60 -> 74 | O23: =ROUNDDOWN(M23*Parametros!$C$26,0) -> 14 | P23: =M23-O23 -> 60 | Q23: Por elaborar | R23: Docentes del Colegio
A24: 20 | B24: ERE-1 | C24: Básica primaria | D24: 1° | E24: Educación Religiosa | F24: Educación Religiosa Escolar | G24: Obligatoria (art. 23) | H24: =Malla_2027!E17 -> 3 | I24: =H24*Parametros!$C$14 -> 30 | J24: =H24*Parametros!$C$15 -> 27 | K24: =H24*Parametros!$C$16 -> 27 | L24: =H24*Parametros!$C$17 -> 27 | M24: =SUM(I24:L24) -> 111 | N24: =M24*Parametros!$C$29/60 -> 111 | O24: =ROUNDDOWN(M24*Parametros!$C$26,0) -> 22 | P24: =M24-O24 -> 89 | Q24: Por elaborar | R24: Docentes del Colegio
A25: 21 | B25: LCA-1 | C25: Básica primaria | D25: 1° | E25: Humanidades: Lengua Castellana e Idiomas Extranjeros | F25: Lengua Castellana | G25: Obligatoria (art. 23) | H25: =Malla_2027!E18 -> 5 | I25: =H25*Parametros!$C$14 -> 50 | J25: =H25*Parametros!$C$15 -> 45 | K25: =H25*Parametros!$C$16 -> 45 | L25: =H25*Parametros!$C$17 -> 45 | M25: =SUM(I25:L25) -> 185 | N25: =M25*Parametros!$C$29/60 -> 185 | O25: =ROUNDDOWN(M25*Parametros!$C$26,0) -> 37 | P25: =M25-O25 -> 148 | Q25: Por elaborar | R25: Docentes del Colegio
A26: 22 | B26: ING-1 | C26: Básica primaria | D26: 1° | E26: Humanidades: Lengua Castellana e Idiomas Extranjeros | F26: Inglés | G26: Obligatoria (art. 23) | H26: =Malla_2027!E19 -> 4 | I26: =H26*Parametros!$C$14 -> 40 | J26: =H26*Parametros!$C$15 -> 36 | K26: =H26*Parametros!$C$16 -> 36 | L26: =H26*Parametros!$C$17 -> 36 | M26: =SUM(I26:L26) -> 148 | N26: =M26*Parametros!$C$29/60 -> 148 | O26: =ROUNDDOWN(M26*Parametros!$C$26,0) -> 29 | P26: =M26-O26 -> 119 | Q26: Por elaborar | R26: Docentes del Colegio
A27: 23 | B27: MAT-1 | C27: Básica primaria | D27: 1° | E27: Matemáticas | F27: Matemáticas | G27: Obligatoria (art. 23) | H27: =Malla_2027!E20 -> 5 | I27: =H27*Parametros!$C$14 -> 50 | J27: =H27*Parametros!$C$15 -> 45 | K27: =H27*Parametros!$C$16 -> 45 | L27: =H27*Parametros!$C$17 -> 45 | M27: =SUM(I27:L27) -> 185 | N27: =M27*Parametros!$C$29/60 -> 185 | O27: =ROUNDDOWN(M27*Parametros!$C$26,0) -> 37 | P27: =M27-O27 -> 148 | Q27: Por elaborar | R27: Docentes del Colegio
A28: 24 | B28: TEI-1 | C28: Básica primaria | D28: 1° | E28: Tecnología e Informática | F28: Tecnología e Informática | G28: Obligatoria (art. 23) | H28: =Malla_2027!E24 -> 3 | I28: =H28*Parametros!$C$14 -> 30 | J28: =H28*Parametros!$C$15 -> 27 | K28: =H28*Parametros!$C$16 -> 27 | L28: =H28*Parametros!$C$17 -> 27 | M28: =SUM(I28:L28) -> 111 | N28: =M28*Parametros!$C$29/60 -> 111 | O28: =ROUNDDOWN(M28*Parametros!$C$26,0) -> 22 | P28: =M28-O28 -> 89 | Q28: Por elaborar | R28: EICIT
A29: 25 | B29: CNA-2 | C29: Básica primaria | D29: 2° | E29: Ciencias Naturales y Educación Ambiental | F29: Ciencias Naturales y Educación Ambiental | G29: Obligatoria (art. 23) | H29: =Malla_2027!F6 -> 4 | I29: =H29*Parametros!$C$14 -> 40 | J29: =H29*Parametros!$C$15 -> 36 | K29: =H29*Parametros!$C$16 -> 36 | L29: =H29*Parametros!$C$17 -> 36 | M29: =SUM(I29:L29) -> 148 | N29: =M29*Parametros!$C$29/60 -> 148 | O29: =ROUNDDOWN(M29*Parametros!$C$26,0) -> 29 | P29: =M29-O29 -> 119 | Q29: Por elaborar | R29: Docentes del Colegio
A30: 26 | B30: SOC-2 | C30: Básica primaria | D30: 2° | E30: Ciencias Sociales, Historia, Geografía, Constitución Política y Democracia | F30: Ciencias Sociales | G30: Obligatoria (art. 23) | H30: =Malla_2027!F9 -> 4 | I30: =H30*Parametros!$C$14 -> 40 | J30: =H30*Parametros!$C$15 -> 36 | K30: =H30*Parametros!$C$16 -> 36 | L30: =H30*Parametros!$C$17 -> 36 | M30: =SUM(I30:L30) -> 148 | N30: =M30*Parametros!$C$29/60 -> 148 | O30: =ROUNDDOWN(M30*Parametros!$C$26,0) -> 29 | P30: =M30-O30 -> 119 | Q30: Por elaborar | R30: Docentes del Colegio
A31: 27 | B31: ART-2 | C31: Básica primaria | D31: 2° | E31: Educación Artística y Cultural | F31: Artes plásticas | G31: Obligatoria (art. 23) | H31: =Malla_2027!F12 -> 1 | I31: =H31*Parametros!$C$14 -> 10 | J31: =H31*Parametros!$C$15 -> 9 | K31: =H31*Parametros!$C$16 -> 9 | L31: =H31*Parametros!$C$17 -> 9 | M31: =SUM(I31:L31) -> 37 | N31: =M31*Parametros!$C$29/60 -> 37 | O31: =ROUNDDOWN(M31*Parametros!$C$26,0) -> 7 | P31: =M31-O31 -> 30 | Q31: Por elaborar | R31: Docentes del Colegio
A32: 28 | B32: MUS-2 | C32: Básica primaria | D32: 2° | E32: Educación Artística y Cultural | F32: Música | G32: Obligatoria (art. 23) | H32: =Malla_2027!F13 -> 1 | I32: =H32*Parametros!$C$14 -> 10 | J32: =H32*Parametros!$C$15 -> 9 | K32: =H32*Parametros!$C$16 -> 9 | L32: =H32*Parametros!$C$17 -> 9 | M32: =SUM(I32:L32) -> 37 | N32: =M32*Parametros!$C$29/60 -> 37 | O32: =ROUNDDOWN(M32*Parametros!$C$26,0) -> 7 | P32: =M32-O32 -> 30 | Q32: Por elaborar | R32: Docentes del Colegio
A33: 29 | B33: DAN-2 | C33: Básica primaria | D33: 2° | E33: Educación Artística y Cultural | F33: Danzas | G33: Obligatoria (art. 23) | H33: =Malla_2027!F14 -> 1 | I33: =H33*Parametros!$C$14 -> 10 | J33: =H33*Parametros!$C$15 -> 9 | K33: =H33*Parametros!$C$16 -> 9 | L33: =H33*Parametros!$C$17 -> 9 | M33: =SUM(I33:L33) -> 37 | N33: =M33*Parametros!$C$29/60 -> 37 | O33: =ROUNDDOWN(M33*Parametros!$C$26,0) -> 7 | P33: =M33-O33 -> 30 | Q33: Por elaborar | R33: Docentes del Colegio
A34: 30 | B34: ETI-2 | C34: Básica primaria | D34: 2° | E34: Educación Ética y en Valores Humanos | F34: Ética y Valores Humanos | G34: Obligatoria (art. 23) | H34: =Malla_2027!F15 -> 1 | I34: =H34*Parametros!$C$14 -> 10 | J34: =H34*Parametros!$C$15 -> 9 | K34: =H34*Parametros!$C$16 -> 9 | L34: =H34*Parametros!$C$17 -> 9 | M34: =SUM(I34:L34) -> 37 | N34: =M34*Parametros!$C$29/60 -> 37 | O34: =ROUNDDOWN(M34*Parametros!$C$26,0) -> 7 | P34: =M34-O34 -> 30 | Q34: Por elaborar | R34: Docentes del Colegio
A35: 31 | B35: EFI-2 | C35: Básica primaria | D35: 2° | E35: Educación Física, Recreación y Deportes | F35: Educación Física, Recreación y Deportes | G35: Obligatoria (art. 23) | H35: =Malla_2027!F16 -> 2 | I35: =H35*Parametros!$C$14 -> 20 | J35: =H35*Parametros!$C$15 -> 18 | K35: =H35*Parametros!$C$16 -> 18 | L35: =H35*Parametros!$C$17 -> 18 | M35: =SUM(I35:L35) -> 74 | N35: =M35*Parametros!$C$29/60 -> 74 | O35: =ROUNDDOWN(M35*Parametros!$C$26,0) -> 14 | P35: =M35-O35 -> 60 | Q35: Por elaborar | R35: Docentes del Colegio
A36: 32 | B36: ERE-2 | C36: Básica primaria | D36: 2° | E36: Educación Religiosa | F36: Educación Religiosa Escolar | G36: Obligatoria (art. 23) | H36: =Malla_2027!F17 -> 3 | I36: =H36*Parametros!$C$14 -> 30 | J36: =H36*Parametros!$C$15 -> 27 | K36: =H36*Parametros!$C$16 -> 27 | L36: =H36*Parametros!$C$17 -> 27 | M36: =SUM(I36:L36) -> 111 | N36: =M36*Parametros!$C$29/60 -> 111 | O36: =ROUNDDOWN(M36*Parametros!$C$26,0) -> 22 | P36: =M36-O36 -> 89 | Q36: Por elaborar | R36: Docentes del Colegio
