Workbook

Sheet Instrucciones
B2: Planilla de análisis — Diagnóstico de competencias digitales docentes (ENSMA)
B3: EICIT · Fase 1 · Tarea F1-T5 · Autor: EICIT IA
B5: 1. La planilla trae datos de EJEMPLO (filas con ID «EJEMPLO-xx») para que veas todo calculando. Bórralos antes de cargar los reales.
B6: 2. Cuando cierres el formulario, abre su hoja de respuestas vinculada en Google Sheets.
B7: 3. Pega los valores en la hoja «Datos», respetando el orden de columnas (es el mismo del formulario). La llave de cruce con la caracterización docente es el correo institucional.
B8: 4. Para el bloque objetivo, pega el puntaje total del cuestionario en OBJ_PUNTAJE (0–9). Si quieres el detalle por pregunta (dificultad por ítem, útil para el Diplomado), marca OBJ1–OBJ9 con 1 (correcto) o 0 (incorrecto).
B9: 5. Todo lo demás se calcula solo: medias por dimensión, nivel MEN (Explorador/Integrador/Innovador), desempeño objetivo, alfa de Cronbach y el tablero.
B10: 6. Hoja «Tablero»: lectura colectiva (línea base) y cortes por segmento. Hoja «Perfil»: elige un docente en el desplegable para ver su radar. Hoja «Fiabilidad»: consistencia interna por dimensión.
B11: 7. Columnas con encabezado azul = se editan (datos crudos). Encabezado dorado = cálculo automático, no tocar.
B12: 8. Salvedad: con N≈40 las conclusiones son descriptivas; los segmentos pequeños se leen con cautela, sin pruebas inferenciales.
B14: Leyenda de color de nivel:
B15: Explorador
... B17: Innovador

Sheet Datos
A1: ID | B1: Nombre | C1: Correo | D1: Nivel | E1: Área | F1: Experiencia | G1: Dispositivo | H1: Conectividad | I1: FormaciónPrevia | J1: ACT1 | K1: ACT2 | L1: ACT3 | M1: ACT4 | N1: ACT5 | O1: ACT6 | P1: ACT7 | Q1: ACT8 | R1: ACT9 | S1: INF1 | T1: INF2 | U1: INF3 | V1: INF4 | W1: INF5 | X1: INF_FREC | Y1: COM1 | Z1: COM2 | AA1: COM3 | AB1: COM4 | AC1: COM5 | AD1: COM_FREC | AE1: SEG1 | AF1: SEG2 | AG1: SEG3 | AH1: SEG4 | AI1: SEG5 | AJ1: SEG6 | AK1: SEG7 | AL1: PED1 | AM1: PED2 | AN1: PED3 | AO1: PED4 | AP1: PED5 | AQ1: PED6 | AR1: PED7 | AS1: IA1 | AT1: IA2 | AU1: IA3 | AV1: IA4 | AW1: IA5 | AX1: IA6 | AY1: IA7 | AZ1: IA8 | BA1: IA_TEMAS | BB1: OBJ_PUNTAJE | BC1: OBJ1 | BD1: OBJ2 | BE1: OBJ3 | BF1: OBJ4 | BG1: OBJ5 | BH1: OBJ6 | BI1: OBJ7 | BJ1: OBJ8 | BK1: OBJ9 | BL1: ACT3r | BM1: ACT6r | BN1: S_Act | BO1: S_Inf | BP1: S_Com | BQ1: S_Seg | BR1: S_Ped | BS1: S_IA | BT1: M_Actitud | BU1: M_Info | BV1: M_Com | BW1: M_Seg | BX1: M_Ped | BY1: M_IA | BZ1: Disp_IA | CA1: N_Actitud | CB1: N_Info | CC1: N_Com | CD1: N_Seg | CE1: N_Ped | CF1: N_IA | CG1: Obj_pct | CH1: N_Obj | CI1: AutoPct | CJ1: Señal
A2: ENSMA-01 | B2: Karla Mariana Gallo Tehelen | C2: Ingles@ensumauxisoacha.edu.co | D2: Primaria | E2: Idioma Extranjero | F2: 3 a 10 | G2: Computador propio | H2: Estable | I2: Ninguna | J2: 5 | K2: 5 | L2: 5 | M2: 5 | N2: 5 | O2: 5 | P2: 5 | Q2: 5 | R2: 5 | S2: 4 | T2: 5 | U2: 4 | V2: 3 | W2: 4 | X2: Diario | Y2: 5 | Z2: 5 | AA2: 5 | AB2: 5 | AC2: 5 | AD2: Nunca | AE2: 5 | AF2: 3 | AG2: 3 | AH2: 4 | AI2: 4 | AJ2: 5 | AK2: 4 | AL2: 4 | AM2: 4 | AN2: 4 | AO2: 4 | AP2: 4 | AQ2: 4 | AR2: 4 | AS2: 5 | AT2: 5 | AU2: 4 | AV2: 5 | AW2: 4 | AX2: 4 | AY2: 3 | AZ2: 5 | BA2: Creación de materiales, Evaluación y retroalimentación, Uso con estudiantes, Herramientas específicas | BB2: 9 | BC2: 1 | BD2: 1 | BE2: 1 | BF2: 1 | BG2: 1 | BH2: 1 | BI2: 1 | BJ2: 1 | BK2: 1 | BL2: =IF($B2="","",6-L2) -> 1 | BM2: =IF($B2="","",6-O2) -> 1 | BN2: =IF($B2="","",J2+K2+BL2+M2+N2+BM2+P2+Q2+R2) -> 37 | BO2: =IF($B2="","",SUM(S2:W2)) -> 20 | BP2: =IF($B2="","",SUM(Y2:AC2)) -> 25 | BQ2: =IF($B2="","",SUM(AE2:AK2)) -> 28 | BR2: =IF($B2="","",SUM(AL2:AR2)) -> 28 | BS2: =IF($B2="","",SUM(AS2:AY2)) -> 30 | BT2: =IF($B2="","",BN2/9) -> 4.1111111 | BU2: =IF($B2="","",BO2/5) -> 4 | BV2: =IF($B2="","",BP2/5) -> 5 | BW2: =IF($B2="","",BQ2/7) -> 4 | BX2: =IF($B2="","",BR2/7) -> 4 | BY2: =IF($B2="","",BS2/7) -> 4.2857143 | BZ2: =IF($B2="","",AZ2) -> 5 | CA2: =IF($B2="","",IF(BT2<2.5,"Explorador",IF(BT2<3.75,"Integrador","Innovador"))) -> Innovador | CB2: =IF($B2="","",IF(BU2<2.5,"Explorador",IF(BU2<3.75,"Integrador","Innovador"))) -> Innovador | CC2: =IF($B2="","",IF(BV2<2.5,"Explorador",IF(BV2<3.75,"Integrador","Innovador"))) -> Innovador | CD2: =IF($B2="","",IF(BW2<2.5,"Explorador",IF(BW2<3.75,"Integrador","Innovador"))) -> Innovador | CE2: =IF($B2="","",IF(BX2<2.5,"Explorador",IF(BX2<3.75,"Integrador","Innovador"))) -> Innovador | CF2: =IF($B2="","",IF(BY2<2.5,"Explorador",IF(BY2<3.75,"Integrador","Innovador"))) -> Innovador | CG2: =IF($B2="","",BB2/9) -> 1 | CH2: =IF($B2="","",IF(CG2<0.4,"Bajo",IF(CG2<0.7,"Medio","Alto"))) -> Alto | CI2: =IF($B2="","",((AVERAGE(BU2,BW2,BY2))-1)/4) -> 0.77380952 | CJ2: =IF($B2="","",IF(CG2-CI2>0.25,"Subvalora",IF(CI2-CG2>0.25,"Sobreconfía","Consistente"))) -> Consistente
A3: ENSMA-02 | B3: Laura Katherin Rodríguez Caucali | C3: Psicoorientacion01@ensumauxisoacha.edu.co | D3: Preescolar | E3: Otra | F3: 3 a 10 | G3: Computador institucional | H3: Estable | I3: Informal o autodidacta | J3: 4 | K3: 5 | L3: 3 | M3: 4 | N3: 5 | O3: 3 | P3: 5 | Q3: 4 | R3: 5 | S3: 3 | T3: 4 | U3: 4 | V3: 5 | W3: 1 | X3: Semanal | Y3: 5 | Z3: 5 | AA3: 5 | AB3: 5 | AC3: 5 | AD3: Nunca | AE3: 4 | AF3: 5 | AG3: 5 | AH3: 3 | AI3: 5 | AJ3: 5 | AK3: 5 | AL3: 4 | AM3: 4 | AN3: 4 | AO3: 4 | AP3: 4 | AQ3: 4 | AR3: 4 | AS3: 4 | AT3: 5 | AU3: 5 | AV3: 5 | AW3: 3 | AX3: 5 | AY3: 4 | AZ3: 5 | BA3: Creación de materiales, Evaluación y retroalimentación, Herramientas específicas | BB3: 7 | BC3: 1 | BD3: 1 | BE3: 1 | BF3: 0 | BG3: 1 | BH3: 1 | BI3: 1 | BJ3: 0 | BK3: 1 | BL3: =IF($B3="","",6-L3) -> 3 | BM3: =IF($B3="","",6-O3) -> 3 | BN3: =IF($B3="","",J3+K3+BL3+M3+N3+BM3+P3+Q3+R3) -> 38 | BO3: =IF($B3="","",SUM(S3:W3)) -> 17 | BP3: =IF($B3="","",SUM(Y3:AC3)) -> 25 | BQ3: =IF($B3="","",SUM(AE3:AK3)) -> 32 | BR3: =IF($B3="","",SUM(AL3:AR3)) -> 28 | BS3: =IF($B3="","",SUM(AS3:AY3)) -> 31 | BT3: =IF($B3="","",BN3/9) -> 4.2222222 | BU3: =IF($B3="","",BO3/5) -> 3.4 | BV3: =IF($B3="","",BP3/5) -> 5 | BW3: =IF($B3="","",BQ3/7) -> 4.5714286 | BX3: =IF($B3="","",BR3/7) -> 4 | BY3: =IF($B3="","",BS3/7) -> 4.4285714 | BZ3: =IF($B3="","",AZ3) -> 5 | CA3: =IF($B3="","",IF(BT3<2.5,"Explorador",IF(BT3<3.75,"Integrador","Innovador"))) -> Innovador | CB3: =IF($B3="","",IF(BU3<2.5,"Explorador",IF(BU3<3.75,"Integrador","Innovador"))) -> Integrador | CC3: =IF($B3="","",IF(BV3<2.5,"Explorador",IF(BV3<3.75,"Integrador","Innovador"))) -> Innovador | CD3: =IF($B3="","",IF(BW3<2.5,"Explorador",IF(BW3<3.75,"Integrador","Innovador"))) -> Innovador | CE3: =IF($B3="","",IF(BX3<2.5,"Explorador",IF(BX3<3.75,"Integrador","Innovador"))) -> Innovador | CF3: =IF($B3="","",IF(BY3<2.5,"Explorador",IF(BY3<3.75,"Integrador","Innovador"))) -> Innovador | CG3: =IF($B3="","",BB3/9) -> 0.77777778 | CH3: =IF($B3="","",IF(CG3<0.4,"Bajo",IF(CG3<0.7,"Medio","Alto"))) -> Alto | CI3: =IF($B3="","",((AVERAGE(BU3,BW3,BY3))-1)/4) -> 0.78333333 | CJ3: =IF($B3="","",IF(CG3-CI3>0.25,"Subvalora",IF(CI3-CG3>0.25,"Sobreconfía","Consistente"))) -> Consistente
A4: ENSMA-03 | B4: Jorge Iván Hernández Loaiza | C4: Ivanhernandez@ensumauxisoacha.edu.co | D4: Secundaria | E4: Matemáticas | F4: 3 a 10 | G4: Computador propio | H4: Limitada | I4: Cursos cortos | J4: 5 | K4: 5 | L4: 1 | M4: 5 | N4: 5 | O4: 2 | P4: 4 | Q4: 5 | R4: 4 | S4: 5 | T4: 5 | U4: 5 | V4: 5 | W4: 4 | X4: Diario | Y4: 5 | Z4: 5 | AA4: 5 | AB4: 4 | AC4: 5 | AD4: Semanal | AE4: 5 | AF4: 3 | AG4: 3 | AH4: 3 | AI4: 4 | AJ4: 4 | AK4: 3 | AL4: 4 | AM4: 4 | AN4: 5 | AO4: 4 | AP4: 3 | AQ4: 4 | AR4: 3 | AS4: 4 | AT4: 4 | AU4: 4 | AV4: 4 | AW4: 4 | AX4: 4 | AY4: 3 | AZ4: 5 | BA4: Creación de materiales, Evaluación y retroalimentación, Uso con estudiantes, Herramientas específicas | BB4: 8 | BC4: 1 | BD4: 1 | BE4: 1 | BF4: 0 | BG4: 1 | BH4: 1 | BI4: 1 | BJ4: 1 | BK4: 1 | BL4: =IF($B4="","",6-L4) -> 5 | BM4: =IF($B4="","",6-O4) -> 4 | BN4: =IF($B4="","",J4+K4+BL4+M4+N4+BM4+P4+Q4+R4) -> 42 | BO4: =IF($B4="","",SUM(S4:W4)) -> 24 | BP4: =IF($B4="","",SUM(Y4:AC4)) -> 24 | BQ4: =IF($B4="","",SUM(AE4:AK4)) -> 25 | BR4: =IF($B4="","",SUM(AL4:AR4)) -> 27 | BS4: =IF($B4="","",SUM(AS4:AY4)) -> 27 | BT4: =IF($B4="","",BN4/9) -> 4.6666667 | BU4: =IF($B4="","",BO4/5) -> 4.8 | BV4: =IF($B4="","",BP4/5) -> 4.8 | BW4: =IF($B4="","",BQ4/7) -> 3.5714286 | BX4: =IF($B4="","",BR4/7) -> 3.8571429 | BY4: =IF($B4="","",BS4/7) -> 3.8571429 | BZ4: =IF($B4="","",AZ4) -> 5 | CA4: =IF($B4="","",IF(BT4<2.5,"Explorador",IF(BT4<3.75,"Integrador","Innovador"))) -> Innovador | CB4: =IF($B4="","",IF(BU4<2.5,"Explorador",IF(BU4<3.75,"Integrador","Innovador"))) -> Innovador | CC4: =IF($B4="","",IF(BV4<2.5,"Explorador",IF(BV4<3.75,"Integrador","Innovador"))) -> Innovador | CD4: =IF($B4="","",IF(BW4<2.5,"Explorador",IF(BW4<3.75,"Integrador","Innovador"))) -> Integrador | CE4: =IF($B4="","",IF(BX4<2.5,"Explorador",IF(BX4<3.75,"Integrador","Innovador"))) -> Innovador | CF4: =IF($B4="","",IF(BY4<2.5,"Explorador",IF(BY4<3.75,"Integrador","Innovador"))) -> Innovador | CG4: =IF($B4="","",BB4/9) -> 0.88888889 | CH4: =IF($B4="","",IF(CG4<0.4,"Bajo",IF(CG4<0.7,"Medio","Alto"))) -> Alto | CI4: =IF($B4="","",((AVERAGE(BU4,BW4,BY4))-1)/4) -> 0.76904762 | CJ4: =IF($B4="","",IF(CG4-CI4>0.25,"Subvalora",IF(CI4-CG4>0.25,"Sobreconfía","Consistente"))) -> Consistente
A5: ENSMA-04 | B5: Carlos Augusto Gómez Gualteros | C5: carlosgomez@ensumauxisoacha.edu.co | D5: Primaria | E5: Otra | F5: 3 a 10 | G5: Computador propio | H5: Estable | I5: Informal o autodidacta | J5: 4 | K5: 5 | L5: 1 | M5: 1 | N5: 5 | O5: 2 | P5: 2 | Q5: 5 | R5: 4 | S5: 5 | T5: 5 | U5: 3 | V5: 5 | W5: 4 | X5: Semanal | Y5: 5 | Z5: 5 | AA5: 5 | AB5: 4 | AC5: 3 | AD5: Semanal | AE5: 3 | AF5: 5 | AG5: 4 | AH5: 5 | AI5: 5 | AJ5: 5 | AK5: 5 | AL5: 5 | AM5: 4 | AN5: 4 | AO5: 2 | AP5: 4 | AQ5: 3 | AR5: 4 | AS5: 4 | AT5: 4 | AU5: 3 | AV5: 5 | AW5: 4 | AX5: 2 | AY5: 4 | AZ5: 5 | BA5: Fundamentos, Creación de materiales, Evaluación y retroalimentación, Ética e integridad, Uso con estudiantes, Herramientas específicas | BB5: 9 | BC5: 1 | BD5: 1 | BE5: 1 | BF5: 1 | BG5: 1 | BH5: 1 | BI5: 1 | BJ5: 1 | BK5: 1 | BL5: =IF($B5="","",6-L5) -> 5 | BM5: =IF($B5="","",6-O5) -> 4 | BN5: =IF($B5="","",J5+K5+BL5+M5+N5+BM5+P5+Q5+R5) -> 35 | BO5: =IF($B5="","",SUM(S5:W5)) -> 22 | BP5: =IF($B5="","",SUM(Y5:AC5)) -> 22 | BQ5: =IF($B5="","",SUM(AE5:AK5)) -> 32 | BR5: =IF($B5="","",SUM(AL5:AR5)) -> 26 | BS5: =IF($B5="","",SUM(AS5:AY5)) -> 26 | BT5: =IF($B5="","",BN5/9) -> 3.8888889 | BU5: =IF($B5="","",BO5/5) -> 4.4 | BV5: =IF($B5="","",BP5/5) -> 4.4 | BW5: =IF($B5="","",BQ5/7) -> 4.5714286 | BX5: =IF($B5="","",BR5/7) -> 3.7142857 | BY5: =IF($B5="","",BS5/7) -> 3.7142857 | BZ5: =IF($B5="","",AZ5) -> 5 | CA5: =IF($B5="","",IF(BT5<2.5,"Explorador",IF(BT5<3.75,"Integrador","Innovador"))) -> Innovador | CB5: =IF($B5="","",IF(BU5<2.5,"Explorador",IF(BU5<3.75,"Integrador","Innovador"))) -> Innovador | CC5: =IF($B5="","",IF(BV5<2.5,"Explorador",IF(BV5<3.75,"Integrador","Innovador"))) -> Innovador | CD5: =IF($B5="","",IF(BW5<2.5,"Explorador",IF(BW5<3.75,"Integrador","Innovador"))) -> Innovador | CE5: =IF($B5="","",IF(BX5<2.5,"Explorador",IF(BX5<3.75,"Integrador","Innovador"))) -> Integrador | CF5: =IF($B5="","",IF(BY5<2.5,"Explorador",IF(BY5<3.75,"Integrador","Innovador"))) -> Integrador | CG5: =IF($B5="","",BB5/9) -> 1 | CH5: =IF($B5="","",IF(CG5<0.4,"Bajo",IF(CG5<0.7,"Medio","Alto"))) -> Alto | CI5: =IF($B5="","",((AVERAGE(BU5,BW5,BY5))-1)/4) -> 0.80714286 | CJ5: =IF($B5="","",IF(CG5-CI5>0.25,"Subvalora",IF(CI5-CG5>0.25,"Sobreconfía","Consistente"))) -> Consistente
A6: ENSMA-05 | B6: Gabriel Andrés Moreno Angarita | C6: gabrielmoreno@ensumauxisoacha.edu.co | D6: Secundaria | E6: Educación Religiosa | F6: Más de 20 | G6: Computador propio | H6: Estable | I6: Informal o autodidacta | J6: 5 | K6: 5 | L6: 1 | M6: 5 | N6: 5 | O6: 1 | P6: 5 | Q6: 5 | R6: 5 | S6: 4 | T6: 5 | U6: 5 | V6: 3 | W6: 5 | X6: Diario | Y6: 4 | Z6: 2 | AA6: 5 | AB6: 3 | AC6: 2 | AD6: Nunca | AE6: 5 | AF6: 5 | AG6: 4 | AH6: 3 | AI6: 5 | AJ6: 4 | AK6: 5 | AL6: 4 | AM6: 4 | AN6: 3 | AO6: 2 | AP6: 5 | AQ6: 5 | AR6: 5 | AS6: 5 | AT6: 5 | AU6: 5 | AV6: 5 | AW6: 5 | AX6: 5 | AY6: 4 | AZ6: 5 | BA6: Evaluación y retroalimentación | BB6: 9 | BC6: 1 | BD6: 1 | BE6: 1 | BF6: 1 | BG6: 1 | BH6: 1 | BI6: 1 | BJ6: 1 | BK6: 1 | BL6: =IF($B6="","",6-L6) -> 5 | BM6: =IF($B6="","",6-O6) -> 5 | BN6: =IF($B6="","",J6+K6+BL6+M6+N6+BM6+P6+Q6+R6) -> 45 | BO6: =IF($B6="","",SUM(S6:W6)) -> 22 | BP6: =IF($B6="","",SUM(Y6:AC6)) -> 16 | BQ6: =IF($B6="","",SUM(AE6:AK6)) -> 31 | BR6: =IF($B6="","",SUM(AL6:AR6)) -> 28 | BS6: =IF($B6="","",SUM(AS6:AY6)) -> 34 | BT6: =IF($B6="","",BN6/9) -> 5 | BU6: =IF($B6="","",BO6/5) -> 4.4 | BV6: =IF($B6="","",BP6/5) -> 3.2 | BW6: =IF($B6="","",BQ6/7) -> 4.4285714 | BX6: =IF($B6="","",BR6/7) -> 4 | BY6: =IF($B6="","",BS6/7) -> 4.8571429 | BZ6: =IF($B6="","",AZ6) -> 5 | CA6: =IF($B6="","",IF(BT6<2.5,"Explorador",IF(BT6<3.75,"Integrador","Innovador"))) -> Innovador | CB6: =IF($B6="","",IF(BU6<2.5,"Explorador",IF(BU6<3.75,"Integrador","Innovador"))) -> Innovador | CC6: =IF($B6="","",IF(BV6<2.5,"Explorador",IF(BV6<3.75,"Integrador","Innovador"))) -> Integrador | CD6: =IF($B6="","",IF(BW6<2.5,"Explorador",IF(BW6<3.75,"Integrador","Innovador"))) -> Innovador | CE6: =IF($B6="","",IF(BX6<2.5,"Explorador",IF(BX6<3.75,"Integrador","Innovador"))) -> Innovador | CF6: =IF($B6="","",IF(BY6<2.5,"Explorador",IF(BY6<3.75,"Integrador","Innovador"))) -> Innovador | CG6: =IF($B6="","",BB6/9) -> 1 | CH6: =IF($B6="","",IF(CG6<0.4,"Bajo",IF(CG6<0.7,"Medio","Alto"))) -> Alto | CI6: =IF($B6="","",((AVERAGE(BU6,BW6,BY6))-1)/4) -> 0.89047619 | CJ6: =IF($B6="","",IF(CG6-CI6>0.25,"Subvalora",IF(CI6-CG6>0.25,"Sobreconfía","Consistente"))) -> Consistente
A7: ENSMA-06 | B7: Laura Milena Casallas Velandia | C7: Lauracasallas@ensumauxisoacha.edu.co | D7: Secundaria | E7: Educación Física | F7: 3 a 10 | G7: Computador propio | H7: Intermitente | I7: Ninguna | J7: 4 | K7: 5 | L7: 1 | M7: 5 | N7: 5 | O7: 2 | P7: 4 | Q7: 4 | R7: 5 | S7: 3 | T7: 4 | U7: 4 | V7: 5 | W7: 2 | X7: Semanal | Y7: 5 | Z7: 5 | AA7: 4 | AB7: 4 | AC7: 1 | AD7: Nunca | AE7: 5 | AF7: 4 | AG7: 4 | AH7: 2 | AI7: 5 | AJ7: 5 | AK7: 4 | AL7: 4 | AM7: 4 | AN7: 1 | AO7: 1 | AP7: 4 | AQ7: 4 | AR7: 1 | AS7: 5 | AT7: 4 | AU7: 4 | AV7: 3 | AW7: 4 | AX7: 4 | AY7: 4 | AZ7: 4 | BA7: Fundamentos, Creación de materiales, Evaluación y retroalimentación, Ética e integridad, Uso con estudiantes, Herramientas específicas | BB7: 9 | BC7: 1 | BD7: 1 | BE7: 1 | BF7: 1 | BG7: 1 | BH7: 1 | BI7: 1 | BJ7: 1 | BK7: 1 | BL7: =IF($B7="","",6-L7) -> 5 | BM7: =IF($B7="","",6-O7) -> 4 | BN7: =IF($B7="","",J7+K7+BL7+M7+N7+BM7+P7+Q7+R7) -> 41 | BO7: =IF($B7="","",SUM(S7:W7)) -> 18 | BP7: =IF($B7="","",SUM(Y7:AC7)) -> 19 | BQ7: =IF($B7="","",SUM(AE7:AK7)) -> 29 | BR7: =IF($B7="","",SUM(AL7:AR7)) -> 19 | BS7: =IF($B7="","",SUM(AS7:AY7)) -> 28 | BT7: =IF($B7="","",BN7/9) -> 4.5555556 | BU7: =IF($B7="","",BO7/5) -> 3.6 | BV7: =IF($B7="","",BP7/5) -> 3.8 | BW7: =IF($B7="","",BQ7/7) -> 4.1428571 | BX7: =IF($B7="","",BR7/7) -> 2.7142857 | BY7: =IF($B7="","",BS7/7) -> 4 | BZ7: =IF($B7="","",AZ7) -> 4 | CA7: =IF($B7="","",IF(BT7<2.5,"Explorador",IF(BT7<3.75,"Integrador","Innovador"))) -> Innovador | CB7: =IF($B7="","",IF(BU7<2.5,"Explorador",IF(BU7<3.75,"Integrador","Innovador"))) -> Integrador | CC7: =IF($B7="","",IF(BV7<2.5,"Explorador",IF(BV7<3.75,"Integrador","Innovador"))) -> Innovador | CD7: =IF($B7="","",IF(BW7<2.5,"Explorador",IF(BW7<3.75,"Integrador","Innovador"))) -> Innovador | CE7: =IF($B7="","",IF(BX7<2.5,"Explorador",IF(BX7<3.75,"Integrador","Innovador"))) -> Integrador | CF7: =IF($B7="","",IF(BY7<2.5,"Explorador",IF(BY7<3.75,"Integrador","Innovador"))) -> Innovador | CG7: =IF($B7="","",BB7/9) -> 1 | CH7: =IF($B7="","",IF(CG7<0.4,"Bajo",IF(CG7<0.7,"Medio","Alto"))) -> Alto | CI7: =IF($B7="","",((AVERAGE(BU7,BW7,BY7))-1)/4) -> 0.72857143 | CJ7: =IF($B7="","",IF(CG7-CI7>0.25,"Subvalora",IF(CI7-CG7>0.25,"Sobreconfía","Consistente"))) -> Subvalora
A8: ENSMA-07 | B8: Norma constanza ortiz cañon | C8: normaortiz@ensumauxisoacha | D8: Primaria | E8: Idioma Extranjero | F8: 11 a 20 | G8: Computador propio | H8: Estable | I8: Informal o autodidacta | J8: 5 | K8: 4 | L8: 3 | M8: 5 | N8: 5 | O8: 3 | P8: 5 | Q8: 4 | R8: 5 | S8: 3 | T8: 4 | U8: 4 | V8: 3 | W8: 2 | X8: Diario | Y8: 5 | Z8: 5 | AA8: 5 | AB8: 5 | AC8: 3 | AD8: Nunca | AE8: 4 | AF8: 2 | AG8: 2 | AH8: 2 | AI8: 3 | AJ8: 2 | AK8: 3 | AL8: 5 | AM8: 5 | AN8: 4 | AO8: 5 | AP8: 5 | AQ8: 4 | AR8: 3 | AS8: 3 | AT8: 4 | AU8: 3 | AV8: 4 | AW8: 3 | AX8: 3 | AY8: 2 | AZ8: 4 | BA8: Fundamentos, Creación de materiales, Uso con estudiantes, Herramientas específicas | BB8: 9 | BC8: 1 | BD8: 1 | BE8: 1 | BF8: 1 | BG8: 1 | BH8: 1 | BI8: 1 | BJ8: 1 | BK8: 1 | BL8: =IF($B8="","",6-L8) -> 3 | BM8: =IF($B8="","",6-O8) -> 3 | BN8: =IF($B8="","",J8+K8+BL8+M8+N8+BM8+P8+Q8+R8) -> 39 | BO8: =IF($B8="","",SUM(S8:W8)) -> 16 | BP8: =IF($B8="","",SUM(Y8:AC8)) -> 23 | BQ8: =IF($B8="","",SUM(AE8:AK8)) -> 18 | BR8: =IF($B8="","",SUM(AL8:AR8)) -> 31 | BS8: =IF($B8="","",SUM(AS8:AY8)) -> 22 | BT8: =IF($B8="","",BN8/9) -> 4.3333333 | BU8: =IF($B8="","",BO8/5) -> 3.2 | BV8: =IF($B8="","",BP8/5) -> 4.6 | BW8: =IF($B8="","",BQ8/7) -> 2.5714286 | BX8: =IF($B8="","",BR8/7) -> 4.4285714 | BY8: =IF($B8="","",BS8/7) -> 3.1428571 | BZ8: =IF($B8="","",AZ8) -> 4 | CA8: =IF($B8="","",IF(BT8<2.5,"Explorador",IF(BT8<3.75,"Integrador","Innovador"))) -> Innovador | CB8: =IF($B8="","",IF(BU8<2.5,"Explorador",IF(BU8<3.75,"Integrador","Innovador"))) -> Integrador | CC8: =IF($B8="","",IF(BV8<2.5,"Explorador",IF(BV8<3.75,"Integrador","Innovador"))) -> Innovador | CD8: =IF($B8="","",IF(BW8<2.5,"Explorador",IF(BW8<3.75,"Integrador","Innovador"))) -> Integrador | CE8: =IF($B8="","",IF(BX8<2.5,"Explorador",IF(BX8<3.75,"Integrador","Innovador"))) -> Innovador | CF8: =IF($B8="","",IF(BY8<2.5,"Explorador",IF(BY8<3.75,"Integrador","Innovador"))) -> Integrador | CG8: =IF($B8="","",BB8/9) -> 1 | CH8: =IF($B8="","",IF(CG8<0.4,"Bajo",IF(CG8<0.7,"Medio","Alto"))) -> Alto | CI8: =IF($B8="","",((AVERAGE(BU8,BW8,BY8))-1)/4) -> 0.49285714 | CJ8: =IF($B8="","",IF(CG8-CI8>0.25,"Subvalora",IF(CI8-CG8>0.25,"Sobreconfía","Consistente"))) -> Subvalora
A9: ENSMA-08 | B9: Angela Viviana Alarcón Alfonso | C9: angelavivianaalarcon@ensumauxisoacha.edu.co | D9: Primaria | E9: Ciencias Sociales | F9: 11 a 20 | G9: Computador institucional | H9: Intermitente | I9: Informal o autodidacta | J9: 4 | K9: 5 | L9: 1 | M9: 5 | N9: 5 | O9: 1 | P9: 4 | Q9: 5 | R9: 5 | S9: 4 | T9: 4 | U9: 2 | V9: 5 | W9: 3 | X9: Semanal | Y9: 5 | Z9: 5 | AA9: 4 | AB9: 3 | AC9: 2 | AD9: Nunca | AE9: 4 | AF9: 4 | AG9: 3 | AH9: 1 | AI9: 4 | AJ9: 3 | AK9: 4 | AL9: 3 | AM9: 2 | AN9: 1 | AO9: 1 | AP9: 1 | AQ9: 2 | AR9: 1 | AS9: 4 | AT9: 4 | AU9: 3 | AV9: 4 | AW9: 2 | AX9: 2 | AY9: 2 | AZ9: 4 | BA9: Creación de materiales, Evaluación y retroalimentación, Ética e integridad, Herramientas específicas | BB9: 9 | BC9: 1 | BD9: 1 | BE9: 1 | BF9: 1 | BG9: 1 | BH9: 1 | BI9: 1 | BJ9: 1 | BK9: 1 | BL9: =IF($B9="","",6-L9) -> 5 | BM9: =IF($B9="","",6-O9) -> 5 | BN9: =IF($B9="","",J9+K9+BL9+M9+N9+BM9+P9+Q9+R9) -> 43 | BO9: =IF($B9="","",SUM(S9:W9)) -> 18 | BP9: =IF($B9="","",SUM(Y9:AC9)) -> 19 | BQ9: =IF($B9="","",SUM(AE9:AK9)) -> 23 | BR9: =IF($B9="","",SUM(AL9:AR9)) -> 11 | BS9: =IF($B9="","",SUM(AS9:AY9)) -> 21 | BT9: =IF($B9="","",BN9/9) -> 4.7777778 | BU9: =IF($B9="","",BO9/5) -> 3.6 | BV9: =IF($B9="","",BP9/5) -> 3.8 | BW9: =IF($B9="","",BQ9/7) -> 3.2857143 | BX9: =IF($B9="","",BR9/7) -> 1.5714286 | BY9: =IF($B9="","",BS9/7) -> 3 | BZ9: =IF($B9="","",AZ9) -> 4 | CA9: =IF($B9="","",IF(BT9<2.5,"Explorador",IF(BT9<3.75,"Integrador","Innovador"))) -> Innovador | CB9: =IF($B9="","",IF(BU9<2.5,"Explorador",IF(BU9<3.75,"Integrador","Innovador"))) -> Integrador | CC9: =IF($B9="","",IF(BV9<2.5,"Explorador",IF(BV9<3.75,"Integrador","Innovador"))) -> Innovador | CD9: =IF($B9="","",IF(BW9<2.5,"Explorador",IF(BW9<3.75,"Integrador","Innovador"))) -> Integrador | CE9: =IF($B9="","",IF(BX9<2.5,"Explorador",IF(BX9<3.75,"Integrador","Innovador"))) -> Explorador | CF9: =IF($B9="","",IF(BY9<2.5,"Explorador",IF(BY9<3.75,"Integrador","Innovador"))) -> Integrador | CG9: =IF($B9="","",BB9/9) -> 1 | CH9: =IF($B9="","",IF(CG9<0.4,"Bajo",IF(CG9<0.7,"Medio","Alto"))) -> Alto | CI9: =IF($B9="","",((AVERAGE(BU9,BW9,BY9))-1)/4) -> 0.57380952 | CJ9: =IF($B9="","",IF(CG9-CI9>0.25,"Subvalora",IF(CI9-CG9>0.25,"Sobreconfía","Consistente"))) -> Subvalora
A10: ENSMA-09 | B10: Gustavo Adolfo Toscano Gaitán | C10: Gustavotoscano@ensumauxisoacha.edu.co | D10: Secundaria | E10: Idioma Extranjero | F10: 11 a 20 | G10: Computador propio | H10: Intermitente | I10: Posgrado o certificación formal | J10: 4 | K10: 5 | L10: 1 | M10: 3 | N10: 5 | O10: 1 | P10: 5 | Q10: 4 | R10: 5 | S10: 5 | T10: 5 | U10: 5 | V10: 5 | W10: 5 | X10: Semanal | Y10: 5 | Z10: 3 | AA10: 5 | AB10: 4 | AC10: 5 | AD10: Nunca | AE10: 5 | AF10: 3 | AG10: 4 | AH10: 5 | AI10: 5 | AJ10: 5 | AK10: 3 | AL10: 5 | AM10: 5 | AN10: 5 | AO10: 3 | AP10: 5 | AQ10: 5 | AR10: 5 | AS10: 5 | AT10: 4 | AU10: 5 | AV10: 5 | AW10: 5 | AX10: 5 | AY10: 4 | AZ10: 3 | BA10: Uso con estudiantes, Herramientas específicas | BB10: 9 | BC10: 1 | BD10: 1 | BE10: 1 | BF10: 1 | BG10: 1 | BH10: 1 | BI10: 1 | BJ10: 1 | BK10: 1 | BL10: =IF($B10="","",6-L10) -> 5 | BM10: =IF($B10="","",6-O10) -> 5 | BN10: =IF($B10="","",J10+K10+BL10+M10+N10+BM10+P10+Q10+R10) -> 41 | BO10: =IF($B10="","",SUM(S10:W10)) -> 25 | BP10: =IF($B10="","",SUM(Y10:AC10)) -> 22 | BQ10: =IF($B10="","",SUM(AE10:AK10)) -> 30 | BR10: =IF($B10="","",SUM(AL10:AR10)) -> 33 | BS10: =IF($B10="","",SUM(AS10:AY10)) -> 33 | BT10: =IF($B10="","",BN10/9) -> 4.5555556 | BU10: =IF($B10="","",BO10/5) -> 5 | BV10: =IF($B10="","",BP10/5) -> 4.4 | BW10: =IF($B10="","",BQ10/7) -> 4.2857143 | BX10: =IF($B10="","",BR10/7) -> 4.7142857 | BY10: =IF($B10="","",BS10/7) -> 4.7142857 | BZ10: =IF($B10="","",AZ10) -> 3 | CA10: =IF($B10="","",IF(BT10<2.5,"Explorador",IF(BT10<3.75,"Integrador","Innovador"))) -> Innovador | CB10: =IF($B10="","",IF(BU10<2.5,"Explorador",IF(BU10<3.75,"Integrador","Innovador"))) -> Innovador | CC10: =IF($B10="","",IF(BV10<2.5,"Explorador",IF(BV10<3.75,"Integrador","Innovador"))) -> Innovador | CD10: =IF($B10="","",IF(BW10<2.5,"Explorador",IF(BW10<3.75,"Integrador","Innovador"))) -> Innovador | CE10: =IF($B10="","",IF(BX10<2.5,"Explorador",IF(BX10<3.75,"Integrador","Innovador"))) -> Innovador | CF10: =IF($B10="","",IF(BY10<2.5,"Explorador",IF(BY10<3.75,"Integrador","Innovador"))) -> Innovador | CG10: =IF($B10="","",BB10/9) -> 1 | CH10: =IF($B10="","",IF(CG10<0.4,"Bajo",IF(CG10<0.7,"Medio","Alto"))) -> Alto | CI10: =IF($B10="","",((AVERAGE(BU10,BW10,BY10))-1)/4) -> 0.91666667 | CJ10: =IF($B10="","",IF(CG10-CI10>0.25,"Subvalora",IF(CI10-CG10>0.25,"Sobreconfía","Consistente"))) -> Consistente
A11: ENSMA-10 | B11: Kelly Jalexy Díaz Olaya | C11: Investigación@ensumauxisoacha.edu.co | D11: Secundaria | E11: Ciencias Naturales | F11: 3 a 10 | G11: Computador propio | H11: Intermitente | I11: Informal o autodidacta | J11: 5 | K11: 4 | L11: 1 | M11: 5 | N11: 5 | O11: 1 | P11: 5 | Q11: 5 | R11: 5 | S11: 5 | T11: 5 | U11: 5 | V11: 5 | W11: 5 | X11: Diario | Y11: 5 | Z11: 5 | AA11: 5 | AB11: 5 | AC11: 5 | AD11: Nunca | AE11: 5 | AF11: 5 | AG11: 3 | AH11: 3 | AI11: 5 | AJ11: 5 | AK11: 5 | AL11: 5 | AM11: 4 | AN11: 5 | AO11: 4 | AP11: 5 | AQ11: 5 | AR11: 4 | AS11: 5 | AT11: 4 | AU11: 5 | AV11: 4 | AW11: 5 | AX11: 5 | AY11: 4 | AZ11: 5 | BA11: Fundamentos, Creación de materiales, Evaluación y retroalimentación, Ética e integridad, Uso con estudiantes, Herramientas específicas | BB11: 9 | BC11: 1 | BD11: 1 | BE11: 1 | BF11: 1 | BG11: 1 | BH11: 1 | BI11: 1 | BJ11: 1 | BK11: 1 | BL11: =IF($B11="","",6-L11) -> 5 | BM11: =IF($B11="","",6-O11) -> 5 | BN11: =IF($B11="","",J11+K11+BL11+M11+N11+BM11+P11+Q11+R11) -> 44 | BO11: =IF($B11="","",SUM(S11:W11)) -> 25 | BP11: =IF($B11="","",SUM(Y11:AC11)) -> 25 | BQ11: =IF($B11="","",SUM(AE11:AK11)) -> 31 | BR11: =IF($B11="","",SUM(AL11:AR11)) -> 32 | BS11: =IF($B11="","",SUM(AS11:AY11)) -> 32 | BT11: =IF($B11="","",BN11/9) -> 4.8888889 | BU11: =IF($B11="","",BO11/5) -> 5 | BV11: =IF($B11="","",BP11/5) -> 5 | BW11: =IF($B11="","",BQ11/7) -> 4.4285714 | BX11: =IF($B11="","",BR11/7) -> 4.5714286 | BY11: =IF($B11="","",BS11/7) -> 4.5714286 | BZ11: =IF($B11="","",AZ11) -> 5 | CA11: =IF($B11="","",IF(BT11<2.5,"Explorador",IF(BT11<3.75,"Integrador","Innovador"))) -> Innovador | CB11: =IF($B11="","",IF(BU11<2.5,"Explorador",IF(BU11<3.75,"Integrador","Innovador"))) -> Innovador | CC11: =IF($B11="","",IF(BV11<2.5,"Explorador",IF(BV11<3.75,"Integrador","Innovador"))) -> Innovador | CD11: =IF($B11="","",IF(BW11<2.5,"Explorador",IF(BW11<3.75,"Integrador","Innovador"))) -> Innovador | CE11: =IF($B11="","",IF(BX11<2.5,"Explorador",IF(BX11<3.75,"Integrador","Innovador"))) -> Innovador | CF11: =IF($B11="","",IF(BY11<2.5,"Explorador",IF(BY11<3.75,"Integrador","Innovador"))) -> Innovador | CG11: =IF($B11="","",BB11/9) -> 1 | CH11: =IF($B11="","",IF(CG11<0.4,"Bajo",IF(CG11<0.7,"Medio","Alto"))) -> Alto | CI11: =IF($B11="","",((AVERAGE(BU11,BW11,BY11))-1)/4) -> 0.91666667 | CJ11: =IF($B11="","",IF(CG11-CI11>0.25,"Subvalora",IF(CI11-CG11>0.25,"Sobreconfía","Consistente"))) -> Consistente
A12: ENSMA-11 | B12: Deisy Camila Flautero Arias | C12: camilaflautero@ensumaxisoacha.edu.co | D12: Primaria | E12: Ciencias Naturales | F12: 3 a 10 | G12: Computador propio | H12: Estable | I12: Cursos cortos | J12: 5 | K12: 5 | L12: 1 | M12: 5 | N12: 3 | O12: 1 | P12: 4 | Q12: 4 | R12: 5 | S12: 4 | T12: 5 | U12: 4 | V12: 4 | W12: 5 | X12: Diario | Y12: 5 | Z12: 5 | AA12: 5 | AB12: 5 | AC12: 4 | AD12: Semanal | AE12: 5 | AF12: 5 | AG12: 5 | AH12: 5 | AI12: 5 | AJ12: 5 | AK12: 5 | AL12: 5 | AM12: 5 | AN12: 5 | AO12: 4 | AP12: 5 | AQ12: 5 | AR12: 4 | AS12: 5 | AT12: 5 | AU12: 4 | AV12: 4 | AW12: 4 | AX12: 5 | AY12: 4 | AZ12: 5 | BA12: Herramientas específicas | BB12: 9 | BC12: 1 | BD12: 1 | BE12: 1 | BF12: 1 | BG12: 1 | BH12: 1 | BI12: 1 | BJ12: 1 | BK12: 1 | BL12: =IF($B12="","",6-L12) -> 5 | BM12: =IF($B12="","",6-O12) -> 5 | BN12: =IF($B12="","",J12+K12+BL12+M12+N12+BM12+P12+Q12+R12) -> 41 | BO12: =IF($B12="","",SUM(S12:W12)) -> 22 | BP12: =IF($B12="","",SUM(Y12:AC12)) -> 24 | BQ12: =IF($B12="","",SUM(AE12:AK12)) -> 35 | BR12: =IF($B12="","",SUM(AL12:AR12)) -> 33 | BS12: =IF($B12="","",SUM(AS12:AY12)) -> 31 | BT12: =IF($B12="","",BN12/9) -> 4.5555556 | BU12: =IF($B12="","",BO12/5) -> 4.4 | BV12: =IF($B12="","",BP12/5) -> 4.8 | BW12: =IF($B12="","",BQ12/7) -> 5 | BX12: =IF($B12="","",BR12/7) -> 4.7142857 | BY12: =IF($B12="","",BS12/7) -> 4.4285714 | BZ12: =IF($B12="","",AZ12) -> 5 | CA12: =IF($B12="","",IF(BT12<2.5,"Explorador",IF(BT12<3.75,"Integrador","Innovador"))) -> Innovador | CB12: =IF($B12="","",IF(BU12<2.5,"Explorador",IF(BU12<3.75,"Integrador","Innovador"))) -> Innovador | CC12: =IF($B12="","",IF(BV12<2.5,"Explorador",IF(BV12<3.75,"Integrador","Innovador"))) -> Innovador | CD12: =IF($B12="","",IF(BW12<2.5,"Explorador",IF(BW12<3.75,"Integrador","Innovador"))) -> Innovador | CE12: =IF($B12="","",IF(BX12<2.5,"Explorador",IF(BX12<3.75,"Integrador","Innovador"))) -> Innovador | CF12: =IF($B12="","",IF(BY12<2.5,"Explorador",IF(BY12<3.75,"Integrador","Innovador"))) -> Innovador | CG12: =IF($B12="","",BB12/9) -> 1 | CH12: =IF($B12="","",IF(CG12<0.4,"Bajo",IF(CG12<0.7,"Medio","Alto"))) -> Alto | CI12: =IF($B12="","",((AVERAGE(BU12,BW12,BY12))-1)/4) -> 0.90238095 | CJ12: =IF($B12="","",IF(CG12-CI12>0.25,"Subvalora",IF(CI12-CG12>0.25,"Sobreconfía","Consistente"))) -> Consistente
A13: ENSMA-12 | B13: Jaime Orlando Ramírez Vargas | C13: Jaimeramirez@ensumauxisoacha.edu.co | D13: Secundaria | E13: Ciencias Sociales | F13: 11 a 20 | G13: Computador institucional | H13: Limitada | I13: Informal o autodidacta | J13: 5 | K13: 5 | L13: 4 | M13: 5 | N13: 5 | O13: 2 | P13: 5 | Q13: 5 | R13: 5 | S13: 5 | T13: 5 | U13: 5 | V13: 4 | W13: 3 | X13: Mensual | Y13: 5 | Z13: 3 | AA13: 2 | AB13: 2 | AC13: 3 | AD13: Mensual | AE13: 5 | AF13: 5 | AG13: 3 | AH13: 2 | AI13: 3 | AJ13: 3 | AK13: 3 | AL13: 4 | AM13: 4 | AN13: 3 | AO13: 3 | AP13: 3 | AQ13: 3 | AR13: 2 | AS13: 4 | AT13: 5 | AU13: 5 | AV13: 4 | AW13: 4 | AX13: 4 | AY13: 3 | AZ13: 3 | BA13: Fundamentos, Creación de materiales, Evaluación y retroalimentación, Ética e integridad, Uso con estudiantes, Herramientas específicas | BB13: 8 | BC13: 1 | BD13: 1 | BE13: 1 | BF13: 0 | BG13: 1 | BH13: 1 | BI13: 1 | BJ13: 1 | BK13: 1 | BL13: =IF($B13="","",6-L13) -> 2 | BM13: =IF($B13="","",6-O13) -> 4 | BN13: =IF($B13="","",J13+K13+BL13+M13+N13+BM13+P13+Q13+R13) -> 41 | BO13: =IF($B13="","",SUM(S13:W13)) -> 22 | BP13: =IF($B13="","",SUM(Y13:AC13)) -> 15 | BQ13: =IF($B13="","",SUM(AE13:AK13)) -> 24 | BR13: =IF($B13="","",SUM(AL13:AR13)) -> 22 | BS13: =IF($B13="","",SUM(AS13:AY13)) -> 29 | BT13: =IF($B13="","",BN13/9) -> 4.5555556 | BU13: =IF($B13="","",BO13/5) -> 4.4 | BV13: =IF($B13="","",BP13/5) -> 3 | BW13: =IF($B13="","",BQ13/7) -> 3.4285714 | BX13: =IF($B13="","",BR13/7) -> 3.1428571 | BY13: =IF($B13="","",BS13/7) -> 4.1428571 | BZ13: =IF($B13="","",AZ13) -> 3 | CA13: =IF($B13="","",IF(BT13<2.5,"Explorador",IF(BT13<3.75,"Integrador","Innovador"))) -> Innovador | CB13: =IF($B13="","",IF(BU13<2.5,"Explorador",IF(BU13<3.75,"Integrador","Innovador"))) -> Innovador | CC13: =IF($B13="","",IF(BV13<2.5,"Explorador",IF(BV13<3.75,"Integrador","Innovador"))) -> Integrador | CD13: =IF($B13="","",IF(BW13<2.5,"Explorador",IF(BW13<3.75,"Integrador","Innovador"))) -> Integrador | CE13: =IF($B13="","",IF(BX13<2.5,"Explorador",IF(BX13<3.75,"Integrador","Innovador"))) -> Integrador | CF13: =IF($B13="","",IF(BY13<2.5,"Explorador",IF(BY13<3.75,"Integrador","Innovador"))) -> Innovador | CG13: =IF($B13="","",BB13/9) -> 0.88888889 | CH13: =IF($B13="","",IF(CG13<0.4,"Bajo",IF(CG13<0.7,"Medio","Alto"))) -> Alto | CI13: =IF($B13="","",((AVERAGE(BU13,BW13,BY13))-1)/4) -> 0.74761905 | CJ13: =IF($B13="","",IF(CG13-CI13>0.25,"Subvalora",IF(CI13-CG13>0.25,"Sobreconfía","Consistente"))) -> Consistente
... A31: ENSMA-30 | B31: CHIRLEY YESENIA PARADA YANQUEN | C31: cienciassociales@ensumauxisoacha.edu.co | D31: Primaria | E31: Ciencias Sociales | F31: 3 a 10 | G31: Computador propio | H31: Intermitente | I31: Informal o autodidacta | J31: 5 | K31: 5 | L31: 2 | M31: 3 | N31: 5 | O31: 3 | P31: 5 | Q31: 5 | R31: 5 | S31: 5 | T31: 5 | U31: 5 | V31: 5 | W31: 3 | X31: Diario | Y31: 5 | Z31: 5 | AA31: 5 | AB31: 5 | AC31: 3 | AD31: Semanal | AE31: 3 | AF31: 5 | AG31: 5 | AH31: 5 | AI31: 5 | AJ31: 5 | AK31: 5 | AL31: 5 | AM31: 5 | AN31: 5 | AO31: 5 | AP31: 5 | AQ31: 5 | AR31: 5 | AS31: 4 | AT31: 4 | AU31: 4 | AV31: 4 | AW31: 5 | AX31: 4 | AY31: 2 | AZ31: 5 | BA31: Fundamentos, Creación de materiales, Evaluación y retroalimentación, Ética e integridad, Uso con estudiantes, Herramientas específicas | BB31: 8 | BC31: 1 | BD31: 1 | BE31: 1 | BF31: 0 | BG31: 1 | BH31: 1 | BI31: 1 | BJ31: 1 | BK31: 1 | BL31: =IF($B31="","",6-L31) -> 4 | BM31: =IF($B31="","",6-O31) -> 3 | BN31: =IF($B31="","",J31+K31+BL31+M31+N31+BM31+P31+Q31+R31) -> 40 | BO31: =IF($B31="","",SUM(S31:W31)) -> 23 | BP31: =IF($B31="","",SUM(Y31:AC31)) -> 23 | BQ31: =IF($B31="","",SUM(AE31:AK31)) -> 33 | BR31: =IF($B31="","",SUM(AL31:AR31)) -> 35 | BS31: =IF($B31="","",SUM(AS31:AY31)) -> 27 | BT31: =IF($B31="","",BN31/9) -> 4.4444444 | BU31: =IF($B31="","",BO31/5) -> 4.6 | BV31: =IF($B31="","",BP31/5) -> 4.6 | BW31: =IF($B31="","",BQ31/7) -> 4.7142857 | BX31: =IF($B31="","",BR31/7) -> 5 | BY31: =IF($B31="","",BS31/7) -> 3.8571429 | BZ31: =IF($B31="","",AZ31) -> 5 | CA31: =IF($B31="","",IF(BT31<2.5,"Explorador",IF(BT31<3.75,"Integrador","Innovador"))) -> Innovador | CB31: =IF($B31="","",IF(BU31<2.5,"Explorador",IF(BU31<3.75,"Integrador","Innovador"))) -> Innovador | CC31: =IF($B31="","",IF(BV31<2.5,"Explorador",IF(BV31<3.75,"Integrador","Innovador"))) -> Innovador | CD31: =IF($B31="","",IF(BW31<2.5,"Explorador",IF(BW31<3.75,"Integrador","Innovador"))) -> Innovador | CE31: =IF($B31="","",IF(BX31<2.5,"Explorador",IF(BX31<3.75,"Integrador","Innovador"))) -> Innovador | CF31: =IF($B31="","",IF(BY31<2.5,"Explorador",IF(BY31<3.75,"Integrador","Innovador"))) -> Innovador | CG31: =IF($B31="","",BB31/9) -> 0.88888889 | CH31: =IF($B31="","",IF(CG31<0.4,"Bajo",IF(CG31<0.7,"Medio","Alto"))) -> Alto | CI31: =IF($B31="","",((AVERAGE(BU31,BW31,BY31))-1)/4) -> 0.84761905 | CJ31: =IF($B31="","",IF(CG31-CI31>0.25,"Subvalora",IF(CI31-CG31>0.25,"Sobreconfía","Consistente"))) -> Consistente
BL32: =IF($B32="","",6-L32) | BM32: =IF($B32="","",6-O32) | BN32: =IF($B32="","",J32+K32+BL32+M32+N32+BM32+P32+Q32+R32) | BO32: =IF($B32="","",SUM(S32:W32)) | BP32: =IF($B32="","",SUM(Y32:AC32)) | BQ32: =IF($B32="","",SUM(AE32:AK32)) | BR32: =IF($B32="","",SUM(AL32:AR32)) | BS32: =IF($B32="","",SUM(AS32:AY32)) | BT32: =IF($B32="","",BN32/9) | BU32: =IF($B32="","",BO32/5) | BV32: =IF($B32="","",BP32/5) | BW32: =IF($B32="","",BQ32/7) | BX32: =IF($B32="","",BR32/7) | BY32: =IF($B32="","",BS32/7) | BZ32: =IF($B32="","",AZ32) | CA32: =IF($B32="","",IF(BT32<2.5,"Explorador",IF(BT32<3.75,"Integrador","Innovador"))) | CB32: =IF($B32="","",IF(BU32<2.5,"Explorador",IF(BU32<3.75,"Integrador","Innovador"))) | CC32: =IF($B32="","",IF(BV32<2.5,"Explorador",IF(BV32<3.75,"Integrador","Innovador"))) | CD32: =IF($B32="","",IF(BW32<2.5,"Explorador",IF(BW32<3.75,"Integrador","Innovador"))) | CE32: =IF($B32="","",IF(BX32<2.5,"Explorador",IF(BX32<3.75,"Integrador","Innovador"))) | CF32: =IF($B32="","",IF(BY32<2.5,"Explorador",IF(BY32<3.75,"Integrador","Innovador"))) | CG32: =IF($B32="","",BB32/9) | CH32: =IF($B32="","",IF(CG32<0.4,"Bajo",IF(CG32<0.7,"Medio","Alto"))) | CI32: =IF($B32="","",((AVERAGE(BU32,BW32,BY32))-1)/4) | CJ32: =IF($B32="","",IF(CG32-CI32>0.25,"Subvalora",IF(CI32-CG32>0.25,"Sobreconfía","Consistente")))
BL33: =IF($B33="","",6-L33) | BM33: =IF($B33="","",6-O33) | BN33: =IF($B33="","",J33+K33+BL33+M33+N33+BM33+P33+Q33+R33) | BO33: =IF($B33="","",SUM(S33:W33)) | BP33: =IF($B33="","",SUM(Y33:AC33)) | BQ33: =IF($B33="","",SUM(AE33:AK33)) | BR33: =IF($B33="","",SUM(AL33:AR33)) | BS33: =IF($B33="","",SUM(AS33:AY33)) | BT33: =IF($B33="","",BN33/9) | BU33: =IF($B33="","",BO33/5) | BV33: =IF($B33="","",BP33/5) | BW33: =IF($B33="","",BQ33/7) | BX33: =IF($B33="","",BR33/7) | BY33: =IF($B33="","",BS33/7) | BZ33: =IF($B33="","",AZ33) | CA33: =IF($B33="","",IF(BT33<2.5,"Explorador",IF(BT33<3.75,"Integrador","Innovador"))) | CB33: =IF($B33="","",IF(BU33<2.5,"Explorador",IF(BU33<3.75,"Integrador","Innovador"))) | CC33: =IF($B33="","",IF(BV33<2.5,"Explorador",IF(BV33<3.75,"Integrador","Innovador"))) | CD33: =IF($B33="","",IF(BW33<2.5,"Explorador",IF(BW33<3.75,"Integrador","Innovador"))) | CE33: =IF($B33="","",IF(BX33<2.5,"Explorador",IF(BX33<3.75,"Integrador","Innovador"))) | CF33: =IF($B33="","",IF(BY33<2.5,"Explorador",IF(BY33<3.75,"Integrador","Innovador"))) | CG33: =IF($B33="","",BB33/9) | CH33: =IF($B33="","",IF(CG33<0.4,"Bajo",IF(CG33<0.7,"Medio","Alto"))) | CI33: =IF($B33="","",((AVERAGE(BU33,BW33,BY33))-1)/4) | CJ33: =IF($B33="","",IF(CG33-CI33>0.25,"Subvalora",IF(CI33-CG33>0.25,"Sobreconfía","Consistente")))
BL34: =IF($B34="","",6-L34) | BM34: =IF($B34="","",6-O34) | BN34: =IF($B34="","",J34+K34+BL34+M34+N34+BM34+P34+Q34+R34) | BO34: =IF($B34="","",SUM(S34:W34)) | BP34: =IF($B34="","",SUM(Y34:AC34)) | BQ34: =IF($B34="","",SUM(AE34:AK34)) | BR34: =IF($B34="","",SUM(AL34:AR34)) | BS34: =IF($B34="","",SUM(AS34:AY34)) | BT34: =IF($B34="","",BN34/9) | BU34: =IF($B34="","",BO34/5) | BV34: =IF($B34="","",BP34/5) | BW34: =IF($B34="","",BQ34/7) | BX34: =IF($B34="","",BR34/7) | BY34: =IF($B34="","",BS34/7) | BZ34: =IF($B34="","",AZ34) | CA34: =IF($B34="","",IF(BT34<2.5,"Explorador",IF(BT34<3.75,"Integrador","Innovador"))) | CB34: =IF($B34="","",IF(BU34<2.5,"Explorador",IF(BU34<3.75,"Integrador","Innovador"))) | CC34: =IF($B34="","",IF(BV34<2.5,"Explorador",IF(BV34<3.75,"Integrador","Innovador"))) | CD34: =IF($B34="","",IF(BW34<2.5,"Explorador",IF(BW34<3.75,"Integrador","Innovador"))) | CE34: =IF($B34="","",IF(BX34<2.5,"Explorador",IF(BX34<3.75,"Integrador","Innovador"))) | CF34: =IF($B34="","",IF(BY34<2.5,"Explorador",IF(BY34<3.75,"Integrador","Innovador"))) | CG34: =IF($B34="","",BB34/9) | CH34: =IF($B34="","",IF(CG34<0.4,"Bajo",IF(CG34<0.7,"Medio","Alto"))) | CI34: =IF($B34="","",((AVERAGE(BU34,BW34,BY34))-1)/4) | CJ34: =IF($B34="","",IF(CG34-CI34>0.25,"Subvalora",IF(CI34-CG34>0.25,"Sobreconfía","Consistente")))
BL35: =IF($B35="","",6-L35) | BM35: =IF($B35="","",6-O35) | BN35: =IF($B35="","",J35+K35+BL35+M35+N35+BM35+P35+Q35+R35) | BO35: =IF($B35="","",SUM(S35:W35)) | BP35: =IF($B35="","",SUM(Y35:AC35)) | BQ35: =IF($B35="","",SUM(AE35:AK35)) | BR35: =IF($B35="","",SUM(AL35:AR35)) | BS35: =IF($B35="","",SUM(AS35:AY35)) | BT35: =IF($B35="","",BN35/9) | BU35: =IF($B35="","",BO35/5) | BV35: =IF($B35="","",BP35/5) | BW35: =IF($B35="","",BQ35/7) | BX35: =IF($B35="","",BR35/7) | BY35: =IF($B35="","",BS35/7) | BZ35: =IF($B35="","",AZ35) | CA35: =IF($B35="","",IF(BT35<2.5,"Explorador",IF(BT35<3.75,"Integrador","Innovador"))) | CB35: =IF($B35="","",IF(BU35<2.5,"Explorador",IF(BU35<3.75,"Integrador","Innovador"))) | CC35: =IF($B35="","",IF(BV35<2.5,"Explorador",IF(BV35<3.75,"Integrador","Innovador"))) | CD35: =IF($B35="","",IF(BW35<2.5,"Explorador",IF(BW35<3.75,"Integrador","Innovador"))) | CE35: =IF($B35="","",IF(BX35<2.5,"Explorador",IF(BX35<3.75,"Integrador","Innovador"))) | CF35: =IF($B35="","",IF(BY35<2.5,"Explorador",IF(BY35<3.75,"Integrador","Innovador"))) | CG35: =IF($B35="","",BB35/9) | CH35: =IF($B35="","",IF(CG35<0.4,"Bajo",IF(CG35<0.7,"Medio","Alto"))) | CI35: =IF($B35="","",((AVERAGE(BU35,BW35,BY35))-1)/4) | CJ35: =IF($B35="","",IF(CG35-CI35>0.25,"Subvalora",IF(CI35-CG35>0.25,"Sobreconfía","Consistente")))
BL36: =IF($B36="","",6-L36) | BM36: =IF($B36="","",6-O36) | BN36: =IF($B36="","",J36+K36+BL36+M36+N36+BM36+P36+Q36+R36) | BO36: =IF($B36="","",SUM(S36:W36)) | BP36: =IF($B36="","",SUM(Y36:AC36)) | BQ36: =IF($B36="","",SUM(AE36:AK36)) | BR36: =IF($B36="","",SUM(AL36:AR36)) | BS36: =IF($B36="","",SUM(AS36:AY36)) | BT36: =IF($B36="","",BN36/9) | BU36: =IF($B36="","",BO36/5) | BV36: =IF($B36="","",BP36/5) | BW36: =IF($B36="","",BQ36/7) | BX36: =IF($B36="","",BR36/7) | BY36: =IF($B36="","",BS36/7) | BZ36: =IF($B36="","",AZ36) | CA36: =IF($B36="","",IF(BT36<2.5,"Explorador",IF(BT36<3.75,"Integrador","Innovador"))) | CB36: =IF($B36="","",IF(BU36<2.5,"Explorador",IF(BU36<3.75,"Integrador","Innovador"))) | CC36: =IF($B36="","",IF(BV36<2.5,"Explorador",IF(BV36<3.75,"Integrador","Innovador"))) | CD36: =IF($B36="","",IF(BW36<2.5,"Explorador",IF(BW36<3.75,"Integrador","Innovador"))) | CE36: =IF($B36="","",IF(BX36<2.5,"Explorador",IF(BX36<3.75,"Integrador","Innovador"))) | CF36: =IF($B36="","",IF(BY36<2.5,"Explorador",IF(BY36<3.75,"Integrador","Innovador"))) | CG36: =IF($B36="","",BB36/9) | CH36: =IF($B36="","",IF(CG36<0.4,"Bajo",IF(CG36<0.7,"Medio","Alto"))) | CI36: =IF($B36="","",((AVERAGE(BU36,BW36,BY36))-1)/4) | CJ36: =IF($B36="","",IF(CG36-CI36>0.25,"Subvalora",IF(CI36-CG36>0.25,"Sobreconfía","Consistente")))
BL37: =IF($B37="","",6-L37) | BM37: =IF($B37="","",6-O37) | BN37: =IF($B37="","",J37+K37+BL37+M37+N37+BM37+P37+Q37+R37) | BO37: =IF($B37="","",SUM(S37:W37)) | BP37: =IF($B37="","",SUM(Y37:AC37)) | BQ37: =IF($B37="","",SUM(AE37:AK37)) | BR37: =IF($B37="","",SUM(AL37:AR37)) | BS37: =IF($B37="","",SUM(AS37:AY37)) | BT37: =IF($B37="","",BN37/9) | BU37: =IF($B37="","",BO37/5) | BV37: =IF($B37="","",BP37/5) | BW37: =IF($B37="","",BQ37/7) | BX37: =IF($B37="","",BR37/7) | BY37: =IF($B37="","",BS37/7) | BZ37: =IF($B37="","",AZ37) | CA37: =IF($B37="","",IF(BT37<2.5,"Explorador",IF(BT37<3.75,"Integrador","Innovador"))) | CB37: =IF($B37="","",IF(BU37<2.5,"Explorador",IF(BU37<3.75,"Integrador","Innovador"))) | CC37: =IF($B37="","",IF(BV37<2.5,"Explorador",IF(BV37<3.75,"Integrador","Innovador"))) | CD37: =IF($B37="","",IF(BW37<2.5,"Explorador",IF(BW37<3.75,"Integrador","Innovador"))) | CE37: =IF($B37="","",IF(BX37<2.5,"Explorador",IF(BX37<3.75,"Integrador","Innovador"))) | CF37: =IF($B37="","",IF(BY37<2.5,"Explorador",IF(BY37<3.75,"Integrador","Innovador"))) | CG37: =IF($B37="","",BB37/9) | CH37: =IF($B37="","",IF(CG37<0.4,"Bajo",IF(CG37<0.7,"Medio","Alto"))) | CI37: =IF($B37="","",((AVERAGE(BU37,BW37,BY37))-1)/4) | CJ37: =IF($B37="","",IF(CG37-CI37>0.25,"Subvalora",IF(CI37-CG37>0.25,"Sobreconfía","Consistente")))
BL38: =IF($B38="","",6-L38) | BM38: =IF($B38="","",6-O38) | BN38: =IF($B38="","",J38+K38+BL38+M38+N38+BM38+P38+Q38+R38) | BO38: =IF($B38="","",SUM(S38:W38)) | BP38: =IF($B38="","",SUM(Y38:AC38)) | BQ38: =IF($B38="","",SUM(AE38:AK38)) | BR38: =IF($B38="","",SUM(AL38:AR38)) | BS38: =IF($B38="","",SUM(AS38:AY38)) | BT38: =IF($B38="","",BN38/9) | BU38: =IF($B38="","",BO38/5) | BV38: =IF($B38="","",BP38/5) | BW38: =IF($B38="","",BQ38/7) | BX38: =IF($B38="","",BR38/7) | BY38: =IF($B38="","",BS38/7) | BZ38: =IF($B38="","",AZ38) | CA38: =IF($B38="","",IF(BT38<2.5,"Explorador",IF(BT38<3.75,"Integrador","Innovador"))) | CB38: =IF($B38="","",IF(BU38<2.5,"Explorador",IF(BU38<3.75,"Integrador","Innovador"))) | CC38: =IF($B38="","",IF(BV38<2.5,"Explorador",IF(BV38<3.75,"Integrador","Innovador"))) | CD38: =IF($B38="","",IF(BW38<2.5,"Explorador",IF(BW38<3.75,"Integrador","Innovador"))) | CE38: =IF($B38="","",IF(BX38<2.5,"Explorador",IF(BX38<3.75,"Integrador","Innovador"))) | CF38: =IF($B38="","",IF(BY38<2.5,"Explorador",IF(BY38<3.75,"Integrador","Innovador"))) | CG38: =IF($B38="","",BB38/9) | CH38: =IF($B38="","",IF(CG38<0.4,"Bajo",IF(CG38<0.7,"Medio","Alto"))) | CI38: =IF($B38="","",((AVERAGE(BU38,BW38,BY38))-1)/4) | CJ38: =IF($B38="","",IF(CG38-CI38>0.25,"Subvalora",IF(CI38-CG38>0.25,"Sobreconfía","Consistente")))
BL39: =IF($B39="","",6-L39) | BM39: =IF($B39="","",6-O39) | BN39: =IF($B39="","",J39+K39+BL39+M39+N39+BM39+P39+Q39+R39) | BO39: =IF($B39="","",SUM(S39:W39)) | BP39: =IF($B39="","",SUM(Y39:AC39)) | BQ39: =IF($B39="","",SUM(AE39:AK39)) | BR39: =IF($B39="","",SUM(AL39:AR39)) | BS39: =IF($B39="","",SUM(AS39:AY39)) | BT39: =IF($B39="","",BN39/9) | BU39: =IF($B39="","",BO39/5) | BV39: =IF($B39="","",BP39/5) | BW39: =IF($B39="","",BQ39/7) | BX39: =IF($B39="","",BR39/7) | BY39: =IF($B39="","",BS39/7) | BZ39: =IF($B39="","",AZ39) | CA39: =IF($B39="","",IF(BT39<2.5,"Explorador",IF(BT39<3.75,"Integrador","Innovador"))) | CB39: =IF($B39="","",IF(BU39<2.5,"Explorador",IF(BU39<3.75,"Integrador","Innovador"))) | CC39: =IF($B39="","",IF(BV39<2.5,"Explorador",IF(BV39<3.75,"Integrador","Innovador"))) | CD39: =IF($B39="","",IF(BW39<2.5,"Explorador",IF(BW39<3.75,"Integrador","Innovador"))) | CE39: =IF($B39="","",IF(BX39<2.5,"Explorador",IF(BX39<3.75,"Integrador","Innovador"))) | CF39: =IF($B39="","",IF(BY39<2.5,"Explorador",IF(BY39<3.75,"Integrador","Innovador"))) | CG39: =IF($B39="","",BB39/9) | CH39: =IF($B39="","",IF(CG39<0.4,"Bajo",IF(CG39<0.7,"Medio","Alto"))) | CI39: =IF($B39="","",((AVERAGE(BU39,BW39,BY39))-1)/4) | CJ39: =IF($B39="","",IF(CG39-CI39>0.25,"Subvalora",IF(CI39-CG39>0.25,"Sobreconfía","Consistente")))
BL40: =IF($B40="","",6-L40) | BM40: =IF($B40="","",6-O40) | BN40: =IF($B40="","",J40+K40+BL40+M40+N40+BM40+P40+Q40+R40) | BO40: =IF($B40="","",SUM(S40:W40)) | BP40: =IF($B40="","",SUM(Y40:AC40)) | BQ40: =IF($B40="","",SUM(AE40:AK40)) | BR40: =IF($B40="","",SUM(AL40:AR40)) | BS40: =IF($B40="","",SUM(AS40:AY40)) | BT40: =IF($B40="","",BN40/9) | BU40: =IF($B40="","",BO40/5) | BV40: =IF($B40="","",BP40/5) | BW40: =IF($B40="","",BQ40/7) | BX40: =IF($B40="","",BR40/7) | BY40: =IF($B40="","",BS40/7) | BZ40: =IF($B40="","",AZ40) | CA40: =IF($B40="","",IF(BT40<2.5,"Explorador",IF(BT40<3.75,"Integrador","Innovador"))) | CB40: =IF($B40="","",IF(BU40<2.5,"Explorador",IF(BU40<3.75,"Integrador","Innovador"))) | CC40: =IF($B40="","",IF(BV40<2.5,"Explorador",IF(BV40<3.75,"Integrador","Innovador"))) | CD40: =IF($B40="","",IF(BW40<2.5,"Explorador",IF(BW40<3.75,"Integrador","Innovador"))) | CE40: =IF($B40="","",IF(BX40<2.5,"Explorador",IF(BX40<3.75,"Integrador","Innovador"))) | CF40: =IF($B40="","",IF(BY40<2.5,"Explorador",IF(BY40<3.75,"Integrador","Innovador"))) | CG40: =IF($B40="","",BB40/9) | CH40: =IF($B40="","",IF(CG40<0.4,"Bajo",IF(CG40<0.7,"Medio","Alto"))) | CI40: =IF($B40="","",((AVERAGE(BU40,BW40,BY40))-1)/4) | CJ40: =IF($B40="","",IF(CG40-CI40>0.25,"Subvalora",IF(CI40-CG40>0.25,"Sobreconfía","Consistente")))
BL41: =IF($B41="","",6-L41) | BM41: =IF($B41="","",6-O41) | BN41: =IF($B41="","",J41+K41+BL41+M41+N41+BM41+P41+Q41+R41) | BO41: =IF($B41="","",SUM(S41:W41)) | BP41: =IF($B41="","",SUM(Y41:AC41)) | BQ41: =IF($B41="","",SUM(AE41:AK41)) | BR41: =IF($B41="","",SUM(AL41:AR41)) | BS41: =IF($B41="","",SUM(AS41:AY41)) | BT41: =IF($B41="","",BN41/9) | BU41: =IF($B41="","",BO41/5) | BV41: =IF($B41="","",BP41/5) | BW41: =IF($B41="","",BQ41/7) | BX41: =IF($B41="","",BR41/7) | BY41: =IF($B41="","",BS41/7) | BZ41: =IF($B41="","",AZ41) | CA41: =IF($B41="","",IF(BT41<2.5,"Explorador",IF(BT41<3.75,"Integrador","Innovador"))) | CB41: =IF($B41="","",IF(BU41<2.5,"Explorador",IF(BU41<3.75,"Integrador","Innovador"))) | CC41: =IF($B41="","",IF(BV41<2.5,"Explorador",IF(BV41<3.75,"Integrador","Innovador"))) | CD41: =IF($B41="","",IF(BW41<2.5,"Explorador",IF(BW41<3.75,"Integrador","Innovador"))) | CE41: =IF($B41="","",IF(BX41<2.5,"Explorador",IF(BX41<3.75,"Integrador","Innovador"))) | CF41: =IF($B41="","",IF(BY41<2.5,"Explorador",IF(BY41<3.75,"Integrador","Innovador"))) | CG41: =IF($B41="","",BB41/9) | CH41: =IF($B41="","",IF(CG41<0.4,"Bajo",IF(CG41<0.7,"Medio","Alto"))) | CI41: =IF($B41="","",((AVERAGE(BU41,BW41,BY41))-1)/4) | CJ41: =IF($B41="","",IF(CG41-CI41>0.25,"Subvalora",IF(CI41-CG41>0.25,"Sobreconfía","Consistente")))
BL42: =IF($B42="","",6-L42) | BM42: =IF($B42="","",6-O42) | BN42: =IF($B42="","",J42+K42+BL42+M42+N42+BM42+P42+Q42+R42) | BO42: =IF($B42="","",SUM(S42:W42)) | BP42: =IF($B42="","",SUM(Y42:AC42)) | BQ42: =IF($B42="","",SUM(AE42:AK42)) | BR42: =IF($B42="","",SUM(AL42:AR42)) | BS42: =IF($B42="","",SUM(AS42:AY42)) | BT42: =IF($B42="","",BN42/9) | BU42: =IF($B42="","",BO42/5) | BV42: =IF($B42="","",BP42/5) | BW42: =IF($B42="","",BQ42/7) | BX42: =IF($B42="","",BR42/7) | BY42: =IF($B42="","",BS42/7) | BZ42: =IF($B42="","",AZ42) | CA42: =IF($B42="","",IF(BT42<2.5,"Explorador",IF(BT42<3.75,"Integrador","Innovador"))) | CB42: =IF($B42="","",IF(BU42<2.5,"Explorador",IF(BU42<3.75,"Integrador","Innovador"))) | CC42: =IF($B42="","",IF(BV42<2.5,"Explorador",IF(BV42<3.75,"Integrador","Innovador"))) | CD42: =IF($B42="","",IF(BW42<2.5,"Explorador",IF(BW42<3.75,"Integrador","Innovador"))) | CE42: =IF($B42="","",IF(BX42<2.5,"Explorador",IF(BX42<3.75,"Integrador","Innovador"))) | CF42: =IF($B42="","",IF(BY42<2.5,"Explorador",IF(BY42<3.75,"Integrador","Innovador"))) | CG42: =IF($B42="","",BB42/9) | CH42: =IF($B42="","",IF(CG42<0.4,"Bajo",IF(CG42<0.7,"Medio","Alto"))) | CI42: =IF($B42="","",((AVERAGE(BU42,BW42,BY42))-1)/4) | CJ42: =IF($B42="","",IF(CG42-CI42>0.25,"Subvalora",IF(CI42-CG42>0.25,"Sobreconfía","Consistente")))
BL43: =IF($B43="","",6-L43) | BM43: =IF($B43="","",6-O43) | BN43: =IF($B43="","",J43+K43+BL43+M43+N43+BM43+P43+Q43+R43) | BO43: =IF($B43="","",SUM(S43:W43)) | BP43: =IF($B43="","",SUM(Y43:AC43)) | BQ43: =IF($B43="","",SUM(AE43:AK43)) | BR43: =IF($B43="","",SUM(AL43:AR43)) | BS43: =IF($B43="","",SUM(AS43:AY43)) | BT43: =IF($B43="","",BN43/9) | BU43: =IF($B43="","",BO43/5) | BV43: =IF($B43="","",BP43/5) | BW43: =IF($B43="","",BQ43/7) | BX43: =IF($B43="","",BR43/7) | BY43: =IF($B43="","",BS43/7) | BZ43: =IF($B43="","",AZ43) | CA43: =IF($B43="","",IF(BT43<2.5,"Explorador",IF(BT43<3.75,"Integrador","Innovador"))) | CB43: =IF($B43="","",IF(BU43<2.5,"Explorador",IF(BU43<3.75,"Integrador","Innovador"))) | CC43: =IF($B43="","",IF(BV43<2.5,"Explorador",IF(BV43<3.75,"Integrador","Innovador"))) | CD43: =IF($B43="","",IF(BW43<2.5,"Explorador",IF(BW43<3.75,"Integrador","Innovador"))) | CE43: =IF($B43="","",IF(BX43<2.5,"Explorador",IF(BX43<3.75,"Integrador","Innovador"))) | CF43: =IF($B43="","",IF(BY43<2.5,"Explorador",IF(BY43<3.75,"Integrador","Innovador"))) | CG43: =IF($B43="","",BB43/9) | CH43: =IF($B43="","",IF(CG43<0.4,"Bajo",IF(CG43<0.7,"Medio","Alto"))) | CI43: =IF($B43="","",((AVERAGE(BU43,BW43,BY43))-1)/4) | CJ43: =IF($B43="","",IF(CG43-CI43>0.25,"Subvalora",IF(CI43-CG43>0.25,"Sobreconfía","Consistente")))
... BL101: =IF($B101="","",6-L101) | BM101: =IF($B101="","",6-O101) | BN101: =IF($B101="","",J101+K101+BL101+M101+N101+BM101+P101+Q101+R101) | BO101: =IF($B101="","",SUM(S101:W101)) | BP101: =IF($B101="","",SUM(Y101:AC101)) | BQ101: =IF($B101="","",SUM(AE101:AK101)) | BR101: =IF($B101="","",SUM(AL101:AR101)) | BS101: =IF($B101="","",SUM(AS101:AY101)) | BT101: =IF($B101="","",BN101/9) | BU101: =IF($B101="","",BO101/5) | BV101: =IF($B101="","",BP101/5) | BW101: =IF($B101="","",BQ101/7) | BX101: =IF($B101="","",BR101/7) | BY101: =IF($B101="","",BS101/7) | BZ101: =IF($B101="","",AZ101) | CA101: =IF($B101="","",IF(BT101<2.5,"Explorador",IF(BT101<3.75,"Integrador","Innovador"))) | CB101: =IF($B101="","",IF(BU101<2.5,"Explorador",IF(BU101<3.75,"Integrador","Innovador"))) | CC101: =IF($B101="","",IF(BV101<2.5,"Explorador",IF(BV101<3.75,"Integrador","Innovador"))) | CD101: =IF($B101="","",IF(BW101<2.5,"Explorador",IF(BW101<3.75,"Integrador","Innovador"))) | CE101: =IF($B101="","",IF(BX101<2.5,"Explorador",IF(BX101<3.75,"Integrador","Innovador"))) | CF101: =IF($B101="","",IF(BY101<2.5,"Explorador",IF(BY101<3.75,"Integrador","Innovador"))) | CG101: =IF($B101="","",BB101/9) | CH101: =IF($B101="","",IF(CG101<0.4,"Bajo",IF(CG101<0.7,"Medio","Alto"))) | CI101: =IF($B101="","",((AVERAGE(BU101,BW101,BY101))-1)/4) | CJ101: =IF($B101="","",IF(CG101-CI101>0.25,"Subvalora",IF(CI101-CG101>0.25,"Sobreconfía","Consistente")))

Sheet Tablero
B2: Tablero de la línea base — Competencias digitales docentes ENSMA
B3: Los cálculos se actualizan automáticamente al pegar las respuestas en la hoja «Datos».
B5: Dimensión | C5: Explorador | D5: Integrador | E5: Innovador | F5: Media institucional | G5: Nivel predominante
B6: Actitud | C6: =COUNTIF(Datos!$CA$2:$CA$101,"Explorador") -> 0 | D6: =COUNTIF(Datos!$CA$2:$CA$101,"Integrador") -> 1 | E6: =COUNTIF(Datos!$CA$2:$CA$101,"Innovador") -> 29 | F6: =IFERROR(AVERAGE(Datos!$BT$2:$BT$101),"") -> 4.4925926 | G6: =IFERROR(INDEX({"Explorador";"Integrador";"Innovador"},MATCH(MAX(C6:E6),C6:E6,0)),"") -> Innovador
B7: Información | C7: =COUNTIF(Datos!$CB$2:$CB$101,"Explorador") -> 0 | D7: =COUNTIF(Datos!$CB$2:$CB$101,"Integrador") -> 8 | E7: =COUNTIF(Datos!$CB$2:$CB$101,"Innovador") -> 22 | F7: =IFERROR(AVERAGE(Datos!$BU$2:$BU$101),"") -> 4.1466667 | G7: =IFERROR(INDEX({"Explorador";"Integrador";"Innovador"},MATCH(MAX(C7:E7),C7:E7,0)),"") -> Innovador
B8: Comunicación | C8: =COUNTIF(Datos!$CC$2:$CC$101,"Explorador") -> 0 | D8: =COUNTIF(Datos!$CC$2:$CC$101,"Integrador") -> 5 | E8: =COUNTIF(Datos!$CC$2:$CC$101,"Innovador") -> 25 | F8: =IFERROR(AVERAGE(Datos!$BV$2:$BV$101),"") -> 4.2333333 | G8: =IFERROR(INDEX({"Explorador";"Integrador";"Innovador"},MATCH(MAX(C8:E8),C8:E8,0)),"") -> Innovador
B9: Seguridad | C9: =COUNTIF(Datos!$CD$2:$CD$101,"Explorador") -> 1 | D9: =COUNTIF(Datos!$CD$2:$CD$101,"Integrador") -> 10 | E9: =COUNTIF(Datos!$CD$2:$CD$101,"Innovador") -> 19 | F9: =IFERROR(AVERAGE(Datos!$BW$2:$BW$101),"") -> 4.0714286 | G9: =IFERROR(INDEX({"Explorador";"Integrador";"Innovador"},MATCH(MAX(C9:E9),C9:E9,0)),"") -> Innovador
B10: Integración pedagógica | C10: =COUNTIF(Datos!$CE$2:$CE$101,"Explorador") -> 2 | D10: =COUNTIF(Datos!$CE$2:$CE$101,"Integrador") -> 10 | E10: =COUNTIF(Datos!$CE$2:$CE$101,"Innovador") -> 18 | F10: =IFERROR(AVERAGE(Datos!$BX$2:$BX$101),"") -> 3.8285714 | G10: =IFERROR(INDEX({"Explorador";"Integrador";"Innovador"},MATCH(MAX(C10:E10),C10:E10,0)),"") -> Innovador
B11: Inteligencia artificial | C11: =COUNTIF(Datos!$CF$2:$CF$101,"Explorador") -> 0 | D11: =COUNTIF(Datos!$CF$2:$CF$101,"Integrador") -> 10 | E11: =COUNTIF(Datos!$CF$2:$CF$101,"Innovador") -> 20 | F11: =IFERROR(AVERAGE(Datos!$BY$2:$BY$101),"") -> 3.9380952 | G11: =IFERROR(INDEX({"Explorador";"Integrador";"Innovador"},MATCH(MAX(C11:E11),C11:E11,0)),"") -> Innovador
B14: Desempeño demostrado (bloque objetivo)
B15: Media de aciertos (%) | D15: =IFERROR(AVERAGE(Datos!$CG$2:$CG$101),"") -> 0.94814815
B16: Bajo (<40%) | D16: =COUNTIF(Datos!$CH$2:$CH$101,"Bajo") -> 0
B17: Medio (40–69%) | D17: =COUNTIF(Datos!$CH$2:$CH$101,"Medio") -> 0
B18: Alto (≥70%) | D18: =COUNTIF(Datos!$CH$2:$CH$101,"Alto") -> 30
B20: Dificultad por ítem objetivo — % de aciertos (insumo para el Diplomado)
B21: OBJ1 · Evaluar fuentes | D21: =IFERROR(AVERAGE(Datos!$BC$2:$BC$101),"") -> 0.93333333
B22: OBJ2 · Búsqueda exacta | D22: =IFERROR(AVERAGE(Datos!$BD$2:$BD$101),"") -> 0.93333333
B23: OBJ3 · Phishing | D23: =IFERROR(AVERAGE(Datos!$BE$2:$BE$101),"") -> 0.96666667
B24: OBJ4 · Contraseñas | D24: =IFERROR(AVERAGE(Datos!$BF$2:$BF$101),"") -> 0.83333333
B25: OBJ5 · Datos de menores | D25: =IFERROR(AVERAGE(Datos!$BG$2:$BG$101),"") -> 1
B26: OBJ6 · Alucinación IA | D26: =IFERROR(AVERAGE(Datos!$BH$2:$BH$101),"") -> 0.9
B27: OBJ7 · Privacidad en IA | D27: =IFERROR(AVERAGE(Datos!$BI$2:$BI$101),"") -> 1
B28: OBJ8 · Prompting | D28: =IFERROR(AVERAGE(Datos!$BJ$2:$BJ$101),"") -> 0.96666667
B29: OBJ9 · Integridad académica | D29: =IFERROR(AVERAGE(Datos!$BK$2:$BK$101),"") -> 1
B31: Percepción frente a desempeño
B32: Consistente | D32: =COUNTIF(Datos!$CJ$2:$CJ$101,"Consistente") -> 21
B33: Sobreconfía | D33: =COUNTIF(Datos!$CJ$2:$CJ$101,"Sobreconfía") -> 0
B34: Subvalora | D34: =COUNTIF(Datos!$CJ$2:$CJ$101,"Subvalora") -> 9
B36: Disposición media a formarse en IA (1–5) | D36: =IFERROR(AVERAGE(Datos!$BZ$2:$BZ$101),"") -> 4.6666667
B39: Media por dimensión según nivel de enseñanza (leer con cautela por N pequeño)
B40: Nivel | C40: Actitud | D40: Información | E40: Comunicación | F40: Seguridad | G40: Integración pedagógica | H40: Inteligencia artificial
B41: Preescolar | C41: =IFERROR(AVERAGEIFS(Datos!$BT$2:$BT$101,Datos!$D$2:$D$101,"Preescolar"),"") -> 4.6 | D41: =IFERROR(AVERAGEIFS(Datos!$BU$2:$BU$101,Datos!$D$2:$D$101,"Preescolar"),"") -> 4.2 | E41: =IFERROR(AVERAGEIFS(Datos!$BV$2:$BV$101,Datos!$D$2:$D$101,"Preescolar"),"") -> 4.68 | F41: =IFERROR(AVERAGEIFS(Datos!$BW$2:$BW$101,Datos!$D$2:$D$101,"Preescolar"),"") -> 4.5428571 | G41: =IFERROR(AVERAGEIFS(Datos!$BX$2:$BX$101,Datos!$D$2:$D$101,"Preescolar"),"") -> 4.0857143 | H41: =IFERROR(AVERAGEIFS(Datos!$BY$2:$BY$101,Datos!$D$2:$D$101,"Preescolar"),"") -> 4.2285714
B42: Primaria | C42: =IFERROR(AVERAGEIFS(Datos!$BT$2:$BT$101,Datos!$D$2:$D$101,"Primaria"),"") -> 4.3856209 | D42: =IFERROR(AVERAGEIFS(Datos!$BU$2:$BU$101,Datos!$D$2:$D$101,"Primaria"),"") -> 4.0117647 | E42: =IFERROR(AVERAGEIFS(Datos!$BV$2:$BV$101,Datos!$D$2:$D$101,"Primaria"),"") -> 4.2588235 | F42: =IFERROR(AVERAGEIFS(Datos!$BW$2:$BW$101,Datos!$D$2:$D$101,"Primaria"),"") -> 4 | G42: =IFERROR(AVERAGEIFS(Datos!$BX$2:$BX$101,Datos!$D$2:$D$101,"Primaria"),"") -> 3.7983193 | H42: =IFERROR(AVERAGEIFS(Datos!$BY$2:$BY$101,Datos!$D$2:$D$101,"Primaria"),"") -> 3.7226891
B43: Secundaria | C43: =IFERROR(AVERAGEIFS(Datos!$BT$2:$BT$101,Datos!$D$2:$D$101,"Secundaria"),"") -> 4.7142857 | D43: =IFERROR(AVERAGEIFS(Datos!$BU$2:$BU$101,Datos!$D$2:$D$101,"Secundaria"),"") -> 4.5714286 | E43: =IFERROR(AVERAGEIFS(Datos!$BV$2:$BV$101,Datos!$D$2:$D$101,"Secundaria"),"") -> 4.0285714 | F43: =IFERROR(AVERAGEIFS(Datos!$BW$2:$BW$101,Datos!$D$2:$D$101,"Secundaria"),"") -> 3.9183673 | G43: =IFERROR(AVERAGEIFS(Datos!$BX$2:$BX$101,Datos!$D$2:$D$101,"Secundaria"),"") -> 3.7959184 | H43: =IFERROR(AVERAGEIFS(Datos!$BY$2:$BY$101,Datos!$D$2:$D$101,"Secundaria"),"") -> 4.3673469
B44: Media | C44: =IFERROR(AVERAGEIFS(Datos!$BT$2:$BT$101,Datos!$D$2:$D$101,"Media"),"") -> 4.2222222 | D44: =IFERROR(AVERAGEIFS(Datos!$BU$2:$BU$101,Datos!$D$2:$D$101,"Media"),"") -> 3.2 | E44: =IFERROR(AVERAGEIFS(Datos!$BV$2:$BV$101,Datos!$D$2:$D$101,"Media"),"") -> 3 | F44: =IFERROR(AVERAGEIFS(Datos!$BW$2:$BW$101,Datos!$D$2:$D$101,"Media"),"") -> 4 | G44: =IFERROR(AVERAGEIFS(Datos!$BX$2:$BX$101,Datos!$D$2:$D$101,"Media"),"") -> 3.2857143 | H44: =IFERROR(AVERAGEIFS(Datos!$BY$2:$BY$101,Datos!$D$2:$D$101,"Media"),"") -> 3.1428571

Sheet Perfil
B2: Perfil individual del docente
B4: Seleccione un docente: | D4: Docente A
B6: Dimensión | C6: Media (1–5) | D6: Nivel MEN | E6: Media institucional
B7: Media Actitud | C7: =IFERROR(INDEX(Datos!$BT$2:$BT$101,MATCH($D$4,Datos!$B$2:$B$101,0)),"") | D7: =IFERROR(INDEX(Datos!$CA$2:$CA$101,MATCH($D$4,Datos!$B$2:$B$101,0)),"") | E7: =IFERROR(AVERAGE(Datos!$BT$2:$BT$101),"") -> 4.4925926
B8: Media Información | C8: =IFERROR(INDEX(Datos!$BU$2:$BU$101,MATCH($D$4,Datos!$B$2:$B$101,0)),"") | D8: =IFERROR(INDEX(Datos!$CB$2:$CB$101,MATCH($D$4,Datos!$B$2:$B$101,0)),"") | E8: =IFERROR(AVERAGE(Datos!$BU$2:$BU$101),"") -> 4.1466667
B9: Media Comunicación | C9: =IFERROR(INDEX(Datos!$BV$2:$BV$101,MATCH($D$4,Datos!$B$2:$B$101,0)),"") | D9: =IFERROR(INDEX(Datos!$CC$2:$CC$101,MATCH($D$4,Datos!$B$2:$B$101,0)),"") | E9: =IFERROR(AVERAGE(Datos!$BV$2:$BV$101),"") -> 4.2333333
B10: Media Seguridad | C10: =IFERROR(INDEX(Datos!$BW$2:$BW$101,MATCH($D$4,Datos!$B$2:$B$101,0)),"") | D10: =IFERROR(INDEX(Datos!$CD$2:$CD$101,MATCH($D$4,Datos!$B$2:$B$101,0)),"") | E10: =IFERROR(AVERAGE(Datos!$BW$2:$BW$101),"") -> 4.0714286
B11: Media Integración pedagógica | C11: =IFERROR(INDEX(Datos!$BX$2:$BX$101,MATCH($D$4,Datos!$B$2:$B$101,0)),"") | D11: =IFERROR(INDEX(Datos!$CE$2:$CE$101,MATCH($D$4,Datos!$B$2:$B$101,0)),"") | E11: =IFERROR(AVERAGE(Datos!$BX$2:$BX$101),"") -> 3.8285714
B12: Media Inteligencia artificial | C12: =IFERROR(INDEX(Datos!$BY$2:$BY$101,MATCH($D$4,Datos!$B$2:$B$101,0)),"") | D12: =IFERROR(INDEX(Datos!$CF$2:$CF$101,MATCH($D$4,Datos!$B$2:$B$101,0)),"") | E12: =IFERROR(AVERAGE(Datos!$BY$2:$BY$101),"") -> 3.9380952
B14: Desempeño objetivo (%) | C14: =IFERROR(INDEX(Datos!$CG$2:$CG$101,MATCH($D$4,Datos!$B$2:$B$101,0)),"")
B15: Disposición a formarse en IA (1–5) | C15: =IFERROR(INDEX(Datos!$BZ$2:$BZ$101,MATCH($D$4,Datos!$B$2:$B$101,0)),"")
B16: Señal percepción vs. desempeño | C16: =IFERROR(INDEX(Datos!$CJ$2:$CJ$101,MATCH($D$4,Datos!$B$2:$B$101,0)),"")

Sheet Fiabilidad
B2: Fiabilidad — Alfa de Cronbach por dimensión
B3: α = (k/(k-1)) · (1 − Σ varianza de ítems / varianza del total). Meta ≥ 0,70. Con pocas respuestas el índice es inestable.
B5: Dimensión | C5: k (ítems) | D5: Σ var ítems | E5: Var total | F5: Alfa | G5: Lectura
B6: Actitud | C6: 9 | D6: =IFERROR(VAR(Datos!$J$2:$J$101)+VAR(Datos!$K$2:$K$101)+VAR(Datos!$BL$2:$BL$101)+VAR(Datos!$M$2:$M$101)+VAR(Datos!$N$2:$N$101)+VAR(Datos!$BM$2:$BM$101)+VAR(Datos!$P$2:$P$101)+VAR(Datos!$Q$2:$Q$101)+VAR(Datos!$R$2:$R$101),"") -> 5.5781609 | E6: =IFERROR(VAR(Datos!$BN$2:$BN$101),"") -> 9.2885057 | F6: =IFERROR((9/8)*(1-D6/E6),"") -> 0.44938745 | G6: =IF(F6="","",IF(F6>=0.7,"Aceptable","Revisar / ampliar N")) -> Revisar / ampliar N
B7: Información | C7: 5 | D7: =IFERROR(VAR(Datos!$S$2:$S$101)+VAR(Datos!$T$2:$T$101)+VAR(Datos!$U$2:$U$101)+VAR(Datos!$V$2:$V$101)+VAR(Datos!$W$2:$W$101),"") -> 4.3241379 | E7: =IFERROR(VAR(Datos!$BO$2:$BO$101),"") -> 9.5126437 | F7: =IFERROR((5/4)*(1-D7/E7),"") -> 0.68179072 | G7: =IF(F7="","",IF(F7>=0.7,"Aceptable","Revisar / ampliar N")) -> Revisar / ampliar N
B8: Comunicación | C8: 5 | D8: =IFERROR(VAR(Datos!$Y$2:$Y$101)+VAR(Datos!$Z$2:$Z$101)+VAR(Datos!$AA$2:$AA$101)+VAR(Datos!$AB$2:$AB$101)+VAR(Datos!$AC$2:$AC$101),"") -> 4.8034483 | E8: =IFERROR(VAR(Datos!$BP$2:$BP$101),"") -> 10.971264 | F8: =IFERROR((5/4)*(1-D8/E8),"") -> 0.70272394 | G8: =IF(F8="","",IF(F8>=0.7,"Aceptable","Revisar / ampliar N")) -> Aceptable
