Workbook

Sheet Portada
B2: EICIT · Escuela Iberoamericana de Ciencias Técnicas
B4: Revisión de la Autoevaluación Institucional (Guía 34)
B5: Insumo para el transverso de calidad del PEI 2026–2027 · ENSMA
B6: ESTRUCTURA DE TRABAJO — lista para cargar y concluir
B8: Tarea del cronograma | C8: 1.2.4 — Revisión de la autoevaluación
B9: Marco | C9: Guía 34 (MEN) · Circular 0064 de 2026 (SEM) · PEI 2026–2027
B10: Fuente autoevaluación | C10: Autoevaluación Procesos Institucionales Guía 34 – 2026 I (I semestre 2026)
B11: Alcance | C11: 6 procesos SGC · 96 componentes · escala 1–4
B12: Estado | C12: Cargado: I-2026 + evidencia externa (Saber 11, matrícula). PENDIENTE: ciclo anterior (2025).
B13: Elaboró | C13: EICIT IA — asistencia técnica
B14: Encuadre | C14: EICIT propone y revisa; la autoevaluación es de la ENSMA, que delibera y adopta.
B16: Cómo está construida
B17: • Matriz_Revisión: las 96 filas ya vienen con proceso, componente y autovaloración I-2026 precargados.
B18: • Columna «Val. ciclo anterior (2025)» en naranja = lo único por diligenciar cuando ENSMA entregue el insumo.
B19: • La «Tendencia» se calcula sola al cargar el 2025; luego se concluye Coherencia, cotejo con PMI y Prioridad.
B20: • Evidencia_Externa y Tablero ya están cargados; Transverso_Calidad es el esqueleto del cuadro de mando.

Sheet Matriz_Revisión
A1: Proceso (SGC) | B1: Gestión (Guía 34) | C1: Subproceso | D1: Componente | E1: Val. ciclo anterior (2025) | F1: Val. I-2026 | G1: Tendencia | H1: Evidencia declarada (resumen) | I1: Triangulación externa | J1: Coherencia autoval.↔evidencia | K1: Oportunidad de mejora (instrumento) | L1: ¿Acción en PMI? | M1: Prioridad
A2: PROCESO DIRECTIVO → Gestión Directiva (25 componentes)
A3: DIRECTIVO | B3: Directiva | C3: Direccionamiento estratégico y horizonte institucional | D3: Conocimiento y apropiación de la Misión, Visión y Política de Calidad | F3: 4 | G3: =IF(E3="","—",IF(F3>E3,"▲",IF(F3<E3,"▼","="))) -> — | H3: Se cuenta con evidencias documentales y prácticas que demuestran la apropiación del horizonte institucional, tales como: los planes operativos y de me… | I3: Matrícula 803→425→503 (2015–24); transición de identidad (Normal→EPBM/técnica). | K3: Aunque se evidencia una apropiación significativa del horizonte institucional, es conveniente fortalecer los mecanismos de evaluación del impacto de las estrategias implementadas, ampliar los espacios…
A4: DIRECTIVO | B4: Directiva | C4: Direccionamiento estratégico y horizonte institucional | D4: Conocimiento y apropiación de los Objetivos institucionales | F4: 3 | G4: =IF(E4="","—",IF(F4>E4,"▲",IF(F4<E4,"▼","="))) -> — | H4: Los objetivos institucionales se encuentran consignados en el PEI, en algunas carteleras Asimismo, existen registros de capacitaciones, reuniones, jor… | I4: Matrícula 803→425→503 (2015–24); transición de identidad (Normal→EPBM/técnica). | K4: Fortalecer las estrategias de sensibilización y seguimiento para garantizar una mayor apropiación de los objetivos institucionales por parte de todos los miembros de la comunidad educativa. Asimismo, …
A5: DIRECTIVO | B5: Directiva | C5: Direccionamiento estratégico y horizonte institucional | D5: Conocimiento y apropiación de la filosofía educativa salesiana: Principios y Fundamentos del Sistema Preventivo de Don Bosco | F5: 4 | G5: =IF(E5="","—",IF(F5>E5,"▲",IF(F5<E5,"▼","="))) -> — | H5: Actas de ReuniónTriduo escolarManual de ConvivenciaAguinaldo del Rector mayor Capacitación: Formación conjunta. retiros espirituales por grado | K5: Continuar acompañando a toda la comunidad educativa de la institución para la vivencia del sistema preventivo y el aguinaldo del rector mayor.Tener presente que criterios se van a evaluar de acuerdo a…
A6: DIRECTIVO | B6: Directiva | C6: Direccionamiento estratégico y horizonte institucional | D6: Política de inclusión de estudiantes con capacidades disímiles o diversidad cultural | F6: 4 | G6: =IF(E6="","—",IF(F6>E6,"▲",IF(F6<E6,"▼","="))) -> — | H6: La cartelera informativa ENSUMAUXI inclusiva tercer piso. Acta reunión de consejo académico. Acta de Equipo Pastoral Actas de Reunión de Docentescapac… | I6: Matrícula 803→425→503 (2015–24); transición de identidad (Normal→EPBM/técnica). | K6: Fortalecer la apropiación de la política de educación inclusiva y de la normatividad vigente (Decreto 1421 de 2017 y Decreto 2216 de 2022), con el fin de consolidar estrategias integrales que responda…
A7: DIRECTIVO | B7: Directiva | C7: Gestión estratégica | D7: Liderazgo y criterios claros en el direccionamiento de la ENS | F7: 4 | G7: =IF(E7="","—",IF(F7>E7,"▲",IF(F7<E7,"▼","="))) -> — | H7: PEI y actas de reuniones del consejo académico, resultados de autoevaluaciones institucionales que están en el drive.Estos permiten verificar la plane… | K7: Fortalecer la sistematización y socialización de los acuerdos, decisiones y resultados derivados de las reuniones y autoevaluaciones, de manera que toda la comunidad educativa conozca los avances y co…
A8: DIRECTIVO | B8: Directiva | C8: Gestión estratégica | D8: Seguimiento y evaluación adecuada y oportuna de las actividades programadas y realizadas en la institución | F8: 3 | G8: =IF(E8="","—",IF(F8>E8,"▲",IF(F8<E8,"▼","="))) -> — | H8: Resultados de las evaluaciones aplicadas a las diferentes actividades institucionales desarrolladas con los cursos, los cuales permiten evidenciar el … | K8: Establecer estrategias de retroalimentación que permitan socializar los hallazgos de cada una de las actividades y definiendo de manera concreta las acciones de mejora.
A9: DIRECTIVO | B9: Directiva | C9: Gobierno escolar | D9: Organización y funcionamiento del Consejo Directivo | F9: 4 | G9: =IF(E9="","—",IF(F9>E9,"▲",IF(F9<E9,"▼","="))) -> — | H9: Acta de conformación Actas de reuniones | K9: Se recomienda dar continuidad a la gestión del Consejo Directivo mediante el seguimiento permanente de los temas abordados, el cumplimiento de los compromisos adquiridos y el avance efectivo de las ac…
A10: DIRECTIVO | B10: Directiva | C10: Gobierno escolar | D10: Organización y funcionamiento del Consejo Académico | F10: 4 | G10: =IF(E10="","—",IF(F10>E10,"▲",IF(F10<E10,"▼","="))) -> — | H10: Acta de conformación y actas de reuniones | K10: Continuar fortaleciendo este proceso, avanzando en pro de una gestión cada vez más eficiente y con miras a la mejora continua
A11: DIRECTIVO | B11: Directiva | C11: Gobierno escolar | D11: Organización y funcionamiento de las Comisiones de Evaluación y Promoción | F11: 4 | G11: =IF(E11="","—",IF(F11>E11,"▲",IF(F11<E11,"▼","="))) -> — | H11: Acta de conformación y actas de comisión y consolidado de notas | K11: Mayor exigencia y compromiso por parte de docentes en todo el proceso de pre-comisión y comisión, con el fin de contar con los soportes necesarios para poder proponer estrategias de mejora a casos esp…
A12: DIRECTIVO | B12: Directiva | C12: Gobierno escolar | D12: Organización y funcionamiento del Consejo Estudiantil | F12: 4 | G12: =IF(E12="","—",IF(F12>E12,"▲",IF(F12<E12,"▼","="))) -> — | H12: Acta de conformaciónActa izada de Banderas Posesión consejos estudiantil.Material visual en la carpeta de evidencias del área de Ciencias Sociales. | K12: Fortalecer el conocimiento y la apropiación de las funciones y responsabilidades de los integrantes del Consejo Estudiantil, con el fin de potenciar y visibilizar su liderazgo dentro de la comunidad e…
A13: DIRECTIVO | B13: Directiva | C13: Gobierno escolar | D13: Desempeño de la Personera de Estudiantes | F13: 3 | G13: =IF(E13="","—",IF(F13>E13,"▲",IF(F13<E13,"▼","="))) -> — | H13: Acta de posesiónHojas de vida Propuestas de gobiernoActa No 1 de izada de banderaActas de reuniones de consejo estudiantes y directivoParticipación co… | K13: Continuar trabajando con compromiso y responsabilidad para que sus propuestas se lleven a cabo para el beneficio de la comunidad estudiantil.
A14: DIRECTIVO | B14: Directiva | C14: Gobierno escolar | D14: Organización y realización de las reuniones con los Padres de familia | F14: 4 | G14: =IF(E14="","—",IF(F14>E14,"▲",IF(F14<E14,"▼","="))) -> — | H14: Acta de conformaciónLink de asistencia | K14: Continuar con la promoción de la importancia de asistencia a escuela de padres
A15: DIRECTIVO | B15: Directiva | C15: Gobierno escolar | D15: Organización y funcionamiento del Consejo de Padres de Familia. | F15: 3 | G15: =IF(E15="","—",IF(F15>E15,"▲",IF(F15<E15,"▼","="))) -> — | H15: Actas mensuales de reuniones del Consejo de Padres de Familia. | K15: Mayor compromiso por parte de los padres de familia en cuanto a la asistencia, asegurando la asistencia del titular o del suplente, para poder dar un buen orden a la reunión. Hacer seguimiento a los c…
A16: DIRECTIVO | B16: Directiva | C16: Cultura institucional | D16: Uso apropiado y oportuno de los Mecanismos de comunicación interna y externa | F16: 3 | G16: =IF(E16="","—",IF(F16>E16,"▲",IF(F16<E16,"▼","="))) -> — | H16: Se implementan medios físicos y virtuales, como lo son: agenda escolar, correos institucionales, plataforma (pegasus), teléfono institucional, redes s… | K16: Realizar una revisión periódica y oportuna de todos los medios de comunicación establecidos por la institución, tales como la agenda estudiantil, correos electrónicos, plataformas institucionales, cir…
A17: DIRECTIVO | B17: Directiva | C17: Cultura institucional | D17: Ambiente de trabajo colaborativo y en equipo | F17: 3 | G17: =IF(E17="","—",IF(F17>E17,"▲",IF(F17<E17,"▼","="))) -> — | H17: Se realizan diferentes encuentros de integración y socialización que ayudan y promueven el trabajo en equipo y la colaboración. Esto liderado por el c… | K17: Continuar fortaleciendo y ampliando los espacios de integración y socialización, promoviendo una mayor participación de todos los miembros de la comunidad educativa para consolidar el trabajo en equip…
A18: DIRECTIVO | B18: Directiva | C18: Cultura institucional | D18: Divulgación de las buenas prácticas educativas y de experiencias pedagógicas, significativas | F18: 4 | G18: =IF(E18="","—",IF(F18>E18,"▲",IF(F18<E18,"▼","="))) -> — | H18: La institución divulga información a través de redes sociales, boletines informativos y encuentros presenciales con la comunidad educativa, garantizan… | K18: Fortalecer el uso y alcance de las redes sociales institucionales como medio de divulgación de las actividades, proyectos y logros de la comunidad educativa, promoviendo una mayor participación e inte…
... A27: DIRECTIVO | B27: Directiva | C27: Relaciones con el entorno. | D27: Relaciones con el Sector Productivo | F27: 4 | G27: =IF(E27="","—",IF(F27>E27,"▲",IF(F27<E27,"▼","="))) -> — | H27: Se están articulando y estableciendo alianzas estratégicas con universidades,sector productivo y otras entidades con el propósito de fortalecer los pr… | K27: Continuar fortaleciendo los procesos de articulación entre la formación académica, técnica y las necesidades del entorno laboral.
A28: PROCESO ACADÉMICO PEDAGÓGICO → Gestión Académica (24 componentes)
A29: ACADÉMICO PEDAGÓGICO | B29: Académica | C29: Diseño Curricular | D29: Conocimiento, desarrollo y aplicación de la Estructura Curricular (formas 1, 2 y 3) y del Plan de estudios. | F29: 4 | G29: =IF(E29="","—",IF(F29>E29,"▲",IF(F29<E29,"▼","="))) -> — | H29: Se cuenta con las estructuras y formatos institucionales organizados por áreas en Drive. | K29: Continuar fortaleciendo el uso responsable y la actualización oportuna de estos instrumentos en el desarrollo del proceso académico.
A30: ACADÉMICO PEDAGÓGICO | B30: Académica | C30: Diseño Curricular | D30: Organización, desarrollo y articulación en el aula de los proyectos transversales. | F30: 3 | G30: =IF(E30="","—",IF(F30>E30,"▲",IF(F30<E30,"▼","="))) -> — | H30: Se cuenta con el documento y el formato F3 que registran la planeación de actividades de los proyectos transversales. | K30: Continuar llevando al aula las actividades propuestas para fortalecer el aprendizaje y la apropiación de los proyectos por parte de los estudiantes.
A31: ACADÉMICO PEDAGÓGICO | B31: Académica | C31: Diseño Curricular | D31: Conocimiento y aplicación en el aula de la estrategia pedagógica del Constructivismo y Aprendizaje Significativo. | F31: 4 | G31: =IF(E31="","—",IF(F31>E31,"▲",IF(F31<E31,"▼","="))) -> — | H31: En la Forma 3 se evidencia claramente mediante la secuencia didáctica establecida. | K31: Se sugiere dar continuidad a estas prácticas para asegurar y fortalecer la calidad educativa.
A32: ACADÉMICO PEDAGÓGICO | B32: Académica | C32: Diseño Curricular | D32: Uso apropiado de recursos didácticos virtuales y materiales para mejorar el aprendizaje. | F32: 2 | G32: =IF(E32="","—",IF(F32>E32,"▲",IF(F32<E32,"▼","="))) -> — | H32: Se busca la implementación desde la planeación en la F3. | I32: Coincide con línea base 1.2.5: aula virtual y creación con TIC son los ítems más bajos. | K32: Se deben priorizar la generación de espacios físicos y herramientas que promuevan el uso de las TICs.
A33: ACADÉMICO PEDAGÓGICO | B33: Académica | C33: Diseño Curricular | D33: Cumplimiento y provecho de la Jornada escolar. | F33: 4 | G33: =IF(E33="","—",IF(F33>E33,"▲",IF(F33<E33,"▼","="))) -> — | H33: Registro de inicio de jornada, llegadas tarde, información semanal de actividades a destacar y cronograma institucional. | K33: Estar atentos a las actualizaciones de los diferentes informes.
A34: ACADÉMICO PEDAGÓGICO | B34: Académica | C34: Diseño Curricular | D34: Conocimiento y aplicación del Sistema Institucional de Evaluación del Aprendizaje y de la Matriz de Evaluación Integral según nuevos ajustes. | F34: 4 | G34: =IF(E34="","—",IF(F34>E34,"▲",IF(F34<E34,"▼","="))) -> — | H34: Se evidencia en la plataforma educativa Pegasus y las planillas físicas. En el PMI. En las formas 4 mediante plan de mejora. | I34: Saber 11: −19,8 pts (2023–2025), caída en todas las áreas; foco C. Naturales y Sociales. | K34: Continuar con la formación y aplicación del SIEE.
A35: ACADÉMICO PEDAGÓGICO | B35: Académica | C35: Desempeño docente de la práctica pedagógica en el aula. | D35: Asignación de tareas dosificadas que facilitan: la profundización, complementación, asimilación y aplicación de los conocimientos trabajados en clase. | F35: 3 | G35: =IF(E35="","—",IF(F35>E35,"▲",IF(F35<E35,"▼","="))) -> — | H35: Se evidencia en las formas 3, y así mismo en el cronograma de tareas por curso. | K35: Continuar fortaleciendo el objetivo de las tareas en casa..
A36: ACADÉMICO PEDAGÓGICO | B36: Académica | C36: Desempeño docente de la práctica pedagógica en el aula. | D36: Empleo responsable y apropiado del tiempo de clase para mejorar el aprendizaje. | F36: 4 | G36: =IF(E36="","—",IF(F36>E36,"▲",IF(F36<E36,"▼","="))) -> — | H36: Trazabilidad con forma 3, cuadernos, planillas y observaciones de clase. | K36: Continuar trabajando y fortaleciendo los procesos del empleo responsable y apropiado del tiempo de clase para mejorar el aprendizaje.
A37: ACADÉMICO PEDAGÓGICO | B37: Académica | C37: Desempeño docente de la práctica pedagógica en el aula. | D37: Implementar la cultura de la Investigación en el aula, para un mejor aprendizaje. | F37: 2 | G37: =IF(E37="","—",IF(F37>E37,"▲",IF(F37<E37,"▼","="))) -> — | H37: Predomina la mecanización de las clases, con énfasis en lo formal, dejando en segundo plano actividades de exploración como el trabajo de campo. | K37: Incentivar a los docentes a promover la transversalidad desde las diferentes áreas, fortaleciendo la cultura investigativa.
A38: ACADÉMICO PEDAGÓGICO | B38: Académica | C38: Desempeño docente de la práctica pedagógica en el aula. | D38: Planeación y preparación apropiada de las clases periódicamente según la estructura curricular. | F38: 4 | G38: =IF(E38="","—",IF(F38>E38,"▲",IF(F38<E38,"▼","="))) -> — | H38: Se puede evidenciar en las formas 3, seguimiento de trabajo en clase. | K38: Continuar con el proceso de la planeación y preparación apropiada de las clases periódicamente según la estructura curricular.
A39: ACADÉMICO PEDAGÓGICO | B39: Académica | C39: Gestión en el aula | D39: Aplicación de estrategias pedagógicas para mejorar el aprendizaje en el aula y motivar al alcance de la excelencia. | F39: 3 | G39: =IF(E39="","—",IF(F39>E39,"▲",IF(F39<E39,"▼","="))) -> — | H39: La excelencia académica en las asignaturas. | K39: Motivar e implementar estrategias pedagógicas innovadoras y didácticas, lúdicas.
A40: ACADÉMICO PEDAGÓGICO | B40: Académica | C40: Gestión en el aula | D40: Aplicación de diversas estrategias de Evaluación del aprendizaje según la planeación de las formas. tres | F40: 4 | G40: =IF(E40="","—",IF(F40>E40,"▲",IF(F40<E40,"▼","="))) -> — | H40: Se evidencia en la Forma 3, a través del seguimiento al trabajo desarrollado en clase. | I40: Saber 11: −19,8 pts (2023–2025), caída en todas las áreas; foco C. Naturales y Sociales. | K40: Se recomienda continuar fortaleciendo la elaboración y aplicación de diferentes tipos de evaluación.
A41: ACADÉMICO PEDAGÓGICO | B41: Académica | C41: Gestión en el aula | D41: Uso pedagógico de los resultados de las evaluaciones del conocimiento en el aula, para mejorar el aprendizaje de los estudiantes. | F41: 4 | G41: =IF(E41="","—",IF(F41>E41,"▲",IF(F41<E41,"▼","="))) -> — | H41: Se puede evidenciar en las actas de consejo académico, en las formas 4.Los resultados de icfes de la entidad que lo realiza. | I41: Saber 11: −19,8 pts (2023–2025), caída en todas las áreas; foco C. Naturales y Sociales. | K41: Continuar con la generación de estrategias que permitan un análisis exhaustivo de las evaluaciones de conocimiento en el aula.
A42: ACADÉMICO PEDAGÓGICO | B42: Académica | C42: Seguimiento y acompañamiento académico | D42: Uso pedagógico de los resultados de las evaluaciones externas (Estado), para mejorar el aprendizaje en el aula. | F42: 4 | G42: =IF(E42="","—",IF(F42>E42,"▲",IF(F42<E42,"▼","="))) -> — | H42: Se realiza revisión y socialización desde consejo académico de los resultados de las pruebas externas anualmente | I42: Saber 11: −19,8 pts (2023–2025), caída en todas las áreas; foco C. Naturales y Sociales. | K42: Continuar realizando la socialización de las pruebas externas con el fin de que en cada área se puedan implementar las estrategías de mejora pertinentes.
A43: ACADÉMICO PEDAGÓGICO | B43: Académica | C43: Seguimiento y acompañamiento académico | D43: Control y seguimiento de asistencia a clase de estudiantes, por educadores y coordinación. | F43: 4 | G43: =IF(E43="","—",IF(F43>E43,"▲",IF(F43<E43,"▼","="))) -> — | H43: Se cuenta con evidencia en las planillas de asistencia de cada docente, así como en la agenda de portería, donde se registra diariamente la inasistenc… | I43: Saber 11: −19,8 pts (2023–2025), caída en todas las áreas; foco C. Naturales y Sociales. | K43: Se considera fundamental mantener la rigurosidad en el manejo de las inasistencias para garantizar la efectividad del proceso; adicionalmente, se sugiere implementar una estrategia virtual de control …
A44: ACADÉMICO PEDAGÓGICO | B44: Académica | C44: Seguimiento y acompañamiento académico | D44: Reconocimiento y estímulos a estudiantes que sobresalen en su formación integral. | F44: 4 | G44: =IF(E44="","—",IF(F44>E44,"▲",IF(F44<E44,"▼","="))) -> — | H44: Los estudiantes que sobresalen en su formación integral quedan en cuadro de honor y este es visible, además se entrega a los estudiantes un reconocimi… | K44: Pensar en otro reconocimiento para premiar a los estudiantes por su formación integral y tener en cuenta los estudiantes que alcanzan el nivel alto o superior en cuarto periodo para dar su respectivo …
A45: ACADÉMICO PEDAGÓGICO | B45: Académica | C45: Seguimiento y acompañamiento académico | D45: Seguimiento y acompañamiento pedagógico en el aula, a estudiantes con desempeño bajo por debilidades académicas y/o formativas. | F45: 4 | G45: =IF(E45="","—",IF(F45>E45,"▲",IF(F45<E45,"▼","="))) -> — | H45: Los docentes realizan seguimiento y acompañamiento procesual a los estudiantes con desempeño bajo y se cita acudiente para informar. Se registra en el… | I45: Saber 11: −19,8 pts (2023–2025), caída en todas las áreas; foco C. Naturales y Sociales. | K45: Aunque se hace un proceso, en ocasiones se cita a los padres de familia sobre el tiempo, finalizando el periodo, lo que impide que la familia esté con mayor acompañamiento tiempo antes.
A46: ACADÉMICO PEDAGÓGICO | B46: Académica | C46: Seguimiento y acompañamiento académico | D46: Seguimiento y acompañamiento por Coordinación y Psico-orientación a estudiantes con debilidades especiales, académicas y/o formativas. | F46: 4 | G46: =IF(E46="","—",IF(F46>E46,"▲",IF(F46<E46,"▼","="))) -> — | H46: Los registros de los encuentros se consignan en el observador del estudiante, en las agendas y en la plataforma Pegasus. | I46: Saber 11: −19,8 pts (2023–2025), caída en todas las áreas; foco C. Naturales y Sociales. | K46: Se recomienda fortalecer estrategias de acompañamiento con las familias y dar continuidad al seguimiento de los estudiantes con PIAR.
A47: ACADÉMICO PEDAGÓGICO | B47: Académica | C47: Seguimiento y acompañamiento académico | D47: Organización y realización de seguimiento y encuentros de egresadas. | F47: 2 | G47: =IF(E47="","—",IF(F47>E47,"▲",IF(F47<E47,"▼","="))) -> — | H47: Se realiza seguimiento a los estudiantes egresados mediante una base de datos actualizada periódicamente y la organización de un cronograma anual de e… | I47: Saber 11: −19,8 pts (2023–2025), caída en todas las áreas; foco C. Naturales y Sociales. | K47: Se recomienda implementar estrategias que fortalezcan la vinculación de los egresados, promoviendo una mayor participación e incluyendo incentivos que favorezcan su asistencia.
A48: ACADÉMICO PEDAGÓGICO | B48: Académica | C48: Seguimiento y acompañamiento académico | D48: Orientación y acompañamiento por coordinación y maestros orientadores, a los estudiantes del PFC (Programa de Formación Complementaria), en el proceso formativo según el plan de estudios y en su desempeño en la práctica docente. | F48: 4 | G48: =IF(E48="","—",IF(F48>E48,"▲",IF(F48<E48,"▼","="))) -> — | H48: Està evidenciado en los contenidos programàticos del PFC y carpetas propias de la coordinaciòn de investigaciòn | I48: Saber 11: −19,8 pts (2023–2025), caída en todas las áreas; foco C. Naturales y Sociales. | K48: Continuar fortaleciendo la apropiación de los contenidos de clase y el contenido propio de los proyectos de investigación por parte de las maestras de formación..
...

Sheet Tablero_Perfil
A1: Perfil institucional de calidad — consolidado (auto)
A3: Proceso | B3: N.º comp. | C3: Nivel 1 | D3: Nivel 2 | E3: Nivel 3 | F3: Nivel 4 | G3: Media I-2026
A4: DIRECTIVO | B4: =COUNTIF(Matriz_Revisión!A2:A103,"DIRECTIVO") -> 25 | C4: =COUNTIFS(Matriz_Revisión!A2:A103,"DIRECTIVO",Matriz_Revisión!F2:F103,1) -> 0 | D4: =COUNTIFS(Matriz_Revisión!A2:A103,"DIRECTIVO",Matriz_Revisión!F2:F103,2) -> 0 | E4: =COUNTIFS(Matriz_Revisión!A2:A103,"DIRECTIVO",Matriz_Revisión!F2:F103,3) -> 8 | F4: =COUNTIFS(Matriz_Revisión!A2:A103,"DIRECTIVO",Matriz_Revisión!F2:F103,4) -> 17 | G4: =IFERROR(AVERAGEIF(Matriz_Revisión!A2:A103,"DIRECTIVO",Matriz_Revisión!F2:F103),"—") -> 3.68
A5: ACADÉMICO PEDAGÓGICO | B5: =COUNTIF(Matriz_Revisión!A2:A103,"ACADÉMICO PEDAGÓGICO") -> 24 | C5: =COUNTIFS(Matriz_Revisión!A2:A103,"ACADÉMICO PEDAGÓGICO",Matriz_Revisión!F2:F103,1) -> 0 | D5: =COUNTIFS(Matriz_Revisión!A2:A103,"ACADÉMICO PEDAGÓGICO",Matriz_Revisión!F2:F103,2) -> 3 | E5: =COUNTIFS(Matriz_Revisión!A2:A103,"ACADÉMICO PEDAGÓGICO",Matriz_Revisión!F2:F103,3) -> 3 | F5: =COUNTIFS(Matriz_Revisión!A2:A103,"ACADÉMICO PEDAGÓGICO",Matriz_Revisión!F2:F103,4) -> 18 | G5: =IFERROR(AVERAGEIF(Matriz_Revisión!A2:A103,"ACADÉMICO PEDAGÓGICO",Matriz_Revisión!F2:F103),"—") -> 3.625
A6: ADMINISTRATIVO FINANCIERO | B6: =COUNTIF(Matriz_Revisión!A2:A103,"ADMINISTRATIVO FINANCIERO") -> 20 | C6: =COUNTIFS(Matriz_Revisión!A2:A103,"ADMINISTRATIVO FINANCIERO",Matriz_Revisión!F2:F103,1) -> 0 | D6: =COUNTIFS(Matriz_Revisión!A2:A103,"ADMINISTRATIVO FINANCIERO",Matriz_Revisión!F2:F103,2) -> 0 | E6: =COUNTIFS(Matriz_Revisión!A2:A103,"ADMINISTRATIVO FINANCIERO",Matriz_Revisión!F2:F103,3) -> 4 | F6: =COUNTIFS(Matriz_Revisión!A2:A103,"ADMINISTRATIVO FINANCIERO",Matriz_Revisión!F2:F103,4) -> 16 | G6: =IFERROR(AVERAGEIF(Matriz_Revisión!A2:A103,"ADMINISTRATIVO FINANCIERO",Matriz_Revisión!F2:F103),"—") -> 3.8
A7: SOCIAL COMUNITARIO | B7: =COUNTIF(Matriz_Revisión!A2:A103,"SOCIAL COMUNITARIO") -> 10 | C7: =COUNTIFS(Matriz_Revisión!A2:A103,"SOCIAL COMUNITARIO",Matriz_Revisión!F2:F103,1) -> 0 | D7: =COUNTIFS(Matriz_Revisión!A2:A103,"SOCIAL COMUNITARIO",Matriz_Revisión!F2:F103,2) -> 0 | E7: =COUNTIFS(Matriz_Revisión!A2:A103,"SOCIAL COMUNITARIO",Matriz_Revisión!F2:F103,3) -> 3 | F7: =COUNTIFS(Matriz_Revisión!A2:A103,"SOCIAL COMUNITARIO",Matriz_Revisión!F2:F103,4) -> 7 | G7: =IFERROR(AVERAGEIF(Matriz_Revisión!A2:A103,"SOCIAL COMUNITARIO",Matriz_Revisión!F2:F103),"—") -> 3.7
A8: EVANGELIZADOR | B8: =COUNTIF(Matriz_Revisión!A2:A103,"EVANGELIZADOR") -> 12 | C8: =COUNTIFS(Matriz_Revisión!A2:A103,"EVANGELIZADOR",Matriz_Revisión!F2:F103,1) -> 0 | D8: =COUNTIFS(Matriz_Revisión!A2:A103,"EVANGELIZADOR",Matriz_Revisión!F2:F103,2) -> 1 | E8: =COUNTIFS(Matriz_Revisión!A2:A103,"EVANGELIZADOR",Matriz_Revisión!F2:F103,3) -> 3 | F8: =COUNTIFS(Matriz_Revisión!A2:A103,"EVANGELIZADOR",Matriz_Revisión!F2:F103,4) -> 8 | G8: =IFERROR(AVERAGEIF(Matriz_Revisión!A2:A103,"EVANGELIZADOR",Matriz_Revisión!F2:F103),"—") -> 3.5833333
A9: GESTIÓN DE CALIDAD | B9: =COUNTIF(Matriz_Revisión!A2:A103,"GESTIÓN DE CALIDAD") -> 5 | C9: =COUNTIFS(Matriz_Revisión!A2:A103,"GESTIÓN DE CALIDAD",Matriz_Revisión!F2:F103,1) -> 0 | D9: =COUNTIFS(Matriz_Revisión!A2:A103,"GESTIÓN DE CALIDAD",Matriz_Revisión!F2:F103,2) -> 0 | E9: =COUNTIFS(Matriz_Revisión!A2:A103,"GESTIÓN DE CALIDAD",Matriz_Revisión!F2:F103,3) -> 3 | F9: =COUNTIFS(Matriz_Revisión!A2:A103,"GESTIÓN DE CALIDAD",Matriz_Revisión!F2:F103,4) -> 2 | G9: =IFERROR(AVERAGEIF(Matriz_Revisión!A2:A103,"GESTIÓN DE CALIDAD",Matriz_Revisión!F2:F103),"—") -> 3.4
A10: TOTAL | B10: =SUM(B4:B9) -> 96 | C10: =COUNTIF(Matriz_Revisión!F2:F103,1) -> 0 | D10: =COUNTIF(Matriz_Revisión!F2:F103,2) -> 4 | E10: =COUNTIF(Matriz_Revisión!F2:F103,3) -> 24 | F10: =COUNTIF(Matriz_Revisión!F2:F103,4) -> 68 | G10: =IFERROR(AVERAGE(Matriz_Revisión!F2:F103),"—") -> 3.6666667
A12: Lectura: 71% de los componentes se autovaloran en nivel 4 y ninguno en nivel 1 — leer con cautela (efecto techo). El contraste con la evidencia externa (hoja Evidencia_Externa) es el núcleo de la revisión.

Sheet Evidencia_Externa
A1: Evidencia externa para triangular la autovaloración
A3: Saber 11 — puntaje por área (fuente: ICFES, reexpuesto por ICFES Analytics)
A4: Área | B4: 2023 | C4: 2024 | D4: 2025 | E4: Δ 2023–25
A5: Global | B5: 324.6 | C5: 316 | D5: 304.8 | E5: =D5-B5 -> -19.8
A6: Matemáticas | B6: 65.6 | C6: 61.9 | D6: 60.3 | E6: =D6-B6 -> -5.3
A7: Lectura Crítica | B7: 64.8 | C7: 64.9 | D7: 62.9 | E7: =D7-B7 -> -1.9
A8: Ciencias Naturales | B8: 63.6 | C8: 62.1 | D8: 59.6 | E8: =D8-B8 -> -4
A9: Sociales y Ciudadanas | B9: 63.4 | C9: 60.9 | D9: 58.4 | E9: =D9-B9 -> -5
A10: Inglés | B10: 71.4 | C10: 71.9 | D10: 69.2 | E10: =D10-B10 -> -2.2
A12: Contexto 2025
A13: Puntaje global 2025 | B13: 304,8
A14: Percentil nacional | B14: 88 (Top 12%)
A15: Puesto Soacha | B15: #5 de 113
A16: Valor agregado contextual | B16: +42,6 pts sobre lo esperado (262,2)
A17: vs promedio nacional | B17: +47,1 pts
A18: Estudiantes evaluados | B18: ≈25 (alta variabilidad entre cohortes)
A19: Fortalezas | B19: Inglés · Lectura Crítica
A20: Áreas foco | B20: C. Naturales · Sociales y Ciudadanas
A22: Matrícula (SIMAT) — evolución
A23: 2015 | B23: 2016 | C23: 2017 | D23: 2018 | E23: 2019 | F23: 2020 | G23: 2021 | H23: 2022 | I23: 2024
A24: 803 | B24: 683 | C24: 636 | D24: 595 | E24: 553 | F24: 470 | G24: 446 | H24: 425 | I24: 503
A26: 803 (2015) → piso 425 (2022) → 503 (2024). Grados 9–11 hoy 100% femeninos; preescolar/primaria mixtos: transición de identidad.
A29: Fuentes: ICFES Analytics (icfes-analytics.com) y MIAcademia (miacademia.ai), plataformas de terceros; puntajes por área = datos oficiales ICFES reexpuestos. Índices derivados (valor agregado, cuadrantes) son modelos propios, no causales. N≈25 → interpretar con cautela.

Sheet Transverso_Calidad
A1: Transverso de calidad — esqueleto del cuadro de mando (a definir en el PEI)
A2: Línea base precargada donde existe; metas, responsables y periodicidad se concretan con la ENSMA.
A4: Indicador | B4: Fuente | C4: Línea base | D4: Meta 2027 | E4: Responsable | F4: Periodicidad
A5: Saber 11 — puntaje global | B5: ICFES | C5: 304,8 (2025)
A6: Saber 11 — C. Naturales | B6: ICFES | C6: 59,6 (2025)
A7: Saber 11 — Sociales y Ciudadanas | B7: ICFES | C7: 58,4 (2025)
A8: Matrícula total | B8: SIMAT | C8: 503 (2024)
A9: Competencia digital docente (índice) | B9: Instrumento 1.2.5 | C9: 79,4 (2026)
A10: Brecha IA docente (interés−destreza) | B10: Instrumento 1.2.5 | C10: 23,2 (2026)
A11: % componentes autoeval. ≥ nivel 3 | B11: Autoevaluación Guía 34 | C11: ≈96% (I-2026)
A12: Cierre de oportunidades de mejora del PMI | B12: PMI / seguimiento | C12: (cargar)
A13: Uso de recursos virtuales/multimedia (aula) | B13: Autoeval. comp. · 1.2.5 | C13: Nivel 2 (I-2026)
A15: El transverso re-funda el proceso de Gestión de Calidad ya existente, re-anclado al horizonte nuevo (post-Normal, EPBM + media técnica) e incorporando innovación/tecnología como dimensión evaluable.

Sheet Notas_Método
B1: Notas de método, escala y pendientes
B3: Escala Guía 34 (autovaloración)
B4: 1 Existencia · 2 Pertinencia · 3 Apropiación · 4 Mejoramiento continuo.
B5: Semáforo de la matriz: 1 rojo · 2 naranja · 3 amarillo · 4 verde. Naranja claro = celda por diligenciar.
B6: Lo que falta para concluir
B7: • Autoevaluación del ciclo anterior (2025) → columna E de la matriz; habilita «Tendencia» y el contraste temporal del propio instrumento.
B8: • PMI del año anterior con corte de seguimiento → columna L (¿acción en PMI?) y cierre de oportunidades.
B9: • Ratificación de la autoevaluación por Consejo Académico/Directivo (traza de gobernanza).
B10: Hallazgos ya visibles
B11: • Autovaloración sesgada al alza: 71% en nivel 4, 0 en nivel 1 — efecto techo, coherente con el instrumento de competencias.
B12: • El componente «recursos didácticos virtuales y multimedia» se autopuntúa en 2: la institución ya reconoce la brecha tecnológica.
B13: • Saber 11 en descenso 3 años mientras el proceso académico se autovalora alto → principal tensión a resolver en el PEI.
B14: Encuadre EICIT propone y revisa; la autoevaluación es de la ENSMA. No se modifican sus valoraciones: se contrastan con evidencia y se priorizan.
