Workbook

Sheet Resumen cursos
A1: INFORME DE HORAS SEMANALES POR CURSO Y MATERIA
A2: Curso | B2: Horas semanales | C2: N.º materias/actividades | D2: Mayor carga en una materia | E2: Observación
A3: TA | B3: =SUMIFS(Detalle!$F$2:$F$723,Detalle!$A$2:$A$723,A3) -> 35 | C3: =COUNTA('Curso TA'!$A$4:$A$18) -> 15 | D3: =MAX('Curso TA'!$B$4:$B$18) -> 7
A4: 1A | B4: =SUMIFS(Detalle!$F$2:$F$723,Detalle!$A$2:$A$723,A4) -> 35 | C4: =COUNTA('Curso 1A'!$A$5:$A$20) -> 16 | D4: =MAX('Curso 1A'!$B$5:$B$20) -> 5
A5: 1B | B5: =SUMIFS(Detalle!$F$2:$F$723,Detalle!$A$2:$A$723,A5) -> 35 | C5: =COUNTA('Curso 1B'!$A$5:$A$20) -> 16 | D5: =MAX('Curso 1B'!$B$5:$B$20) -> 5
A6: 2A | B6: =SUMIFS(Detalle!$F$2:$F$723,Detalle!$A$2:$A$723,A6) -> 35 | C6: =COUNTA('Curso 2A'!$A$5:$A$20) -> 16 | D6: =MAX('Curso 2A'!$B$5:$B$20) -> 5 | E6: Revisar Observaciones
A7: 2B | B7: =SUMIFS(Detalle!$F$2:$F$723,Detalle!$A$2:$A$723,A7) -> 35 | C7: =COUNTA('Curso 2B'!$A$5:$A$19) -> 15 | D7: =MAX('Curso 2B'!$B$5:$B$19) -> 5
A8: 3A | B8: =SUMIFS(Detalle!$F$2:$F$723,Detalle!$A$2:$A$723,A8) -> 35 | C8: =COUNTA('Curso 3A'!$A$5:$A$20) -> 16 | D8: =MAX('Curso 3A'!$B$5:$B$20) -> 5
A9: 3B | B9: =SUMIFS(Detalle!$F$2:$F$723,Detalle!$A$2:$A$723,A9) -> 35 | C9: =COUNTA('Curso 3B'!$A$5:$A$20) -> 16 | D9: =MAX('Curso 3B'!$B$5:$B$20) -> 5
A10: 3C | B10: =SUMIFS(Detalle!$F$2:$F$723,Detalle!$A$2:$A$723,A10) -> 35 | C10: =COUNTA('Curso 3C'!$A$5:$A$20) -> 16 | D10: =MAX('Curso 3C'!$B$5:$B$20) -> 5
A11: 4A | B11: =SUMIFS(Detalle!$F$2:$F$723,Detalle!$A$2:$A$723,A11) -> 35 | C11: =COUNTA('Curso 4A'!$A$5:$A$22) -> 18 | D11: =MAX('Curso 4A'!$B$5:$B$22) -> 4
A12: 4B | B12: =SUMIFS(Detalle!$F$2:$F$723,Detalle!$A$2:$A$723,A12) -> 35 | C12: =COUNTA('Curso 4B'!$A$5:$A$22) -> 18 | D12: =MAX('Curso 4B'!$B$5:$B$22) -> 4
A13: 5A | B13: =SUMIFS(Detalle!$F$2:$F$723,Detalle!$A$2:$A$723,A13) -> 35 | C13: =COUNTA('Curso 5A'!$A$5:$A$22) -> 18 | D13: =MAX('Curso 5A'!$B$5:$B$22) -> 4
A14: 5B | B14: =SUMIFS(Detalle!$F$2:$F$723,Detalle!$A$2:$A$723,A14) -> 35 | C14: =COUNTA('Curso 5B'!$A$5:$A$22) -> 18 | D14: =MAX('Curso 5B'!$B$5:$B$22) -> 4
A15: 6A | B15: =SUMIFS(Detalle!$F$2:$F$723,Detalle!$A$2:$A$723,A15) -> 35 | C15: =COUNTA('Curso 6A'!$A$5:$A$22) -> 18 | D15: =MAX('Curso 6A'!$B$5:$B$22) -> 4
A16: 6B | B16: =SUMIFS(Detalle!$F$2:$F$723,Detalle!$A$2:$A$723,A16) -> 35 | C16: =COUNTA('Curso 6B'!$A$5:$A$22) -> 18 | D16: =MAX('Curso 6B'!$B$5:$B$22) -> 4
A17: 7A | B17: =SUMIFS(Detalle!$F$2:$F$723,Detalle!$A$2:$A$723,A17) -> 35 | C17: =COUNTA('Curso 7A'!$A$5:$A$22) -> 18 | D17: =MAX('Curso 7A'!$B$5:$B$22) -> 4
A18: 7B | B18: =SUMIFS(Detalle!$F$2:$F$723,Detalle!$A$2:$A$723,A18) -> 35 | C18: =COUNTA('Curso 7B'!$A$5:$A$22) -> 18 | D18: =MAX('Curso 7B'!$B$5:$B$22) -> 4
A19: 8° | B19: =SUMIFS(Detalle!$F$2:$F$723,Detalle!$A$2:$A$723,A19) -> 35 | C19: =COUNTA('Curso 8°'!$A$5:$A$23) -> 19 | D19: =MAX('Curso 8°'!$B$5:$B$23) -> 4 | E19: Revisar Observaciones
A20: 9° | B20: =SUMIFS(Detalle!$F$2:$F$723,Detalle!$A$2:$A$723,A20) -> 35 | C20: =COUNTA('Curso 9°'!$A$5:$A$22) -> 18 | D20: =MAX('Curso 9°'!$B$5:$B$22) -> 4
A21: 10° | B21: =SUMIFS(Detalle!$F$2:$F$723,Detalle!$A$2:$A$723,A21) -> 35 | C21: =COUNTA('Curso 10°'!$A$5:$A$21) -> 17 | D21: =MAX('Curso 10°'!$B$5:$B$21) -> 5
A22: 11° | B22: =SUMIFS(Detalle!$F$2:$F$723,Detalle!$A$2:$A$723,A22) -> 35 | C22: =COUNTA('Curso 11°'!$A$5:$A$21) -> 17 | D22: =MAX('Curso 11°'!$B$5:$B$21) -> 5
A23: IV SEMESTRE | B23: =SUMIFS(Detalle!$F$2:$F$723,Detalle!$A$2:$A$723,A23) -> 22 | C23: =COUNTA('Curso IV SEMESTRE'!$A$5:$A$16) -> 12 | D23: =MAX('Curso IV SEMESTRE'!$B$5:$B$16) -> 3
A24: TOTAL | B24: =SUM(B3:B23) -> 722

Sheet Resumen materias
A1: RESUMEN GENERAL POR MATERIA / ACTIVIDAD
A2: Materia / actividad | B2: Horas semanales totales | C2: Cursos con presencia
A3: INGLÉS | B3: =SUMIFS(Detalle!$F$2:$F$723,Detalle!$E$2:$E$723,A3) -> 81 | C3: =COUNTIF('Matriz cursos'!B3:V3,">0") -> 20
A4: L. CASTELLANA | B4: =SUMIFS(Detalle!$F$2:$F$723,Detalle!$E$2:$E$723,A4) -> 80 | C4: =COUNTIF('Matriz cursos'!B4:V4,">0") -> 19
A5: C. NATURALES | B5: =SUMIFS(Detalle!$F$2:$F$723,Detalle!$E$2:$E$723,A5) -> 68 | C5: =COUNTIF('Matriz cursos'!B5:V5,">0") -> 17
A6: MATEMÁTICAS | B6: =SUMIFS(Detalle!$F$2:$F$723,Detalle!$E$2:$E$723,A6) -> 60 | C6: =COUNTIF('Matriz cursos'!B6:V6,">0") -> 15
A7: ED. FÍSICA | B7: =SUMIFS(Detalle!$F$2:$F$723,Detalle!$E$2:$E$723,A7) -> 40 | C7: =COUNTIF('Matriz cursos'!B7:V7,">0") -> 20
A8: ERE | B8: =SUMIFS(Detalle!$F$2:$F$723,Detalle!$E$2:$E$723,A8) -> 40 | C8: =COUNTIF('Matriz cursos'!B8:V8,">0") -> 20
A9: INFORMÁTICA | B9: =SUMIFS(Detalle!$F$2:$F$723,Detalle!$E$2:$E$723,A9) -> 38 | C9: =COUNTIF('Matriz cursos'!B9:V9,">0") -> 19
A10: C. SOCIALES | B10: =SUMIFS(Detalle!$F$2:$F$723,Detalle!$E$2:$E$723,A10) -> 28 | C10: =COUNTIF('Matriz cursos'!B10:V10,">0") -> 7
A11: EUCARISTÍA | B11: =SUMIFS(Detalle!$F$2:$F$723,Detalle!$E$2:$E$723,A11) -> 21 | C11: =COUNTIF('Matriz cursos'!B11:V11,">0") -> 21
A12: DANZAS | B12: =SUMIFS(Detalle!$F$2:$F$723,Detalle!$E$2:$E$723,A12) -> 20 | C12: =COUNTIF('Matriz cursos'!B12:V12,">0") -> 20
A13: GEOGRAFÍA | B13: =SUMIFS(Detalle!$F$2:$F$723,Detalle!$E$2:$E$723,A13) -> 20 | C13: =COUNTIF('Matriz cursos'!B13:V13,">0") -> 10
A14: HISTORIA | B14: =SUMIFS(Detalle!$F$2:$F$723,Detalle!$E$2:$E$723,A14) -> 20 | C14: =COUNTIF('Matriz cursos'!B14:V14,">0") -> 10
... A50: SIN IDENTIFICAR | B50: =SUMIFS(Detalle!$F$2:$F$723,Detalle!$E$2:$E$723,A50) -> 1 | C50: =COUNTIF('Matriz cursos'!B50:V50,">0") -> 1
A51: TOTAL | B51: =SUM(B3:B50) -> 722

Sheet Matriz cursos
A1: MATRIZ DE HORAS SEMANALES POR MATERIA Y CURSO
A2: Materia / actividad | B2: TA | C2: 1A | D2: 1B | E2: 2A | F2: 2B | G2: 3A | H2: 3B | I2: 3C | J2: 4A | K2: 4B | L2: 5A | M2: 5B | N2: 6A | O2: 6B | P2: 7A | Q2: 7B | R2: 8° | S2: 9° | T2: 10° | U2: 11° | V2: IV SEMESTRE
A3: INGLÉS | B3: =SUMIFS(Detalle!$F$2:$F$723,Detalle!$A$2:$A$723,B$2,Detalle!$E$2:$E$723,$A3) -> 3 | C3: =SUMIFS(Detalle!$F$2:$F$723,Detalle!$A$2:$A$723,C$2,Detalle!$E$2:$E$723,$A3) -> 4 | D3: =SUMIFS(Detalle!$F$2:$F$723,Detalle!$A$2:$A$723,D$2,Detalle!$E$2:$E$723,$A3) -> 4 | E3: =SUMIFS(Detalle!$F$2:$F$723,Detalle!$A$2:$A$723,E$2,Detalle!$E$2:$E$723,$A3) -> 4 | F3: =SUMIFS(Detalle!$F$2:$F$723,Detalle!$A$2:$A$723,F$2,Detalle!$E$2:$E$723,$A3) -> 4 | G3: =SUMIFS(Detalle!$F$2:$F$723,Detalle!$A$2:$A$723,G$2,Detalle!$E$2:$E$723,$A3) -> 4 | H3: =SUMIFS(Detalle!$F$2:$F$723,Detalle!$A$2:$A$723,H$2,Detalle!$E$2:$E$723,$A3) -> 4 | I3: =SUMIFS(Detalle!$F$2:$F$723,Detalle!$A$2:$A$723,I$2,Detalle!$E$2:$E$723,$A3) -> 4 | ... V3: =SUMIFS(Detalle!$F$2:$F$723,Detalle!$A$2:$A$723,V$2,Detalle!$E$2:$E$723,$A3) -> 0
A4: L. CASTELLANA | B4: =SUMIFS(Detalle!$F$2:$F$723,Detalle!$A$2:$A$723,B$2,Detalle!$E$2:$E$723,$A4) -> 0 | C4: =SUMIFS(Detalle!$F$2:$F$723,Detalle!$A$2:$A$723,C$2,Detalle!$E$2:$E$723,$A4) -> 5 | D4: =SUMIFS(Detalle!$F$2:$F$723,Detalle!$A$2:$A$723,D$2,Detalle!$E$2:$E$723,$A4) -> 5 | E4: =SUMIFS(Detalle!$F$2:$F$723,Detalle!$A$2:$A$723,E$2,Detalle!$E$2:$E$723,$A4) -> 5 | F4: =SUMIFS(Detalle!$F$2:$F$723,Detalle!$A$2:$A$723,F$2,Detalle!$E$2:$E$723,$A4) -> 5 | G4: =SUMIFS(Detalle!$F$2:$F$723,Detalle!$A$2:$A$723,G$2,Detalle!$E$2:$E$723,$A4) -> 5 | H4: =SUMIFS(Detalle!$F$2:$F$723,Detalle!$A$2:$A$723,H$2,Detalle!$E$2:$E$723,$A4) -> 5 | I4: =SUMIFS(Detalle!$F$2:$F$723,Detalle!$A$2:$A$723,I$2,Detalle!$E$2:$E$723,$A4) -> 5 | ... V4: =SUMIFS(Detalle!$F$2:$F$723,Detalle!$A$2:$A$723,V$2,Detalle!$E$2:$E$723,$A4) -> 0
A5: C. NATURALES | B5: =SUMIFS(Detalle!$F$2:$F$723,Detalle!$A$2:$A$723,B$2,Detalle!$E$2:$E$723,$A5) -> 0 | C5: =SUMIFS(Detalle!$F$2:$F$723,Detalle!$A$2:$A$723,C$2,Detalle!$E$2:$E$723,$A5) -> 4 | D5: =SUMIFS(Detalle!$F$2:$F$723,Detalle!$A$2:$A$723,D$2,Detalle!$E$2:$E$723,$A5) -> 4 | E5: =SUMIFS(Detalle!$F$2:$F$723,Detalle!$A$2:$A$723,E$2,Detalle!$E$2:$E$723,$A5) -> 4 | F5: =SUMIFS(Detalle!$F$2:$F$723,Detalle!$A$2:$A$723,F$2,Detalle!$E$2:$E$723,$A5) -> 4 | G5: =SUMIFS(Detalle!$F$2:$F$723,Detalle!$A$2:$A$723,G$2,Detalle!$E$2:$E$723,$A5) -> 4 | H5: =SUMIFS(Detalle!$F$2:$F$723,Detalle!$A$2:$A$723,H$2,Detalle!$E$2:$E$723,$A5) -> 4 | I5: =SUMIFS(Detalle!$F$2:$F$723,Detalle!$A$2:$A$723,I$2,Detalle!$E$2:$E$723,$A5) -> 4 | ... V5: =SUMIFS(Detalle!$F$2:$F$723,Detalle!$A$2:$A$723,V$2,Detalle!$E$2:$E$723,$A5) -> 0
A6: MATEMÁTICAS | B6: =SUMIFS(Detalle!$F$2:$F$723,Detalle!$A$2:$A$723,B$2,Detalle!$E$2:$E$723,$A6) -> 0 | C6: =SUMIFS(Detalle!$F$2:$F$723,Detalle!$A$2:$A$723,C$2,Detalle!$E$2:$E$723,$A6) -> 4 | D6: =SUMIFS(Detalle!$F$2:$F$723,Detalle!$A$2:$A$723,D$2,Detalle!$E$2:$E$723,$A6) -> 4 | E6: =SUMIFS(Detalle!$F$2:$F$723,Detalle!$A$2:$A$723,E$2,Detalle!$E$2:$E$723,$A6) -> 4 | F6: =SUMIFS(Detalle!$F$2:$F$723,Detalle!$A$2:$A$723,F$2,Detalle!$E$2:$E$723,$A6) -> 4 | G6: =SUMIFS(Detalle!$F$2:$F$723,Detalle!$A$2:$A$723,G$2,Detalle!$E$2:$E$723,$A6) -> 4 | H6: =SUMIFS(Detalle!$F$2:$F$723,Detalle!$A$2:$A$723,H$2,Detalle!$E$2:$E$723,$A6) -> 4 | I6: =SUMIFS(Detalle!$F$2:$F$723,Detalle!$A$2:$A$723,I$2,Detalle!$E$2:$E$723,$A6) -> 4 | ... V6: =SUMIFS(Detalle!$F$2:$F$723,Detalle!$A$2:$A$723,V$2,Detalle!$E$2:$E$723,$A6) -> 0
A7: ED. FÍSICA | B7: =SUMIFS(Detalle!$F$2:$F$723,Detalle!$A$2:$A$723,B$2,Detalle!$E$2:$E$723,$A7) -> 1 | C7: =SUMIFS(Detalle!$F$2:$F$723,Detalle!$A$2:$A$723,C$2,Detalle!$E$2:$E$723,$A7) -> 2 | D7: =SUMIFS(Detalle!$F$2:$F$723,Detalle!$A$2:$A$723,D$2,Detalle!$E$2:$E$723,$A7) -> 2 | E7: =SUMIFS(Detalle!$F$2:$F$723,Detalle!$A$2:$A$723,E$2,Detalle!$E$2:$E$723,$A7) -> 2 | F7: =SUMIFS(Detalle!$F$2:$F$723,Detalle!$A$2:$A$723,F$2,Detalle!$E$2:$E$723,$A7) -> 3 | G7: =SUMIFS(Detalle!$F$2:$F$723,Detalle!$A$2:$A$723,G$2,Detalle!$E$2:$E$723,$A7) -> 2 | H7: =SUMIFS(Detalle!$F$2:$F$723,Detalle!$A$2:$A$723,H$2,Detalle!$E$2:$E$723,$A7) -> 2 | I7: =SUMIFS(Detalle!$F$2:$F$723,Detalle!$A$2:$A$723,I$2,Detalle!$E$2:$E$723,$A7) -> 2 | ... V7: =SUMIFS(Detalle!$F$2:$F$723,Detalle!$A$2:$A$723,V$2,Detalle!$E$2:$E$723,$A7) -> 0
A8: ERE | B8: =SUMIFS(Detalle!$F$2:$F$723,Detalle!$A$2:$A$723,B$2,Detalle!$E$2:$E$723,$A8) -> 2 | C8: =SUMIFS(Detalle!$F$2:$F$723,Detalle!$A$2:$A$723,C$2,Detalle!$E$2:$E$723,$A8) -> 2 | D8: =SUMIFS(Detalle!$F$2:$F$723,Detalle!$A$2:$A$723,D$2,Detalle!$E$2:$E$723,$A8) -> 2 | E8: =SUMIFS(Detalle!$F$2:$F$723,Detalle!$A$2:$A$723,E$2,Detalle!$E$2:$E$723,$A8) -> 2 | F8: =SUMIFS(Detalle!$F$2:$F$723,Detalle!$A$2:$A$723,F$2,Detalle!$E$2:$E$723,$A8) -> 2 | G8: =SUMIFS(Detalle!$F$2:$F$723,Detalle!$A$2:$A$723,G$2,Detalle!$E$2:$E$723,$A8) -> 2 | H8: =SUMIFS(Detalle!$F$2:$F$723,Detalle!$A$2:$A$723,H$2,Detalle!$E$2:$E$723,$A8) -> 2 | I8: =SUMIFS(Detalle!$F$2:$F$723,Detalle!$A$2:$A$723,I$2,Detalle!$E$2:$E$723,$A8) -> 2 | ... V8: =SUMIFS(Detalle!$F$2:$F$723,Detalle!$A$2:$A$723,V$2,Detalle!$E$2:$E$723,$A8) -> 0
A9: INFORMÁTICA | B9: =SUMIFS(Detalle!$F$2:$F$723,Detalle!$A$2:$A$723,B$2,Detalle!$E$2:$E$723,$A9) -> 2 | C9: =SUMIFS(Detalle!$F$2:$F$723,Detalle!$A$2:$A$723,C$2,Detalle!$E$2:$E$723,$A9) -> 2 | D9: =SUMIFS(Detalle!$F$2:$F$723,Detalle!$A$2:$A$723,D$2,Detalle!$E$2:$E$723,$A9) -> 2 | E9: =SUMIFS(Detalle!$F$2:$F$723,Detalle!$A$2:$A$723,E$2,Detalle!$E$2:$E$723,$A9) -> 2 | F9: =SUMIFS(Detalle!$F$2:$F$723,Detalle!$A$2:$A$723,F$2,Detalle!$E$2:$E$723,$A9) -> 2 | G9: =SUMIFS(Detalle!$F$2:$F$723,Detalle!$A$2:$A$723,G$2,Detalle!$E$2:$E$723,$A9) -> 2 | H9: =SUMIFS(Detalle!$F$2:$F$723,Detalle!$A$2:$A$723,H$2,Detalle!$E$2:$E$723,$A9) -> 2 | I9: =SUMIFS(Detalle!$F$2:$F$723,Detalle!$A$2:$A$723,I$2,Detalle!$E$2:$E$723,$A9) -> 2 | ... V9: =SUMIFS(Detalle!$F$2:$F$723,Detalle!$A$2:$A$723,V$2,Detalle!$E$2:$E$723,$A9) -> 0
A10: C. SOCIALES | B10: =SUMIFS(Detalle!$F$2:$F$723,Detalle!$A$2:$A$723,B$2,Detalle!$E$2:$E$723,$A10) -> 0 | C10: =SUMIFS(Detalle!$F$2:$F$723,Detalle!$A$2:$A$723,C$2,Detalle!$E$2:$E$723,$A10) -> 4 | D10: =SUMIFS(Detalle!$F$2:$F$723,Detalle!$A$2:$A$723,D$2,Detalle!$E$2:$E$723,$A10) -> 4 | E10: =SUMIFS(Detalle!$F$2:$F$723,Detalle!$A$2:$A$723,E$2,Detalle!$E$2:$E$723,$A10) -> 4 | F10: =SUMIFS(Detalle!$F$2:$F$723,Detalle!$A$2:$A$723,F$2,Detalle!$E$2:$E$723,$A10) -> 4 | G10: =SUMIFS(Detalle!$F$2:$F$723,Detalle!$A$2:$A$723,G$2,Detalle!$E$2:$E$723,$A10) -> 4 | H10: =SUMIFS(Detalle!$F$2:$F$723,Detalle!$A$2:$A$723,H$2,Detalle!$E$2:$E$723,$A10) -> 4 | I10: =SUMIFS(Detalle!$F$2:$F$723,Detalle!$A$2:$A$723,I$2,Detalle!$E$2:$E$723,$A10) -> 4 | ... V10: =SUMIFS(Detalle!$F$2:$F$723,Detalle!$A$2:$A$723,V$2,Detalle!$E$2:$E$723,$A10) -> 0
A11: EUCARISTÍA | B11: =SUMIFS(Detalle!$F$2:$F$723,Detalle!$A$2:$A$723,B$2,Detalle!$E$2:$E$723,$A11) -> 1 | C11: =SUMIFS(Detalle!$F$2:$F$723,Detalle!$A$2:$A$723,C$2,Detalle!$E$2:$E$723,$A11) -> 1 | D11: =SUMIFS(Detalle!$F$2:$F$723,Detalle!$A$2:$A$723,D$2,Detalle!$E$2:$E$723,$A11) -> 1 | E11: =SUMIFS(Detalle!$F$2:$F$723,Detalle!$A$2:$A$723,E$2,Detalle!$E$2:$E$723,$A11) -> 1 | F11: =SUMIFS(Detalle!$F$2:$F$723,Detalle!$A$2:$A$723,F$2,Detalle!$E$2:$E$723,$A11) -> 1 | G11: =SUMIFS(Detalle!$F$2:$F$723,Detalle!$A$2:$A$723,G$2,Detalle!$E$2:$E$723,$A11) -> 1 | H11: =SUMIFS(Detalle!$F$2:$F$723,Detalle!$A$2:$A$723,H$2,Detalle!$E$2:$E$723,$A11) -> 1 | I11: =SUMIFS(Detalle!$F$2:$F$723,Detalle!$A$2:$A$723,I$2,Detalle!$E$2:$E$723,$A11) -> 1 | ... V11: =SUMIFS(Detalle!$F$2:$F$723,Detalle!$A$2:$A$723,V$2,Detalle!$E$2:$E$723,$A11) -> 1
A12: DANZAS | B12: =SUMIFS(Detalle!$F$2:$F$723,Detalle!$A$2:$A$723,B$2,Detalle!$E$2:$E$723,$A12) -> 1 | C12: =SUMIFS(Detalle!$F$2:$F$723,Detalle!$A$2:$A$723,C$2,Detalle!$E$2:$E$723,$A12) -> 1 | D12: =SUMIFS(Detalle!$F$2:$F$723,Detalle!$A$2:$A$723,D$2,Detalle!$E$2:$E$723,$A12) -> 1 | E12: =SUMIFS(Detalle!$F$2:$F$723,Detalle!$A$2:$A$723,E$2,Detalle!$E$2:$E$723,$A12) -> 1 | F12: =SUMIFS(Detalle!$F$2:$F$723,Detalle!$A$2:$A$723,F$2,Detalle!$E$2:$E$723,$A12) -> 1 | G12: =SUMIFS(Detalle!$F$2:$F$723,Detalle!$A$2:$A$723,G$2,Detalle!$E$2:$E$723,$A12) -> 1 | H12: =SUMIFS(Detalle!$F$2:$F$723,Detalle!$A$2:$A$723,H$2,Detalle!$E$2:$E$723,$A12) -> 1 | I12: =SUMIFS(Detalle!$F$2:$F$723,Detalle!$A$2:$A$723,I$2,Detalle!$E$2:$E$723,$A12) -> 1 | ... V12: =SUMIFS(Detalle!$F$2:$F$723,Detalle!$A$2:$A$723,V$2,Detalle!$E$2:$E$723,$A12) -> 0
A13: GEOGRAFÍA | B13: =SUMIFS(Detalle!$F$2:$F$723,Detalle!$A$2:$A$723,B$2,Detalle!$E$2:$E$723,$A13) -> 0 | C13: =SUMIFS(Detalle!$F$2:$F$723,Detalle!$A$2:$A$723,C$2,Detalle!$E$2:$E$723,$A13) -> 0 | D13: =SUMIFS(Detalle!$F$2:$F$723,Detalle!$A$2:$A$723,D$2,Detalle!$E$2:$E$723,$A13) -> 0 | E13: =SUMIFS(Detalle!$F$2:$F$723,Detalle!$A$2:$A$723,E$2,Detalle!$E$2:$E$723,$A13) -> 0 | F13: =SUMIFS(Detalle!$F$2:$F$723,Detalle!$A$2:$A$723,F$2,Detalle!$E$2:$E$723,$A13) -> 0 | G13: =SUMIFS(Detalle!$F$2:$F$723,Detalle!$A$2:$A$723,G$2,Detalle!$E$2:$E$723,$A13) -> 0 | H13: =SUMIFS(Detalle!$F$2:$F$723,Detalle!$A$2:$A$723,H$2,Detalle!$E$2:$E$723,$A13) -> 0 | I13: =SUMIFS(Detalle!$F$2:$F$723,Detalle!$A$2:$A$723,I$2,Detalle!$E$2:$E$723,$A13) -> 0 | ... V13: =SUMIFS(Detalle!$F$2:$F$723,Detalle!$A$2:$A$723,V$2,Detalle!$E$2:$E$723,$A13) -> 0
A14: HISTORIA | B14: =SUMIFS(Detalle!$F$2:$F$723,Detalle!$A$2:$A$723,B$2,Detalle!$E$2:$E$723,$A14) -> 0 | C14: =SUMIFS(Detalle!$F$2:$F$723,Detalle!$A$2:$A$723,C$2,Detalle!$E$2:$E$723,$A14) -> 0 | D14: =SUMIFS(Detalle!$F$2:$F$723,Detalle!$A$2:$A$723,D$2,Detalle!$E$2:$E$723,$A14) -> 0 | E14: =SUMIFS(Detalle!$F$2:$F$723,Detalle!$A$2:$A$723,E$2,Detalle!$E$2:$E$723,$A14) -> 0 | F14: =SUMIFS(Detalle!$F$2:$F$723,Detalle!$A$2:$A$723,F$2,Detalle!$E$2:$E$723,$A14) -> 0 | G14: =SUMIFS(Detalle!$F$2:$F$723,Detalle!$A$2:$A$723,G$2,Detalle!$E$2:$E$723,$A14) -> 0 | H14: =SUMIFS(Detalle!$F$2:$F$723,Detalle!$A$2:$A$723,H$2,Detalle!$E$2:$E$723,$A14) -> 0 | I14: =SUMIFS(Detalle!$F$2:$F$723,Detalle!$A$2:$A$723,I$2,Detalle!$E$2:$E$723,$A14) -> 0 | ... V14: =SUMIFS(Detalle!$F$2:$F$723,Detalle!$A$2:$A$723,V$2,Detalle!$E$2:$E$723,$A14) -> 0
... A50: SIN IDENTIFICAR | B50: =SUMIFS(Detalle!$F$2:$F$723,Detalle!$A$2:$A$723,B$2,Detalle!$E$2:$E$723,$A50) -> 0 | C50: =SUMIFS(Detalle!$F$2:$F$723,Detalle!$A$2:$A$723,C$2,Detalle!$E$2:$E$723,$A50) -> 0 | D50: =SUMIFS(Detalle!$F$2:$F$723,Detalle!$A$2:$A$723,D$2,Detalle!$E$2:$E$723,$A50) -> 0 | E50: =SUMIFS(Detalle!$F$2:$F$723,Detalle!$A$2:$A$723,E$2,Detalle!$E$2:$E$723,$A50) -> 0 | F50: =SUMIFS(Detalle!$F$2:$F$723,Detalle!$A$2:$A$723,F$2,Detalle!$E$2:$E$723,$A50) -> 0 | G50: =SUMIFS(Detalle!$F$2:$F$723,Detalle!$A$2:$A$723,G$2,Detalle!$E$2:$E$723,$A50) -> 0 | H50: =SUMIFS(Detalle!$F$2:$F$723,Detalle!$A$2:$A$723,H$2,Detalle!$E$2:$E$723,$A50) -> 0 | I50: =SUMIFS(Detalle!$F$2:$F$723,Detalle!$A$2:$A$723,I$2,Detalle!$E$2:$E$723,$A50) -> 0 | ... V50: =SUMIFS(Detalle!$F$2:$F$723,Detalle!$A$2:$A$723,V$2,Detalle!$E$2:$E$723,$A50) -> 0

Sheet Detalle
A1: Curso | B1: Día | C1: Periodo | D1: Horario | E1: Materia normalizada | F1: Horas | G1: Fila origen | H1: Texto original
A2: TA | B2: LUNES | C2: 1 | D2: 6:50 - 7:50 | E2: D. COGNITIVA | F2: 1 | G2: 5 | H2: D. COGNITIVA
A3: TA | B3: LUNES | C3: 2 | D3: 7:50 – 8:50 | E3: D. COGNITIVA | F3: 1 | G3: 6 | H3: D. COGNITIVA
A4: TA | B4: LUNES | C4: 3 | D4: 9:20 - 10:20 | E4: D.SOCIOAFECTIVA | F4: 1 | G4: 8 | H4: D.SOCIOAFECTIVA
A5: TA | B5: LUNES | C5: 4 | D5: 10:20 – 11:20 | E5: D.SOCIOAFECTIVA | F5: 1 | G5: 9 | H5: D.SOCIOAFECTIVA
A6: TA | B6: LUNES | C6: 5 | D6: 11:20 – 12:20 | E6: ED. FÍSICA | F6: 1 | G6: 10 | H6: EDU. FÍSICA
A7: TA | B7: LUNES | C7: 6 | D7: 1:00 – 2:00 | E7: D. ESTÉTICA | F7: 1 | G7: 12 | H7: D. ESTÉTICA
A8: TA | B8: LUNES | C8: 7 | D8: 2:00 – 3:00 | E8: D. ESTÉTICA | F8: 1 | G8: 13 | H8: D. ESTÉTICA
A9: TA | B9: MARTES | C9: 1 | D9: 6:50 - 7:50 | E9: D. COMUNICATIVA | F9: 1 | G9: 5 | H9: D. COMUNICATIVA
A10: TA | B10: MARTES | C10: 2 | D10: 7:50 – 8:50 | E10: D. COMUNICATIVA | F10: 1 | G10: 6 | H10: D. COMUNICATIVA
A11: TA | B11: MARTES | C11: 3 | D11: 9:20 - 10:20 | E11: INGLÉS | F11: 1 | G11: 8 | H11: INGLÉS
A12: TA | B12: MARTES | C12: 4 | D12: 10:20 – 11:20 | E12: PROCESOS | F12: 1 | G12: 9 | H12: PROCESOS
A13: TA | B13: MARTES | C13: 5 | D13: 11:20 – 12:20 | E13: INFANCIA MISIONERA | F13: 1 | G13: 10 | H13: INFANCIA MISIONERA
... A723: IV SEMESTRE | B723: VIERNES | C723: 7 | D723: 2:00 – 3:00 | E723: SOCIOLOGÍA EDUCATIVA | F723: 1 | G723: 284 | H723: SOCIOLOGÍA EDUCATIVA

Sheet Observaciones
A1: OBSERVACIONES Y CRITERIOS DE CONSOLIDACIÓN
A3: Curso | B3: Fila origen | C3: Tipo de revisión | D3: Dato encontrado | E3: Día
A4: 2A | B4: 52 | C4: Contenido en fila almuerzo | D4: INGLÉS | E4: LUNES
A5: 8° | B5: 230 | C5: Materia no identificada | D5: } | E5: MIÉRCOLES
A8: Materia normalizada | B8: Variantes encontradas | C8: Criterio
A9: L. CASTELLANA | B9: L .CASTELLANA, L, CASTELLANA, L. CASTELLAMA, L. CASTELLANA, L. CASTELLNA, LENGUA CASTELLANA | C9: Se unificaron diferencias evidentes de acento, singular/plural, abreviación o digitación.
A10: C. NATURALES | B10: C. NATIRALES, C. NATURAL, C. NATURALES, C. NATUURALES, CIENCIAS | C10: Se unificaron diferencias evidentes de acento, singular/plural, abreviación o digitación.
A11: MATEMÁTICAS | B11: MATEMÁTICA, MATEMÁTICAS | C11: Se unificaron diferencias evidentes de acento, singular/plural, abreviación o digitación.
A12: ED. FÍSICA | B12: ED. FISICA, ED. FÍSICA, EDU. FÍSICA | C12: Se unificaron diferencias evidentes de acento, singular/plural, abreviación o digitación.
A13: ERE | B13: E.R.E, ERE | C13: Se unificaron diferencias evidentes de acento, singular/plural, abreviación o digitación.
A14: INFORMÁTICA | B14: INFORMATICA, INFORMÁTICA, INFORMÁTICAS | C14: Se unificaron diferencias evidentes de acento, singular/plural, abreviación o digitación.
A15: C. SOCIALES | B15: C. SOCIALES, C.SOCIALES | C15: Se unificaron diferencias evidentes de acento, singular/plural, abreviación o digitación.
A16: EUCARISTÍA | B16: EUCARISTIA, EUCARISTÍA | C16: Se unificaron diferencias evidentes de acento, singular/plural, abreviación o digitación.
A17: GEOGRAFÍA | B17: GEOGRAFIA, GEOGRAFÍA, GEOGRAFÍÁ, GEOGRÁFIA | C17: Se unificaron diferencias evidentes de acento, singular/plural, abreviación o digitación.
A18: ED. SOCIOEMOCIONAL | B18: ED SOCIOEMOCIONAL, ED. SOCIOEMOCIONAL | C18: Se unificaron diferencias evidentes de acento, singular/plural, abreviación o digitación.
A19: ÉTICA | B19: ETICA, ÉTICA | C19: Se unificaron diferencias evidentes de acento, singular/plural, abreviación o digitación.
... A21: SIN IDENTIFICAR | B21: } | C21: Se unificaron diferencias evidentes de acento, singular/plural, abreviación o digitación.
A24: Criterios aplicados
A25: 1. Se contabilizaron únicamente filas de periodos numerados; descanso y almuerzo no suman horas.
A26: 2. La duración se obtuvo del rango horario de cada periodo. En los horarios registrados, los periodos académicos contabilizados son de 1 hora.
A27: 3. Actividades institucionales programadas dentro de periodos (p. ej., Eucaristía, Semillero, Asesoría) se conservan como materias/actividades para reflejar la carga real del horario.
A28: 4. No se reasignó la celda no identificada de 8°; se reporta como SIN IDENTIFICAR hasta que sea validada.

Sheet Curso TA
A1: CURSO TA – HORAS SEMANALES POR MATERIA
A2: Total horas semanales | B2: =SUMIFS(Detalle!$F$2:$F$723,Detalle!$A$2:$A$723,"TA") -> 35
A3: Materia / actividad | B3: Horas semanales | C3: % del horario
A4: D. COMUNICATIVA | B4: =SUMIFS(Detalle!$F$2:$F$723,Detalle!$A$2:$A$723,"TA",Detalle!$E$2:$E$723,A4) -> 7 | C4: =IF($B$2=0,0,B4/$B$2) -> 0.2
A5: D. COGNITIVA | B5: =SUMIFS(Detalle!$F$2:$F$723,Detalle!$A$2:$A$723,"TA",Detalle!$E$2:$E$723,A5) -> 6 | C5: =IF($B$2=0,0,B5/$B$2) -> 0.17142857
A6: D.SOCIOAFECTIVA | B6: =SUMIFS(Detalle!$F$2:$F$723,Detalle!$A$2:$A$723,"TA",Detalle!$E$2:$E$723,A6) -> 5 | C6: =IF($B$2=0,0,B6/$B$2) -> 0.14285714
A7: INGLÉS | B7: =SUMIFS(Detalle!$F$2:$F$723,Detalle!$A$2:$A$723,"TA",Detalle!$E$2:$E$723,A7) -> 3 | C7: =IF($B$2=0,0,B7/$B$2) -> 0.085714286
A8: D. ESTÉTICA | B8: =SUMIFS(Detalle!$F$2:$F$723,Detalle!$A$2:$A$723,"TA",Detalle!$E$2:$E$723,A8) -> 2 | C8: =IF($B$2=0,0,B8/$B$2) -> 0.057142857
A9: ERE | B9: =SUMIFS(Detalle!$F$2:$F$723,Detalle!$A$2:$A$723,"TA",Detalle!$E$2:$E$723,A9) -> 2 | C9: =IF($B$2=0,0,B9/$B$2) -> 0.057142857
A10: INFORMÁTICA | B10: =SUMIFS(Detalle!$F$2:$F$723,Detalle!$A$2:$A$723,"TA",Detalle!$E$2:$E$723,A10) -> 2 | C10: =IF($B$2=0,0,B10/$B$2) -> 0.057142857
A11: D. ÉTICA | B11: =SUMIFS(Detalle!$F$2:$F$723,Detalle!$A$2:$A$723,"TA",Detalle!$E$2:$E$723,A11) -> 1 | C11: =IF($B$2=0,0,B11/$B$2) -> 0.028571429
A12: DANZAS | B12: =SUMIFS(Detalle!$F$2:$F$723,Detalle!$A$2:$A$723,"TA",Detalle!$E$2:$E$723,A12) -> 1 | C12: =IF($B$2=0,0,B12/$B$2) -> 0.028571429
A13: ED. FÍSICA | B13: =SUMIFS(Detalle!$F$2:$F$723,Detalle!$A$2:$A$723,"TA",Detalle!$E$2:$E$723,A13) -> 1 | C13: =IF($B$2=0,0,B13/$B$2) -> 0.028571429
A14: ED. SOCIOEMOCIONAL | B14: =SUMIFS(Detalle!$F$2:$F$723,Detalle!$A$2:$A$723,"TA",Detalle!$E$2:$E$723,A14) -> 1 | C14: =IF($B$2=0,0,B14/$B$2) -> 0.028571429
A15: EUCARISTÍA | B15: =SUMIFS(Detalle!$F$2:$F$723,Detalle!$A$2:$A$723,"TA",Detalle!$E$2:$E$723,A15) -> 1 | C15: =IF($B$2=0,0,B15/$B$2) -> 0.028571429
... A18: PROCESOS | B18: =SUMIFS(Detalle!$F$2:$F$723,Detalle!$A$2:$A$723,"TA",Detalle!$E$2:$E$723,A18) -> 1 | C18: =IF($B$2=0,0,B18/$B$2) -> 0.028571429
A19: TOTAL | B19: =SUM(B4:B18) -> 35 | C19: =SUM(C4:C18) -> 1

Sheet Curso 1A
A1: CURSO 1A – HORAS SEMANALES POR MATERIA
A2: Total horas semanales | B2: =SUMIFS(Detalle!$F$2:$F$723,Detalle!$A$2:$A$723,"1A") -> 35
A4: Materia / actividad | B4: Horas semanales | C4: % del horario
A5: L. CASTELLANA | B5: =SUMIFS(Detalle!$F$2:$F$723,Detalle!$A$2:$A$723,"1A",Detalle!$E$2:$E$723,A5) -> 5 | C5: =IF($B$2=0,0,B5/$B$2) -> 0.14285714
A6: C. NATURALES | B6: =SUMIFS(Detalle!$F$2:$F$723,Detalle!$A$2:$A$723,"1A",Detalle!$E$2:$E$723,A6) -> 4 | C6: =IF($B$2=0,0,B6/$B$2) -> 0.11428571
A7: C. SOCIALES | B7: =SUMIFS(Detalle!$F$2:$F$723,Detalle!$A$2:$A$723,"1A",Detalle!$E$2:$E$723,A7) -> 4 | C7: =IF($B$2=0,0,B7/$B$2) -> 0.11428571
A8: INGLÉS | B8: =SUMIFS(Detalle!$F$2:$F$723,Detalle!$A$2:$A$723,"1A",Detalle!$E$2:$E$723,A8) -> 4 | C8: =IF($B$2=0,0,B8/$B$2) -> 0.11428571
A9: MATEMÁTICAS | B9: =SUMIFS(Detalle!$F$2:$F$723,Detalle!$A$2:$A$723,"1A",Detalle!$E$2:$E$723,A9) -> 4 | C9: =IF($B$2=0,0,B9/$B$2) -> 0.11428571
A10: ED. FÍSICA | B10: =SUMIFS(Detalle!$F$2:$F$723,Detalle!$A$2:$A$723,"1A",Detalle!$E$2:$E$723,A10) -> 2 | C10: =IF($B$2=0,0,B10/$B$2) -> 0.057142857
A11: ERE | B11: =SUMIFS(Detalle!$F$2:$F$723,Detalle!$A$2:$A$723,"1A",Detalle!$E$2:$E$723,A11) -> 2 | C11: =IF($B$2=0,0,B11/$B$2) -> 0.057142857
A12: INFORMÁTICA | B12: =SUMIFS(Detalle!$F$2:$F$723,Detalle!$A$2:$A$723,"1A",Detalle!$E$2:$E$723,A12) -> 2 | C12: =IF($B$2=0,0,B12/$B$2) -> 0.057142857
A13: ARTES | B13: =SUMIFS(Detalle!$F$2:$F$723,Detalle!$A$2:$A$723,"1A",Detalle!$E$2:$E$723,A13) -> 1 | C13: =IF($B$2=0,0,B13/$B$2) -> 0.028571429
A14: DANZAS | B14: =SUMIFS(Detalle!$F$2:$F$723,Detalle!$A$2:$A$723,"1A",Detalle!$E$2:$E$723,A14) -> 1 | C14: =IF($B$2=0,0,B14/$B$2) -> 0.028571429
A15: ED. SOCIOEMOCIONAL | B15: =SUMIFS(Detalle!$F$2:$F$723,Detalle!$A$2:$A$723,"1A",Detalle!$E$2:$E$723,A15) -> 1 | C15: =IF($B$2=0,0,B15/$B$2) -> 0.028571429
A16: EUCARISTÍA | B16: =SUMIFS(Detalle!$F$2:$F$723,Detalle!$A$2:$A$723,"1A",Detalle!$E$2:$E$723,A16) -> 1 | C16: =IF($B$2=0,0,B16/$B$2) -> 0.028571429
... A20: ÉTICA | B20: =SUMIFS(Detalle!$F$2:$F$723,Detalle!$A$2:$A$723,"1A",Detalle!$E$2:$E$723,A20) -> 1 | C20: =IF($B$2=0,0,B20/$B$2) -> 0.028571429
A21: TOTAL | B21: =SUM(B5:B20) -> 35 | C21: =SUM(C5:C20) -> 1

Sheet Curso 1B
A1: CURSO 1B – HORAS SEMANALES POR MATERIA
A2: Total horas semanales | B2: =SUMIFS(Detalle!$F$2:$F$723,Detalle!$A$2:$A$723,"1B") -> 35
A4: Materia / actividad | B4: Horas semanales | C4: % del horario
A5: L. CASTELLANA | B5: =SUMIFS(Detalle!$F$2:$F$723,Detalle!$A$2:$A$723,"1B",Detalle!$E$2:$E$723,A5) -> 5 | C5: =IF($B$2=0,0,B5/$B$2) -> 0.14285714
A6: C. NATURALES | B6: =SUMIFS(Detalle!$F$2:$F$723,Detalle!$A$2:$A$723,"1B",Detalle!$E$2:$E$723,A6) -> 4 | C6: =IF($B$2=0,0,B6/$B$2) -> 0.11428571
A7: C. SOCIALES | B7: =SUMIFS(Detalle!$F$2:$F$723,Detalle!$A$2:$A$723,"1B",Detalle!$E$2:$E$723,A7) -> 4 | C7: =IF($B$2=0,0,B7/$B$2) -> 0.11428571
A8: INGLÉS | B8: =SUMIFS(Detalle!$F$2:$F$723,Detalle!$A$2:$A$723,"1B",Detalle!$E$2:$E$723,A8) -> 4 | C8: =IF($B$2=0,0,B8/$B$2) -> 0.11428571
A9: MATEMÁTICAS | B9: =SUMIFS(Detalle!$F$2:$F$723,Detalle!$A$2:$A$723,"1B",Detalle!$E$2:$E$723,A9) -> 4 | C9: =IF($B$2=0,0,B9/$B$2) -> 0.11428571
A10: ED. FÍSICA | B10: =SUMIFS(Detalle!$F$2:$F$723,Detalle!$A$2:$A$723,"1B",Detalle!$E$2:$E$723,A10) -> 2 | C10: =IF($B$2=0,0,B10/$B$2) -> 0.057142857
A11: ERE | B11: =SUMIFS(Detalle!$F$2:$F$723,Detalle!$A$2:$A$723,"1B",Detalle!$E$2:$E$723,A11) -> 2 | C11: =IF($B$2=0,0,B11/$B$2) -> 0.057142857
A12: INFORMÁTICA | B12: =SUMIFS(Detalle!$F$2:$F$723,Detalle!$A$2:$A$723,"1B",Detalle!$E$2:$E$723,A12) -> 2 | C12: =IF($B$2=0,0,B12/$B$2) -> 0.057142857
A13: ARTES | B13: =SUMIFS(Detalle!$F$2:$F$723,Detalle!$A$2:$A$723,"1B",Detalle!$E$2:$E$723,A13) -> 1 | C13: =IF($B$2=0,0,B13/$B$2) -> 0.028571429
A14: DANZAS | B14: =SUMIFS(Detalle!$F$2:$F$723,Detalle!$A$2:$A$723,"1B",Detalle!$E$2:$E$723,A14) -> 1 | C14: =IF($B$2=0,0,B14/$B$2) -> 0.028571429
A15: ED. SOCIOEMOCIONAL | B15: =SUMIFS(Detalle!$F$2:$F$723,Detalle!$A$2:$A$723,"1B",Detalle!$E$2:$E$723,A15) -> 1 | C15: =IF($B$2=0,0,B15/$B$2) -> 0.028571429
A16: EUCARISTÍA | B16: =SUMIFS(Detalle!$F$2:$F$723,Detalle!$A$2:$A$723,"1B",Detalle!$E$2:$E$723,A16) -> 1 | C16: =IF($B$2=0,0,B16/$B$2) -> 0.028571429
... A20: ÉTICA | B20: =SUMIFS(Detalle!$F$2:$F$723,Detalle!$A$2:$A$723,"1B",Detalle!$E$2:$E$723,A20) -> 1 | C20: =IF($B$2=0,0,B20/$B$2) -> 0.028571429
A21: TOTAL | B21: =SUM(B5:B20) -> 35 | C21: =SUM(C5:C20) -> 1

Sheet Curso 2A
A1: CURSO 2A – HORAS SEMANALES POR MATERIA
A2: Total horas semanales | B2: =SUMIFS(Detalle!$F$2:$F$723,Detalle!$A$2:$A$723,"2A") -> 35
A4: Materia / actividad | B4: Horas semanales | C4: % del horario
A5: L. CASTELLANA | B5: =SUMIFS(Detalle!$F$2:$F$723,Detalle!$A$2:$A$723,"2A",Detalle!$E$2:$E$723,A5) -> 5 | C5: =IF($B$2=0,0,B5/$B$2) -> 0.14285714
A6: C. NATURALES | B6: =SUMIFS(Detalle!$F$2:$F$723,Detalle!$A$2:$A$723,"2A",Detalle!$E$2:$E$723,A6) -> 4 | C6: =IF($B$2=0,0,B6/$B$2) -> 0.11428571
A7: C. SOCIALES | B7: =SUMIFS(Detalle!$F$2:$F$723,Detalle!$A$2:$A$723,"2A",Detalle!$E$2:$E$723,A7) -> 4 | C7: =IF($B$2=0,0,B7/$B$2) -> 0.11428571
A8: INGLÉS | B8: =SUMIFS(Detalle!$F$2:$F$723,Detalle!$A$2:$A$723,"2A",Detalle!$E$2:$E$723,A8) -> 4 | C8: =IF($B$2=0,0,B8/$B$2) -> 0.11428571
A9: MATEMÁTICAS | B9: =SUMIFS(Detalle!$F$2:$F$723,Detalle!$A$2:$A$723,"2A",Detalle!$E$2:$E$723,A9) -> 4 | C9: =IF($B$2=0,0,B9/$B$2) -> 0.11428571
A10: ED. FÍSICA | B10: =SUMIFS(Detalle!$F$2:$F$723,Detalle!$A$2:$A$723,"2A",Detalle!$E$2:$E$723,A10) -> 2 | C10: =IF($B$2=0,0,B10/$B$2) -> 0.057142857
A11: ERE | B11: =SUMIFS(Detalle!$F$2:$F$723,Detalle!$A$2:$A$723,"2A",Detalle!$E$2:$E$723,A11) -> 2 | C11: =IF($B$2=0,0,B11/$B$2) -> 0.057142857
A12: INFORMÁTICA | B12: =SUMIFS(Detalle!$F$2:$F$723,Detalle!$A$2:$A$723,"2A",Detalle!$E$2:$E$723,A12) -> 2 | C12: =IF($B$2=0,0,B12/$B$2) -> 0.057142857
A13: ARTES | B13: =SUMIFS(Detalle!$F$2:$F$723,Detalle!$A$2:$A$723,"2A",Detalle!$E$2:$E$723,A13) -> 1 | C13: =IF($B$2=0,0,B13/$B$2) -> 0.028571429
A14: DANZAS | B14: =SUMIFS(Detalle!$F$2:$F$723,Detalle!$A$2:$A$723,"2A",Detalle!$E$2:$E$723,A14) -> 1 | C14: =IF($B$2=0,0,B14/$B$2) -> 0.028571429
A15: ED. SOCIOEMOCIONAL | B15: =SUMIFS(Detalle!$F$2:$F$723,Detalle!$A$2:$A$723,"2A",Detalle!$E$2:$E$723,A15) -> 1 | C15: =IF($B$2=0,0,B15/$B$2) -> 0.028571429
A16: EUCARISTÍA | B16: =SUMIFS(Detalle!$F$2:$F$723,Detalle!$A$2:$A$723,"2A",Detalle!$E$2:$E$723,A16) -> 1 | C16: =IF($B$2=0,0,B16/$B$2) -> 0.028571429
... A20: ÉTICA | B20: =SUMIFS(Detalle!$F$2:$F$723,Detalle!$A$2:$A$723,"2A",Detalle!$E$2:$E$723,A20) -> 1 | C20: =IF($B$2=0,0,B20/$B$2) -> 0.028571429
A21: TOTAL | B21: =SUM(B5:B20) -> 35 | C21: =SUM(C5:C20) -> 1

Sheet Curso 2B
A1: CURSO 2B – HORAS SEMANALES POR MATERIA
A2: Total horas semanales | B2: =SUMIFS(Detalle!$F$2:$F$723,Detalle!$A$2:$A$723,"2B") -> 35
A4: Materia / actividad | B4: Horas semanales | C4: % del horario
A5: L. CASTELLANA | B5: =SUMIFS(Detalle!$F$2:$F$723,Detalle!$A$2:$A$723,"2B",Detalle!$E$2:$E$723,A5) -> 5 | C5: =IF($B$2=0,0,B5/$B$2) -> 0.14285714
A6: C. NATURALES | B6: =SUMIFS(Detalle!$F$2:$F$723,Detalle!$A$2:$A$723,"2B",Detalle!$E$2:$E$723,A6) -> 4 | C6: =IF($B$2=0,0,B6/$B$2) -> 0.11428571
A7: C. SOCIALES | B7: =SUMIFS(Detalle!$F$2:$F$723,Detalle!$A$2:$A$723,"2B",Detalle!$E$2:$E$723,A7) -> 4 | C7: =IF($B$2=0,0,B7/$B$2) -> 0.11428571
A8: INGLÉS | B8: =SUMIFS(Detalle!$F$2:$F$723,Detalle!$A$2:$A$723,"2B",Detalle!$E$2:$E$723,A8) -> 4 | C8: =IF($B$2=0,0,B8/$B$2) -> 0.11428571
A9: MATEMÁTICAS | B9: =SUMIFS(Detalle!$F$2:$F$723,Detalle!$A$2:$A$723,"2B",Detalle!$E$2:$E$723,A9) -> 4 | C9: =IF($B$2=0,0,B9/$B$2) -> 0.11428571
A10: ED. FÍSICA | B10: =SUMIFS(Detalle!$F$2:$F$723,Detalle!$A$2:$A$723,"2B",Detalle!$E$2:$E$723,A10) -> 3 | C10: =IF($B$2=0,0,B10/$B$2) -> 0.085714286
A11: ERE | B11: =SUMIFS(Detalle!$F$2:$F$723,Detalle!$A$2:$A$723,"2B",Detalle!$E$2:$E$723,A11) -> 2 | C11: =IF($B$2=0,0,B11/$B$2) -> 0.057142857
A12: INFORMÁTICA | B12: =SUMIFS(Detalle!$F$2:$F$723,Detalle!$A$2:$A$723,"2B",Detalle!$E$2:$E$723,A12) -> 2 | C12: =IF($B$2=0,0,B12/$B$2) -> 0.057142857
A13: ARTES | B13: =SUMIFS(Detalle!$F$2:$F$723,Detalle!$A$2:$A$723,"2B",Detalle!$E$2:$E$723,A13) -> 1 | C13: =IF($B$2=0,0,B13/$B$2) -> 0.028571429
A14: DANZAS | B14: =SUMIFS(Detalle!$F$2:$F$723,Detalle!$A$2:$A$723,"2B",Detalle!$E$2:$E$723,A14) -> 1 | C14: =IF($B$2=0,0,B14/$B$2) -> 0.028571429
A15: EUCARISTÍA | B15: =SUMIFS(Detalle!$F$2:$F$723,Detalle!$A$2:$A$723,"2B",Detalle!$E$2:$E$723,A15) -> 1 | C15: =IF($B$2=0,0,B15/$B$2) -> 0.028571429
A16: INFANCIA MISIONERA | B16: =SUMIFS(Detalle!$F$2:$F$723,Detalle!$A$2:$A$723,"2B",Detalle!$E$2:$E$723,A16) -> 1 | C16: =IF($B$2=0,0,B16/$B$2) -> 0.028571429
... A19: ÉTICA | B19: =SUMIFS(Detalle!$F$2:$F$723,Detalle!$A$2:$A$723,"2B",Detalle!$E$2:$E$723,A19) -> 1 | C19: =IF($B$2=0,0,B19/$B$2) -> 0.028571429
A20: TOTAL | B20: =SUM(B5:B19) -> 35 | C20: =SUM(C5:C19) -> 1

Sheet Curso 3A
A1: CURSO 3A – HORAS SEMANALES POR MATERIA
A2: Total horas semanales | B2: =SUMIFS(Detalle!$F$2:$F$723,Detalle!$A$2:$A$723,"3A") -> 35
A4: Materia / actividad | B4: Horas semanales | C4: % del horario
A5: L. CASTELLANA | B5: =SUMIFS(Detalle!$F$2:$F$723,Detalle!$A$2:$A$723,"3A",Detalle!$E$2:$E$723,A5) -> 5 | C5: =IF($B$2=0,0,B5/$B$2) -> 0.14285714
A6: C. NATURALES | B6: =SUMIFS(Detalle!$F$2:$F$723,Detalle!$A$2:$A$723,"3A",Detalle!$E$2:$E$723,A6) -> 4 | C6: =IF($B$2=0,0,B6/$B$2) -> 0.11428571
A7: C. SOCIALES | B7: =SUMIFS(Detalle!$F$2:$F$723,Detalle!$A$2:$A$723,"3A",Detalle!$E$2:$E$723,A7) -> 4 | C7: =IF($B$2=0,0,B7/$B$2) -> 0.11428571
A8: INGLÉS | B8: =SUMIFS(Detalle!$F$2:$F$723,Detalle!$A$2:$A$723,"3A",Detalle!$E$2:$E$723,A8) -> 4 | C8: =IF($B$2=0,0,B8/$B$2) -> 0.11428571
A9: MATEMÁTICAS | B9: =SUMIFS(Detalle!$F$2:$F$723,Detalle!$A$2:$A$723,"3A",Detalle!$E$2:$E$723,A9) -> 4 | C9: =IF($B$2=0,0,B9/$B$2) -> 0.11428571
A10: ED. FÍSICA | B10: =SUMIFS(Detalle!$F$2:$F$723,Detalle!$A$2:$A$723,"3A",Detalle!$E$2:$E$723,A10) -> 2 | C10: =IF($B$2=0,0,B10/$B$2) -> 0.057142857
A11: ERE | B11: =SUMIFS(Detalle!$F$2:$F$723,Detalle!$A$2:$A$723,"3A",Detalle!$E$2:$E$723,A11) -> 2 | C11: =IF($B$2=0,0,B11/$B$2) -> 0.057142857
A12: INFORMÁTICA | B12: =SUMIFS(Detalle!$F$2:$F$723,Detalle!$A$2:$A$723,"3A",Detalle!$E$2:$E$723,A12) -> 2 | C12: =IF($B$2=0,0,B12/$B$2) -> 0.057142857
A13: ARTES | B13: =SUMIFS(Detalle!$F$2:$F$723,Detalle!$A$2:$A$723,"3A",Detalle!$E$2:$E$723,A13) -> 1 | C13: =IF($B$2=0,0,B13/$B$2) -> 0.028571429
A14: DANZAS | B14: =SUMIFS(Detalle!$F$2:$F$723,Detalle!$A$2:$A$723,"3A",Detalle!$E$2:$E$723,A14) -> 1 | C14: =IF($B$2=0,0,B14/$B$2) -> 0.028571429
A15: ED. SOCIOEMOCIONAL | B15: =SUMIFS(Detalle!$F$2:$F$723,Detalle!$A$2:$A$723,"3A",Detalle!$E$2:$E$723,A15) -> 1 | C15: =IF($B$2=0,0,B15/$B$2) -> 0.028571429
A16: EUCARISTÍA | B16: =SUMIFS(Detalle!$F$2:$F$723,Detalle!$A$2:$A$723,"3A",Detalle!$E$2:$E$723,A16) -> 1 | C16: =IF($B$2=0,0,B16/$B$2) -> 0.028571429
... A20: ÉTICA | B20: =SUMIFS(Detalle!$F$2:$F$723,Detalle!$A$2:$A$723,"3A",Detalle!$E$2:$E$723,A20) -> 1 | C20: =IF($B$2=0,0,B20/$B$2) -> 0.028571429
A21: TOTAL | B21: =SUM(B5:B20) -> 35 | C21: =SUM(C5:C20) -> 1

Sheet Curso 3B
A1: CURSO 3B – HORAS SEMANALES POR MATERIA
A2: Total horas semanales | B2: =SUMIFS(Detalle!$F$2:$F$723,Detalle!$A$2:$A$723,"3B") -> 35
A4: Materia / actividad | B4: Horas semanales | C4: % del horario
A5: L. CASTELLANA | B5: =SUMIFS(Detalle!$F$2:$F$723,Detalle!$A$2:$A$723,"3B",Detalle!$E$2:$E$723,A5) -> 5 | C5: =IF($B$2=0,0,B5/$B$2) -> 0.14285714
A6: C. NATURALES | B6: =SUMIFS(Detalle!$F$2:$F$723,Detalle!$A$2:$A$723,"3B",Detalle!$E$2:$E$723,A6) -> 4 | C6: =IF($B$2=0,0,B6/$B$2) -> 0.11428571
A7: C. SOCIALES | B7: =SUMIFS(Detalle!$F$2:$F$723,Detalle!$A$2:$A$723,"3B",Detalle!$E$2:$E$723,A7) -> 4 | C7: =IF($B$2=0,0,B7/$B$2) -> 0.11428571
A8: INGLÉS | B8: =SUMIFS(Detalle!$F$2:$F$723,Detalle!$A$2:$A$723,"3B",Detalle!$E$2:$E$723,A8) -> 4 | C8: =IF($B$2=0,0,B8/$B$2) -> 0.11428571
A9: MATEMÁTICAS | B9: =SUMIFS(Detalle!$F$2:$F$723,Detalle!$A$2:$A$723,"3B",Detalle!$E$2:$E$723,A9) -> 4 | C9: =IF($B$2=0,0,B9/$B$2) -> 0.11428571
A10: ED. FÍSICA | B10: =SUMIFS(Detalle!$F$2:$F$723,Detalle!$A$2:$A$723,"3B",Detalle!$E$2:$E$723,A10) -> 2 | C10: =IF($B$2=0,0,B10/$B$2) -> 0.057142857
A11: ERE | B11: =SUMIFS(Detalle!$F$2:$F$723,Detalle!$A$2:$A$723,"3B",Detalle!$E$2:$E$723,A11) -> 2 | C11: =IF($B$2=0,0,B11/$B$2) -> 0.057142857
A12: INFORMÁTICA | B12: =SUMIFS(Detalle!$F$2:$F$723,Detalle!$A$2:$A$723,"3B",Detalle!$E$2:$E$723,A12) -> 2 | C12: =IF($B$2=0,0,B12/$B$2) -> 0.057142857
A13: ARTES | B13: =SUMIFS(Detalle!$F$2:$F$723,Detalle!$A$2:$A$723,"3B",Detalle!$E$2:$E$723,A13) -> 1 | C13: =IF($B$2=0,0,B13/$B$2) -> 0.028571429
A14: DANZAS | B14: =SUMIFS(Detalle!$F$2:$F$723,Detalle!$A$2:$A$723,"3B",Detalle!$E$2:$E$723,A14) -> 1 | C14: =IF($B$2=0,0,B14/$B$2) -> 0.028571429
A15: ED. SOCIOEMOCIONAL | B15: =SUMIFS(Detalle!$F$2:$F$723,Detalle!$A$2:$A$723,"3B",Detalle!$E$2:$E$723,A15) -> 1 | C15: =IF($B$2=0,0,B15/$B$2) -> 0.028571429
A16: EUCARISTÍA | B16: =SUMIFS(Detalle!$F$2:$F$723,Detalle!$A$2:$A$723,"3B",Detalle!$E$2:$E$723,A16) -> 1 | C16: =IF($B$2=0,0,B16/$B$2) -> 0.028571429
... A20: ÉTICA | B20: =SUMIFS(Detalle!$F$2:$F$723,Detalle!$A$2:$A$723,"3B",Detalle!$E$2:$E$723,A20) -> 1 | C20: =IF($B$2=0,0,B20/$B$2) -> 0.028571429
A21: TOTAL | B21: =SUM(B5:B20) -> 35 | C21: =SUM(C5:C20) -> 1

Sheet Curso 3C
A1: CURSO 3C – HORAS SEMANALES POR MATERIA
A2: Total horas semanales | B2: =SUMIFS(Detalle!$F$2:$F$723,Detalle!$A$2:$A$723,"3C") -> 35
A4: Materia / actividad | B4: Horas semanales | C4: % del horario
A5: L. CASTELLANA | B5: =SUMIFS(Detalle!$F$2:$F$723,Detalle!$A$2:$A$723,"3C",Detalle!$E$2:$E$723,A5) -> 5 | C5: =IF($B$2=0,0,B5/$B$2) -> 0.14285714
A6: C. NATURALES | B6: =SUMIFS(Detalle!$F$2:$F$723,Detalle!$A$2:$A$723,"3C",Detalle!$E$2:$E$723,A6) -> 4 | C6: =IF($B$2=0,0,B6/$B$2) -> 0.11428571
A7: C. SOCIALES | B7: =SUMIFS(Detalle!$F$2:$F$723,Detalle!$A$2:$A$723,"3C",Detalle!$E$2:$E$723,A7) -> 4 | C7: =IF($B$2=0,0,B7/$B$2) -> 0.11428571
A8: INGLÉS | B8: =SUMIFS(Detalle!$F$2:$F$723,Detalle!$A$2:$A$723,"3C",Detalle!$E$2:$E$723,A8) -> 4 | C8: =IF($B$2=0,0,B8/$B$2) -> 0.11428571
A9: MATEMÁTICAS | B9: =SUMIFS(Detalle!$F$2:$F$723,Detalle!$A$2:$A$723,"3C",Detalle!$E$2:$E$723,A9) -> 4 | C9: =IF($B$2=0,0,B9/$B$2) -> 0.11428571
A10: ED. FÍSICA | B10: =SUMIFS(Detalle!$F$2:$F$723,Detalle!$A$2:$A$723,"3C",Detalle!$E$2:$E$723,A10) -> 2 | C10: =IF($B$2=0,0,B10/$B$2) -> 0.057142857
A11: ERE | B11: =SUMIFS(Detalle!$F$2:$F$723,Detalle!$A$2:$A$723,"3C",Detalle!$E$2:$E$723,A11) -> 2 | C11: =IF($B$2=0,0,B11/$B$2) -> 0.057142857
A12: INFORMÁTICA | B12: =SUMIFS(Detalle!$F$2:$F$723,Detalle!$A$2:$A$723,"3C",Detalle!$E$2:$E$723,A12) -> 2 | C12: =IF($B$2=0,0,B12/$B$2) -> 0.057142857
A13: ARTES | B13: =SUMIFS(Detalle!$F$2:$F$723,Detalle!$A$2:$A$723,"3C",Detalle!$E$2:$E$723,A13) -> 1 | C13: =IF($B$2=0,0,B13/$B$2) -> 0.028571429
A14: DANZAS | B14: =SUMIFS(Detalle!$F$2:$F$723,Detalle!$A$2:$A$723,"3C",Detalle!$E$2:$E$723,A14) -> 1 | C14: =IF($B$2=0,0,B14/$B$2) -> 0.028571429
A15: ED. SOCIOEMOCIONAL | B15: =SUMIFS(Detalle!$F$2:$F$723,Detalle!$A$2:$A$723,"3C",Detalle!$E$2:$E$723,A15) -> 1 | C15: =IF($B$2=0,0,B15/$B$2) -> 0.028571429
A16: EUCARISTÍA | B16: =SUMIFS(Detalle!$F$2:$F$723,Detalle!$A$2:$A$723,"3C",Detalle!$E$2:$E$723,A16) -> 1 | C16: =IF($B$2=0,0,B16/$B$2) -> 0.028571429
... A20: ÉTICA | B20: =SUMIFS(Detalle!$F$2:$F$723,Detalle!$A$2:$A$723,"3C",Detalle!$E$2:$E$723,A20) -> 1 | C20: =IF($B$2=0,0,B20/$B$2) -> 0.028571429
A21: TOTAL | B21: =SUM(B5:B20) -> 35 | C21: =SUM(C5:C20) -> 1

Sheet Curso 4A
A1: CURSO 4A – HORAS SEMANALES POR MATERIA
A2: Total horas semanales | B2: =SUMIFS(Detalle!$F$2:$F$723,Detalle!$A$2:$A$723,"4A") -> 35
A4: Materia / actividad | B4: Horas semanales | C4: % del horario
A5: C. NATURALES | B5: =SUMIFS(Detalle!$F$2:$F$723,Detalle!$A$2:$A$723,"4A",Detalle!$E$2:$E$723,A5) -> 4 | C5: =IF($B$2=0,0,B5/$B$2) -> 0.11428571
A6: INGLÉS | B6: =SUMIFS(Detalle!$F$2:$F$723,Detalle!$A$2:$A$723,"4A",Detalle!$E$2:$E$723,A6) -> 4 | C6: =IF($B$2=0,0,B6/$B$2) -> 0.11428571
A7: L. CASTELLANA | B7: =SUMIFS(Detalle!$F$2:$F$723,Detalle!$A$2:$A$723,"4A",Detalle!$E$2:$E$723,A7) -> 4 | C7: =IF($B$2=0,0,B7/$B$2) -> 0.11428571
A8: MATEMÁTICAS | B8: =SUMIFS(Detalle!$F$2:$F$723,Detalle!$A$2:$A$723,"4A",Detalle!$E$2:$E$723,A8) -> 4 | C8: =IF($B$2=0,0,B8/$B$2) -> 0.11428571
A9: ED. FÍSICA | B9: =SUMIFS(Detalle!$F$2:$F$723,Detalle!$A$2:$A$723,"4A",Detalle!$E$2:$E$723,A9) -> 2 | C9: =IF($B$2=0,0,B9/$B$2) -> 0.057142857
A10: ERE | B10: =SUMIFS(Detalle!$F$2:$F$723,Detalle!$A$2:$A$723,"4A",Detalle!$E$2:$E$723,A10) -> 2 | C10: =IF($B$2=0,0,B10/$B$2) -> 0.057142857
A11: GEOGRAFÍA | B11: =SUMIFS(Detalle!$F$2:$F$723,Detalle!$A$2:$A$723,"4A",Detalle!$E$2:$E$723,A11) -> 2 | C11: =IF($B$2=0,0,B11/$B$2) -> 0.057142857
A12: HISTORIA | B12: =SUMIFS(Detalle!$F$2:$F$723,Detalle!$A$2:$A$723,"4A",Detalle!$E$2:$E$723,A12) -> 2 | C12: =IF($B$2=0,0,B12/$B$2) -> 0.057142857
A13: INFORMÁTICA | B13: =SUMIFS(Detalle!$F$2:$F$723,Detalle!$A$2:$A$723,"4A",Detalle!$E$2:$E$723,A13) -> 2 | C13: =IF($B$2=0,0,B13/$B$2) -> 0.057142857
A14: ARTES | B14: =SUMIFS(Detalle!$F$2:$F$723,Detalle!$A$2:$A$723,"4A",Detalle!$E$2:$E$723,A14) -> 1 | C14: =IF($B$2=0,0,B14/$B$2) -> 0.028571429
A15: DANZAS | B15: =SUMIFS(Detalle!$F$2:$F$723,Detalle!$A$2:$A$723,"4A",Detalle!$E$2:$E$723,A15) -> 1 | C15: =IF($B$2=0,0,B15/$B$2) -> 0.028571429
A16: DEMOCRACIA | B16: =SUMIFS(Detalle!$F$2:$F$723,Detalle!$A$2:$A$723,"4A",Detalle!$E$2:$E$723,A16) -> 1 | C16: =IF($B$2=0,0,B16/$B$2) -> 0.028571429
... A22: ÉTICA | B22: =SUMIFS(Detalle!$F$2:$F$723,Detalle!$A$2:$A$723,"4A",Detalle!$E$2:$E$723,A22) -> 1 | C22: =IF($B$2=0,0,B22/$B$2) -> 0.028571429
A23: TOTAL | B23: =SUM(B5:B22) -> 35 | C23: =SUM(C5:C22) -> 1

Sheet Curso 4B
A1: CURSO 4B – HORAS SEMANALES POR MATERIA
A2: Total horas semanales | B2: =SUMIFS(Detalle!$F$2:$F$723,Detalle!$A$2:$A$723,"4B") -> 35
A4: Materia / actividad | B4: Horas semanales | C4: % del horario
A5: C. NATURALES | B5: =SUMIFS(Detalle!$F$2:$F$723,Detalle!$A$2:$A$723,"4B",Detalle!$E$2:$E$723,A5) -> 4 | C5: =IF($B$2=0,0,B5/$B$2) -> 0.11428571
A6: INGLÉS | B6: =SUMIFS(Detalle!$F$2:$F$723,Detalle!$A$2:$A$723,"4B",Detalle!$E$2:$E$723,A6) -> 4 | C6: =IF($B$2=0,0,B6/$B$2) -> 0.11428571
A7: L. CASTELLANA | B7: =SUMIFS(Detalle!$F$2:$F$723,Detalle!$A$2:$A$723,"4B",Detalle!$E$2:$E$723,A7) -> 4 | C7: =IF($B$2=0,0,B7/$B$2) -> 0.11428571
A8: MATEMÁTICAS | B8: =SUMIFS(Detalle!$F$2:$F$723,Detalle!$A$2:$A$723,"4B",Detalle!$E$2:$E$723,A8) -> 4 | C8: =IF($B$2=0,0,B8/$B$2) -> 0.11428571
A9: ED. FÍSICA | B9: =SUMIFS(Detalle!$F$2:$F$723,Detalle!$A$2:$A$723,"4B",Detalle!$E$2:$E$723,A9) -> 2 | C9: =IF($B$2=0,0,B9/$B$2) -> 0.057142857
A10: ERE | B10: =SUMIFS(Detalle!$F$2:$F$723,Detalle!$A$2:$A$723,"4B",Detalle!$E$2:$E$723,A10) -> 2 | C10: =IF($B$2=0,0,B10/$B$2) -> 0.057142857
A11: GEOGRAFÍA | B11: =SUMIFS(Detalle!$F$2:$F$723,Detalle!$A$2:$A$723,"4B",Detalle!$E$2:$E$723,A11) -> 2 | C11: =IF($B$2=0,0,B11/$B$2) -> 0.057142857
A12: HISTORIA | B12: =SUMIFS(Detalle!$F$2:$F$723,Detalle!$A$2:$A$723,"4B",Detalle!$E$2:$E$723,A12) -> 2 | C12: =IF($B$2=0,0,B12/$B$2) -> 0.057142857
A13: INFORMÁTICA | B13: =SUMIFS(Detalle!$F$2:$F$723,Detalle!$A$2:$A$723,"4B",Detalle!$E$2:$E$723,A13) -> 2 | C13: =IF($B$2=0,0,B13/$B$2) -> 0.057142857
A14: ARTES | B14: =SUMIFS(Detalle!$F$2:$F$723,Detalle!$A$2:$A$723,"4B",Detalle!$E$2:$E$723,A14) -> 1 | C14: =IF($B$2=0,0,B14/$B$2) -> 0.028571429
A15: DANZAS | B15: =SUMIFS(Detalle!$F$2:$F$723,Detalle!$A$2:$A$723,"4B",Detalle!$E$2:$E$723,A15) -> 1 | C15: =IF($B$2=0,0,B15/$B$2) -> 0.028571429
A16: DEMOCRACIA | B16: =SUMIFS(Detalle!$F$2:$F$723,Detalle!$A$2:$A$723,"4B",Detalle!$E$2:$E$723,A16) -> 1 | C16: =IF($B$2=0,0,B16/$B$2) -> 0.028571429
... A22: ÉTICA | B22: =SUMIFS(Detalle!$F$2:$F$723,Detalle!$A$2:$A$723,"4B",Detalle!$E$2:$E$723,A22) -> 1 | C22: =IF($B$2=0,0,B22/$B$2) -> 0.028571429
A23: TOTAL | B23: =SUM(B5:B22) -> 35 | C23: =SUM(C5:C22) -> 1

Sheet Curso 5A
A1: CURSO 5A – HORAS SEMANALES POR MATERIA
A2: Total horas semanales | B2: =SUMIFS(Detalle!$F$2:$F$723,Detalle!$A$2:$A$723,"5A") -> 35
A4: Materia / actividad | B4: Horas semanales | C4: % del horario
A5: C. NATURALES | B5: =SUMIFS(Detalle!$F$2:$F$723,Detalle!$A$2:$A$723,"5A",Detalle!$E$2:$E$723,A5) -> 4 | C5: =IF($B$2=0,0,B5/$B$2) -> 0.11428571
A6: INGLÉS | B6: =SUMIFS(Detalle!$F$2:$F$723,Detalle!$A$2:$A$723,"5A",Detalle!$E$2:$E$723,A6) -> 4 | C6: =IF($B$2=0,0,B6/$B$2) -> 0.11428571
A7: L. CASTELLANA | B7: =SUMIFS(Detalle!$F$2:$F$723,Detalle!$A$2:$A$723,"5A",Detalle!$E$2:$E$723,A7) -> 4 | C7: =IF($B$2=0,0,B7/$B$2) -> 0.11428571
A8: MATEMÁTICAS | B8: =SUMIFS(Detalle!$F$2:$F$723,Detalle!$A$2:$A$723,"5A",Detalle!$E$2:$E$723,A8) -> 4 | C8: =IF($B$2=0,0,B8/$B$2) -> 0.11428571
A9: ED. FÍSICA | B9: =SUMIFS(Detalle!$F$2:$F$723,Detalle!$A$2:$A$723,"5A",Detalle!$E$2:$E$723,A9) -> 2 | C9: =IF($B$2=0,0,B9/$B$2) -> 0.057142857
A10: ERE | B10: =SUMIFS(Detalle!$F$2:$F$723,Detalle!$A$2:$A$723,"5A",Detalle!$E$2:$E$723,A10) -> 2 | C10: =IF($B$2=0,0,B10/$B$2) -> 0.057142857
A11: GEOGRAFÍA | B11: =SUMIFS(Detalle!$F$2:$F$723,Detalle!$A$2:$A$723,"5A",Detalle!$E$2:$E$723,A11) -> 2 | C11: =IF($B$2=0,0,B11/$B$2) -> 0.057142857
A12: HISTORIA | B12: =SUMIFS(Detalle!$F$2:$F$723,Detalle!$A$2:$A$723,"5A",Detalle!$E$2:$E$723,A12) -> 2 | C12: =IF($B$2=0,0,B12/$B$2) -> 0.057142857
A13: INFORMÁTICA | B13: =SUMIFS(Detalle!$F$2:$F$723,Detalle!$A$2:$A$723,"5A",Detalle!$E$2:$E$723,A13) -> 2 | C13: =IF($B$2=0,0,B13/$B$2) -> 0.057142857
A14: ARTES | B14: =SUMIFS(Detalle!$F$2:$F$723,Detalle!$A$2:$A$723,"5A",Detalle!$E$2:$E$723,A14) -> 1 | C14: =IF($B$2=0,0,B14/$B$2) -> 0.028571429
A15: DANZAS | B15: =SUMIFS(Detalle!$F$2:$F$723,Detalle!$A$2:$A$723,"5A",Detalle!$E$2:$E$723,A15) -> 1 | C15: =IF($B$2=0,0,B15/$B$2) -> 0.028571429
A16: DEMOCRACIA | B16: =SUMIFS(Detalle!$F$2:$F$723,Detalle!$A$2:$A$723,"5A",Detalle!$E$2:$E$723,A16) -> 1 | C16: =IF($B$2=0,0,B16/$B$2) -> 0.028571429
... A22: ÉTICA | B22: =SUMIFS(Detalle!$F$2:$F$723,Detalle!$A$2:$A$723,"5A",Detalle!$E$2:$E$723,A22) -> 1 | C22: =IF($B$2=0,0,B22/$B$2) -> 0.028571429
A23: TOTAL | B23: =SUM(B5:B22) -> 35 | C23: =SUM(C5:C22) -> 1

Sheet Curso 5B
A1: CURSO 5B – HORAS SEMANALES POR MATERIA
A2: Total horas semanales | B2: =SUMIFS(Detalle!$F$2:$F$723,Detalle!$A$2:$A$723,"5B") -> 35
A4: Materia / actividad | B4: Horas semanales | C4: % del horario
A5: C. NATURALES | B5: =SUMIFS(Detalle!$F$2:$F$723,Detalle!$A$2:$A$723,"5B",Detalle!$E$2:$E$723,A5) -> 4 | C5: =IF($B$2=0,0,B5/$B$2) -> 0.11428571
A6: INGLÉS | B6: =SUMIFS(Detalle!$F$2:$F$723,Detalle!$A$2:$A$723,"5B",Detalle!$E$2:$E$723,A6) -> 4 | C6: =IF($B$2=0,0,B6/$B$2) -> 0.11428571
A7: L. CASTELLANA | B7: =SUMIFS(Detalle!$F$2:$F$723,Detalle!$A$2:$A$723,"5B",Detalle!$E$2:$E$723,A7) -> 4 | C7: =IF($B$2=0,0,B7/$B$2) -> 0.11428571
A8: MATEMÁTICAS | B8: =SUMIFS(Detalle!$F$2:$F$723,Detalle!$A$2:$A$723,"5B",Detalle!$E$2:$E$723,A8) -> 4 | C8: =IF($B$2=0,0,B8/$B$2) -> 0.11428571
A9: ED. FÍSICA | B9: =SUMIFS(Detalle!$F$2:$F$723,Detalle!$A$2:$A$723,"5B",Detalle!$E$2:$E$723,A9) -> 2 | C9: =IF($B$2=0,0,B9/$B$2) -> 0.057142857
A10: ERE | B10: =SUMIFS(Detalle!$F$2:$F$723,Detalle!$A$2:$A$723,"5B",Detalle!$E$2:$E$723,A10) -> 2 | C10: =IF($B$2=0,0,B10/$B$2) -> 0.057142857
A11: GEOGRAFÍA | B11: =SUMIFS(Detalle!$F$2:$F$723,Detalle!$A$2:$A$723,"5B",Detalle!$E$2:$E$723,A11) -> 2 | C11: =IF($B$2=0,0,B11/$B$2) -> 0.057142857
A12: HISTORIA | B12: =SUMIFS(Detalle!$F$2:$F$723,Detalle!$A$2:$A$723,"5B",Detalle!$E$2:$E$723,A12) -> 2 | C12: =IF($B$2=0,0,B12/$B$2) -> 0.057142857
A13: INFORMÁTICA | B13: =SUMIFS(Detalle!$F$2:$F$723,Detalle!$A$2:$A$723,"5B",Detalle!$E$2:$E$723,A13) -> 2 | C13: =IF($B$2=0,0,B13/$B$2) -> 0.057142857
A14: ARTES | B14: =SUMIFS(Detalle!$F$2:$F$723,Detalle!$A$2:$A$723,"5B",Detalle!$E$2:$E$723,A14) -> 1 | C14: =IF($B$2=0,0,B14/$B$2) -> 0.028571429
A15: DANZAS | B15: =SUMIFS(Detalle!$F$2:$F$723,Detalle!$A$2:$A$723,"5B",Detalle!$E$2:$E$723,A15) -> 1 | C15: =IF($B$2=0,0,B15/$B$2) -> 0.028571429
A16: DEMOCRACIA | B16: =SUMIFS(Detalle!$F$2:$F$723,Detalle!$A$2:$A$723,"5B",Detalle!$E$2:$E$723,A16) -> 1 | C16: =IF($B$2=0,0,B16/$B$2) -> 0.028571429
... A22: ÉTICA | B22: =SUMIFS(Detalle!$F$2:$F$723,Detalle!$A$2:$A$723,"5B",Detalle!$E$2:$E$723,A22) -> 1 | C22: =IF($B$2=0,0,B22/$B$2) -> 0.028571429
A23: TOTAL | B23: =SUM(B5:B22) -> 35 | C23: =SUM(C5:C22) -> 1

Sheet Curso 6A
A1: CURSO 6A – HORAS SEMANALES POR MATERIA
A2: Total horas semanales | B2: =SUMIFS(Detalle!$F$2:$F$723,Detalle!$A$2:$A$723,"6A") -> 35
A4: Materia / actividad | B4: Horas semanales | C4: % del horario
A5: C. NATURALES | B5: =SUMIFS(Detalle!$F$2:$F$723,Detalle!$A$2:$A$723,"6A",Detalle!$E$2:$E$723,A5) -> 4 | C5: =IF($B$2=0,0,B5/$B$2) -> 0.11428571
A6: INGLÉS | B6: =SUMIFS(Detalle!$F$2:$F$723,Detalle!$A$2:$A$723,"6A",Detalle!$E$2:$E$723,A6) -> 4 | C6: =IF($B$2=0,0,B6/$B$2) -> 0.11428571
A7: L. CASTELLANA | B7: =SUMIFS(Detalle!$F$2:$F$723,Detalle!$A$2:$A$723,"6A",Detalle!$E$2:$E$723,A7) -> 4 | C7: =IF($B$2=0,0,B7/$B$2) -> 0.11428571
A8: MATEMÁTICAS | B8: =SUMIFS(Detalle!$F$2:$F$723,Detalle!$A$2:$A$723,"6A",Detalle!$E$2:$E$723,A8) -> 4 | C8: =IF($B$2=0,0,B8/$B$2) -> 0.11428571
A9: ED. FÍSICA | B9: =SUMIFS(Detalle!$F$2:$F$723,Detalle!$A$2:$A$723,"6A",Detalle!$E$2:$E$723,A9) -> 2 | C9: =IF($B$2=0,0,B9/$B$2) -> 0.057142857
A10: ERE | B10: =SUMIFS(Detalle!$F$2:$F$723,Detalle!$A$2:$A$723,"6A",Detalle!$E$2:$E$723,A10) -> 2 | C10: =IF($B$2=0,0,B10/$B$2) -> 0.057142857
A11: GEOGRAFÍA | B11: =SUMIFS(Detalle!$F$2:$F$723,Detalle!$A$2:$A$723,"6A",Detalle!$E$2:$E$723,A11) -> 2 | C11: =IF($B$2=0,0,B11/$B$2) -> 0.057142857
A12: HISTORIA | B12: =SUMIFS(Detalle!$F$2:$F$723,Detalle!$A$2:$A$723,"6A",Detalle!$E$2:$E$723,A12) -> 2 | C12: =IF($B$2=0,0,B12/$B$2) -> 0.057142857
A13: INFORMÁTICA | B13: =SUMIFS(Detalle!$F$2:$F$723,Detalle!$A$2:$A$723,"6A",Detalle!$E$2:$E$723,A13) -> 2 | C13: =IF($B$2=0,0,B13/$B$2) -> 0.057142857
A14: ARTES | B14: =SUMIFS(Detalle!$F$2:$F$723,Detalle!$A$2:$A$723,"6A",Detalle!$E$2:$E$723,A14) -> 1 | C14: =IF($B$2=0,0,B14/$B$2) -> 0.028571429
A15: DANZAS | B15: =SUMIFS(Detalle!$F$2:$F$723,Detalle!$A$2:$A$723,"6A",Detalle!$E$2:$E$723,A15) -> 1 | C15: =IF($B$2=0,0,B15/$B$2) -> 0.028571429
A16: DEMOCRACIA | B16: =SUMIFS(Detalle!$F$2:$F$723,Detalle!$A$2:$A$723,"6A",Detalle!$E$2:$E$723,A16) -> 1 | C16: =IF($B$2=0,0,B16/$B$2) -> 0.028571429
... A22: ÉTICA | B22: =SUMIFS(Detalle!$F$2:$F$723,Detalle!$A$2:$A$723,"6A",Detalle!$E$2:$E$723,A22) -> 1 | C22: =IF($B$2=0,0,B22/$B$2) -> 0.028571429
A23: TOTAL | B23: =SUM(B5:B22) -> 35 | C23: =SUM(C5:C22) -> 1

Sheet Curso 6B
A1: CURSO 6B – HORAS SEMANALES POR MATERIA
A2: Total horas semanales | B2: =SUMIFS(Detalle!$F$2:$F$723,Detalle!$A$2:$A$723,"6B") -> 35
A4: Materia / actividad | B4: Horas semanales | C4: % del horario
A5: C. NATURALES | B5: =SUMIFS(Detalle!$F$2:$F$723,Detalle!$A$2:$A$723,"6B",Detalle!$E$2:$E$723,A5) -> 4 | C5: =IF($B$2=0,0,B5/$B$2) -> 0.11428571
A6: INGLÉS | B6: =SUMIFS(Detalle!$F$2:$F$723,Detalle!$A$2:$A$723,"6B",Detalle!$E$2:$E$723,A6) -> 4 | C6: =IF($B$2=0,0,B6/$B$2) -> 0.11428571
A7: L. CASTELLANA | B7: =SUMIFS(Detalle!$F$2:$F$723,Detalle!$A$2:$A$723,"6B",Detalle!$E$2:$E$723,A7) -> 4 | C7: =IF($B$2=0,0,B7/$B$2) -> 0.11428571
A8: MATEMÁTICAS | B8: =SUMIFS(Detalle!$F$2:$F$723,Detalle!$A$2:$A$723,"6B",Detalle!$E$2:$E$723,A8) -> 4 | C8: =IF($B$2=0,0,B8/$B$2) -> 0.11428571
A9: ED. FÍSICA | B9: =SUMIFS(Detalle!$F$2:$F$723,Detalle!$A$2:$A$723,"6B",Detalle!$E$2:$E$723,A9) -> 2 | C9: =IF($B$2=0,0,B9/$B$2) -> 0.057142857
A10: ERE | B10: =SUMIFS(Detalle!$F$2:$F$723,Detalle!$A$2:$A$723,"6B",Detalle!$E$2:$E$723,A10) -> 2 | C10: =IF($B$2=0,0,B10/$B$2) -> 0.057142857
A11: GEOGRAFÍA | B11: =SUMIFS(Detalle!$F$2:$F$723,Detalle!$A$2:$A$723,"6B",Detalle!$E$2:$E$723,A11) -> 2 | C11: =IF($B$2=0,0,B11/$B$2) -> 0.057142857
A12: HISTORIA | B12: =SUMIFS(Detalle!$F$2:$F$723,Detalle!$A$2:$A$723,"6B",Detalle!$E$2:$E$723,A12) -> 2 | C12: =IF($B$2=0,0,B12/$B$2) -> 0.057142857
A13: INFORMÁTICA | B13: =SUMIFS(Detalle!$F$2:$F$723,Detalle!$A$2:$A$723,"6B",Detalle!$E$2:$E$723,A13) -> 2 | C13: =IF($B$2=0,0,B13/$B$2) -> 0.057142857
A14: ARTES | B14: =SUMIFS(Detalle!$F$2:$F$723,Detalle!$A$2:$A$723,"6B",Detalle!$E$2:$E$723,A14) -> 1 | C14: =IF($B$2=0,0,B14/$B$2) -> 0.028571429
A15: DANZAS | B15: =SUMIFS(Detalle!$F$2:$F$723,Detalle!$A$2:$A$723,"6B",Detalle!$E$2:$E$723,A15) -> 1 | C15: =IF($B$2=0,0,B15/$B$2) -> 0.028571429
A16: DEMOCRACIA | B16: =SUMIFS(Detalle!$F$2:$F$723,Detalle!$A$2:$A$723,"6B",Detalle!$E$2:$E$723,A16) -> 1 | C16: =IF($B$2=0,0,B16/$B$2) -> 0.028571429
... A22: ÉTICA | B22: =SUMIFS(Detalle!$F$2:$F$723,Detalle!$A$2:$A$723,"6B",Detalle!$E$2:$E$723,A22) -> 1 | C22: =IF($B$2=0,0,B22/$B$2) -> 0.028571429
A23: TOTAL | B23: =SUM(B5:B22) -> 35 | C23: =SUM(C5:C22) -> 1

Sheet Curso 7A
A1: CURSO 7A – HORAS SEMANALES POR MATERIA
A2: Total horas semanales | B2: =SUMIFS(Detalle!$F$2:$F$723,Detalle!$A$2:$A$723,"7A") -> 35
A4: Materia / actividad | B4: Horas semanales | C4: % del horario
A5: C. NATURALES | B5: =SUMIFS(Detalle!$F$2:$F$723,Detalle!$A$2:$A$723,"7A",Detalle!$E$2:$E$723,A5) -> 4 | C5: =IF($B$2=0,0,B5/$B$2) -> 0.11428571
A6: INGLÉS | B6: =SUMIFS(Detalle!$F$2:$F$723,Detalle!$A$2:$A$723,"7A",Detalle!$E$2:$E$723,A6) -> 4 | C6: =IF($B$2=0,0,B6/$B$2) -> 0.11428571
A7: L. CASTELLANA | B7: =SUMIFS(Detalle!$F$2:$F$723,Detalle!$A$2:$A$723,"7A",Detalle!$E$2:$E$723,A7) -> 4 | C7: =IF($B$2=0,0,B7/$B$2) -> 0.11428571
A8: MATEMÁTICAS | B8: =SUMIFS(Detalle!$F$2:$F$723,Detalle!$A$2:$A$723,"7A",Detalle!$E$2:$E$723,A8) -> 4 | C8: =IF($B$2=0,0,B8/$B$2) -> 0.11428571
A9: ED. FÍSICA | B9: =SUMIFS(Detalle!$F$2:$F$723,Detalle!$A$2:$A$723,"7A",Detalle!$E$2:$E$723,A9) -> 2 | C9: =IF($B$2=0,0,B9/$B$2) -> 0.057142857
A10: ERE | B10: =SUMIFS(Detalle!$F$2:$F$723,Detalle!$A$2:$A$723,"7A",Detalle!$E$2:$E$723,A10) -> 2 | C10: =IF($B$2=0,0,B10/$B$2) -> 0.057142857
A11: GEOGRAFÍA | B11: =SUMIFS(Detalle!$F$2:$F$723,Detalle!$A$2:$A$723,"7A",Detalle!$E$2:$E$723,A11) -> 2 | C11: =IF($B$2=0,0,B11/$B$2) -> 0.057142857
A12: HISTORIA | B12: =SUMIFS(Detalle!$F$2:$F$723,Detalle!$A$2:$A$723,"7A",Detalle!$E$2:$E$723,A12) -> 2 | C12: =IF($B$2=0,0,B12/$B$2) -> 0.057142857
A13: INFORMÁTICA | B13: =SUMIFS(Detalle!$F$2:$F$723,Detalle!$A$2:$A$723,"7A",Detalle!$E$2:$E$723,A13) -> 2 | C13: =IF($B$2=0,0,B13/$B$2) -> 0.057142857
A14: ARTES | B14: =SUMIFS(Detalle!$F$2:$F$723,Detalle!$A$2:$A$723,"7A",Detalle!$E$2:$E$723,A14) -> 1 | C14: =IF($B$2=0,0,B14/$B$2) -> 0.028571429
A15: DANZAS | B15: =SUMIFS(Detalle!$F$2:$F$723,Detalle!$A$2:$A$723,"7A",Detalle!$E$2:$E$723,A15) -> 1 | C15: =IF($B$2=0,0,B15/$B$2) -> 0.028571429
A16: DEMOCRACIA | B16: =SUMIFS(Detalle!$F$2:$F$723,Detalle!$A$2:$A$723,"7A",Detalle!$E$2:$E$723,A16) -> 1 | C16: =IF($B$2=0,0,B16/$B$2) -> 0.028571429
... A22: ÉTICA | B22: =SUMIFS(Detalle!$F$2:$F$723,Detalle!$A$2:$A$723,"7A",Detalle!$E$2:$E$723,A22) -> 1 | C22: =IF($B$2=0,0,B22/$B$2) -> 0.028571429
A23: TOTAL | B23: =SUM(B5:B22) -> 35 | C23: =SUM(C5:C22) -> 1

Sheet Curso 7B
A1: CURSO 7B – HORAS SEMANALES POR MATERIA
A2: Total horas semanales | B2: =SUMIFS(Detalle!$F$2:$F$723,Detalle!$A$2:$A$723,"7B") -> 35
A4: Materia / actividad | B4: Horas semanales | C4: % del horario
A5: C. NATURALES | B5: =SUMIFS(Detalle!$F$2:$F$723,Detalle!$A$2:$A$723,"7B",Detalle!$E$2:$E$723,A5) -> 4 | C5: =IF($B$2=0,0,B5/$B$2) -> 0.11428571
A6: INGLÉS | B6: =SUMIFS(Detalle!$F$2:$F$723,Detalle!$A$2:$A$723,"7B",Detalle!$E$2:$E$723,A6) -> 4 | C6: =IF($B$2=0,0,B6/$B$2) -> 0.11428571
A7: L. CASTELLANA | B7: =SUMIFS(Detalle!$F$2:$F$723,Detalle!$A$2:$A$723,"7B",Detalle!$E$2:$E$723,A7) -> 4 | C7: =IF($B$2=0,0,B7/$B$2) -> 0.11428571
A8: MATEMÁTICAS | B8: =SUMIFS(Detalle!$F$2:$F$723,Detalle!$A$2:$A$723,"7B",Detalle!$E$2:$E$723,A8) -> 4 | C8: =IF($B$2=0,0,B8/$B$2) -> 0.11428571
A9: ED. FÍSICA | B9: =SUMIFS(Detalle!$F$2:$F$723,Detalle!$A$2:$A$723,"7B",Detalle!$E$2:$E$723,A9) -> 2 | C9: =IF($B$2=0,0,B9/$B$2) -> 0.057142857
A10: ERE | B10: =SUMIFS(Detalle!$F$2:$F$723,Detalle!$A$2:$A$723,"7B",Detalle!$E$2:$E$723,A10) -> 2 | C10: =IF($B$2=0,0,B10/$B$2) -> 0.057142857
A11: GEOGRAFÍA | B11: =SUMIFS(Detalle!$F$2:$F$723,Detalle!$A$2:$A$723,"7B",Detalle!$E$2:$E$723,A11) -> 2 | C11: =IF($B$2=0,0,B11/$B$2) -> 0.057142857
A12: HISTORIA | B12: =SUMIFS(Detalle!$F$2:$F$723,Detalle!$A$2:$A$723,"7B",Detalle!$E$2:$E$723,A12) -> 2 | C12: =IF($B$2=0,0,B12/$B$2) -> 0.057142857
A13: INFORMÁTICA | B13: =SUMIFS(Detalle!$F$2:$F$723,Detalle!$A$2:$A$723,"7B",Detalle!$E$2:$E$723,A13) -> 2 | C13: =IF($B$2=0,0,B13/$B$2) -> 0.057142857
A14: ARTES | B14: =SUMIFS(Detalle!$F$2:$F$723,Detalle!$A$2:$A$723,"7B",Detalle!$E$2:$E$723,A14) -> 1 | C14: =IF($B$2=0,0,B14/$B$2) -> 0.028571429
A15: DANZAS | B15: =SUMIFS(Detalle!$F$2:$F$723,Detalle!$A$2:$A$723,"7B",Detalle!$E$2:$E$723,A15) -> 1 | C15: =IF($B$2=0,0,B15/$B$2) -> 0.028571429
A16: DEMOCRACIA | B16: =SUMIFS(Detalle!$F$2:$F$723,Detalle!$A$2:$A$723,"7B",Detalle!$E$2:$E$723,A16) -> 1 | C16: =IF($B$2=0,0,B16/$B$2) -> 0.028571429
... A22: ÉTICA | B22: =SUMIFS(Detalle!$F$2:$F$723,Detalle!$A$2:$A$723,"7B",Detalle!$E$2:$E$723,A22) -> 1 | C22: =IF($B$2=0,0,B22/$B$2) -> 0.028571429
A23: TOTAL | B23: =SUM(B5:B22) -> 35 | C23: =SUM(C5:C22) -> 1

Sheet Curso 8°
A1: CURSO 8° – HORAS SEMANALES POR MATERIA
A2: Total horas semanales | B2: =SUMIFS(Detalle!$F$2:$F$723,Detalle!$A$2:$A$723,"8°") -> 35
A4: Materia / actividad | B4: Horas semanales | C4: % del horario
A5: C. NATURALES | B5: =SUMIFS(Detalle!$F$2:$F$723,Detalle!$A$2:$A$723,"8°",Detalle!$E$2:$E$723,A5) -> 4 | C5: =IF($B$2=0,0,B5/$B$2) -> 0.11428571
A6: INGLÉS | B6: =SUMIFS(Detalle!$F$2:$F$723,Detalle!$A$2:$A$723,"8°",Detalle!$E$2:$E$723,A6) -> 4 | C6: =IF($B$2=0,0,B6/$B$2) -> 0.11428571
A7: ÁLGEBRA | B7: =SUMIFS(Detalle!$F$2:$F$723,Detalle!$A$2:$A$723,"8°",Detalle!$E$2:$E$723,A7) -> 4 | C7: =IF($B$2=0,0,B7/$B$2) -> 0.11428571
A8: L. CASTELLANA | B8: =SUMIFS(Detalle!$F$2:$F$723,Detalle!$A$2:$A$723,"8°",Detalle!$E$2:$E$723,A8) -> 3 | C8: =IF($B$2=0,0,B8/$B$2) -> 0.085714286
A9: ED. FÍSICA | B9: =SUMIFS(Detalle!$F$2:$F$723,Detalle!$A$2:$A$723,"8°",Detalle!$E$2:$E$723,A9) -> 2 | C9: =IF($B$2=0,0,B9/$B$2) -> 0.057142857
A10: ERE | B10: =SUMIFS(Detalle!$F$2:$F$723,Detalle!$A$2:$A$723,"8°",Detalle!$E$2:$E$723,A10) -> 2 | C10: =IF($B$2=0,0,B10/$B$2) -> 0.057142857
A11: GEOGRAFÍA | B11: =SUMIFS(Detalle!$F$2:$F$723,Detalle!$A$2:$A$723,"8°",Detalle!$E$2:$E$723,A11) -> 2 | C11: =IF($B$2=0,0,B11/$B$2) -> 0.057142857
A12: HISTORIA | B12: =SUMIFS(Detalle!$F$2:$F$723,Detalle!$A$2:$A$723,"8°",Detalle!$E$2:$E$723,A12) -> 2 | C12: =IF($B$2=0,0,B12/$B$2) -> 0.057142857
A13: INFORMÁTICA | B13: =SUMIFS(Detalle!$F$2:$F$723,Detalle!$A$2:$A$723,"8°",Detalle!$E$2:$E$723,A13) -> 2 | C13: =IF($B$2=0,0,B13/$B$2) -> 0.057142857
A14: ARTES | B14: =SUMIFS(Detalle!$F$2:$F$723,Detalle!$A$2:$A$723,"8°",Detalle!$E$2:$E$723,A14) -> 1 | C14: =IF($B$2=0,0,B14/$B$2) -> 0.028571429
A15: DANZAS | B15: =SUMIFS(Detalle!$F$2:$F$723,Detalle!$A$2:$A$723,"8°",Detalle!$E$2:$E$723,A15) -> 1 | C15: =IF($B$2=0,0,B15/$B$2) -> 0.028571429
A16: DEMOCRACIA | B16: =SUMIFS(Detalle!$F$2:$F$723,Detalle!$A$2:$A$723,"8°",Detalle!$E$2:$E$723,A16) -> 1 | C16: =IF($B$2=0,0,B16/$B$2) -> 0.028571429
... A23: ÉTICA | B23: =SUMIFS(Detalle!$F$2:$F$723,Detalle!$A$2:$A$723,"8°",Detalle!$E$2:$E$723,A23) -> 1 | C23: =IF($B$2=0,0,B23/$B$2) -> 0.028571429
A24: TOTAL | B24: =SUM(B5:B23) -> 35 | C24: =SUM(C5:C23) -> 1

Sheet Curso 9°
A1: CURSO 9° – HORAS SEMANALES POR MATERIA
A2: Total horas semanales | B2: =SUMIFS(Detalle!$F$2:$F$723,Detalle!$A$2:$A$723,"9°") -> 35
A4: Materia / actividad | B4: Horas semanales | C4: % del horario
A5: C. NATURALES | B5: =SUMIFS(Detalle!$F$2:$F$723,Detalle!$A$2:$A$723,"9°",Detalle!$E$2:$E$723,A5) -> 4 | C5: =IF($B$2=0,0,B5/$B$2) -> 0.11428571
A6: INGLÉS | B6: =SUMIFS(Detalle!$F$2:$F$723,Detalle!$A$2:$A$723,"9°",Detalle!$E$2:$E$723,A6) -> 4 | C6: =IF($B$2=0,0,B6/$B$2) -> 0.11428571
A7: L. CASTELLANA | B7: =SUMIFS(Detalle!$F$2:$F$723,Detalle!$A$2:$A$723,"9°",Detalle!$E$2:$E$723,A7) -> 4 | C7: =IF($B$2=0,0,B7/$B$2) -> 0.11428571
A8: ÁLGEBRA | B8: =SUMIFS(Detalle!$F$2:$F$723,Detalle!$A$2:$A$723,"9°",Detalle!$E$2:$E$723,A8) -> 4 | C8: =IF($B$2=0,0,B8/$B$2) -> 0.11428571
A9: ED. FÍSICA | B9: =SUMIFS(Detalle!$F$2:$F$723,Detalle!$A$2:$A$723,"9°",Detalle!$E$2:$E$723,A9) -> 2 | C9: =IF($B$2=0,0,B9/$B$2) -> 0.057142857
A10: ERE | B10: =SUMIFS(Detalle!$F$2:$F$723,Detalle!$A$2:$A$723,"9°",Detalle!$E$2:$E$723,A10) -> 2 | C10: =IF($B$2=0,0,B10/$B$2) -> 0.057142857
A11: GEOGRAFÍA | B11: =SUMIFS(Detalle!$F$2:$F$723,Detalle!$A$2:$A$723,"9°",Detalle!$E$2:$E$723,A11) -> 2 | C11: =IF($B$2=0,0,B11/$B$2) -> 0.057142857
A12: HISTORIA | B12: =SUMIFS(Detalle!$F$2:$F$723,Detalle!$A$2:$A$723,"9°",Detalle!$E$2:$E$723,A12) -> 2 | C12: =IF($B$2=0,0,B12/$B$2) -> 0.057142857
A13: INFORMÁTICA | B13: =SUMIFS(Detalle!$F$2:$F$723,Detalle!$A$2:$A$723,"9°",Detalle!$E$2:$E$723,A13) -> 2 | C13: =IF($B$2=0,0,B13/$B$2) -> 0.057142857
A14: ARTES | B14: =SUMIFS(Detalle!$F$2:$F$723,Detalle!$A$2:$A$723,"9°",Detalle!$E$2:$E$723,A14) -> 1 | C14: =IF($B$2=0,0,B14/$B$2) -> 0.028571429
